Workbook
Name EarnField: Control!$B$5
Name TkrSuffix: Control!$B$4

Sheet README
A1: README — Earnings announcement history (Bloomberg BDS)
A2: For human readers and AI models: read this sheet before using the data.
A4: Key | B4: Value
A5: content | B5: Historical earnings announcement dates/times with EPS, one block per stock.
A6: bloomberg_field | B6: EARN_ANN_DT_TIME_HIST_WITH_EPS (BDS bulk field; see Control!B5)
A7: columns | B7: Year/Period | Announcement Date | Announcement Time | Earnings EPS | Comparable EPS | Estimate EPS
A8: eps_definitions | B8: As defined by Bloomberg for this field. Check FLDS <GO> on the terminal for the exact definitions of Earnings vs Comparable vs Estimate EPS and the time zone of Announcement Time before relying on them.
A9: row_order | B9: As returned by Bloomberg (not re-sorted in this workbook).
A10: history_depth | B10: As returned by Bloomberg; varies by stock. Recent listings (PLTR, COIN, HOOD) have short histories.
A11: fiscal_periods | B11: Year/Period is each company's FISCAL period, not calendar quarter (e.g. AAPL, MSFT, NVDA, ORCL, COST, CRM, ADBE have non-December fiscal years).
A12: currency | B12: TSM is the NYSE ADR; check EPS currency/ADR ratio basis before comparing to TWSE-listed 2330.
A13: layout | B13: Data sheet: one 6-column block per stock + 1 spacer column. Row 1 ticker, row 2 Bloomberg security, row 3 headers, data from row 4. Rows are NOT aligned across stocks.
A14: source | B14: Bloomberg BDS via Excel add-in

Sheet Control
A1: Earnings Dates Pull — Control Panel
A2: Yellow cells are inputs (blue text).
A4: Ticker suffix | B4: US Equity | C4: Appended to each ticker (leading space).
A5: BDS field | B5: EARN_ANN_DT_TIME_HIST_WITH_EPS | C5: From your AAPL formula.
A8: Ticker list
A9: # | B9: Ticker | C9: Bloomberg security | D9: Block starts at (Data col) | F9: Notes
A10: 1 | B10: AAPL | C10: =B10&TkrSuffix -> AAPL US Equity | D10: A | F10: 1. Open in Excel with the Bloomberg add-in logged in; BDS cells show a name error until then.
A11: 2 | B11: AMZN | C11: =B11&TkrSuffix -> AMZN US Equity | D11: H | F11: 2. Bloomberg ribbon > Refresh Worksheet on the Data sheet.
A12: 3 | B12: GOOGL | C12: =B12&TkrSuffix -> GOOGL US Equity | D12: O | F12: 3. BDS is a bulk field: each block spills down a variable number of rows.
A13: 4 | B13: META | C13: =B13&TkrSuffix -> META US Equity | D13: V | F13: 4. Once loaded, Paste Values into a new sheet (keep README) so reopening doesn't re-pull.
A14: 5 | B14: MSFT | C14: =B14&TkrSuffix -> MSFT US Equity | D14: AC
A15: 6 | B15: NFLX | C15: =B15&TkrSuffix -> NFLX US Equity | D15: AJ
A16: 7 | B16: NVDA | C16: =B16&TkrSuffix -> NVDA US Equity | D16: AQ
A17: 8 | B17: PLTR | C17: =B17&TkrSuffix -> PLTR US Equity | D17: AX
A18: 9 | B18: TSLA | C18: =B18&TkrSuffix -> TSLA US Equity | D18: BE
A19: 10 | B19: TSM | C19: =B19&TkrSuffix -> TSM US Equity | D19: BL
A20: 11 | B20: AVGO | C20: =B20&TkrSuffix -> AVGO US Equity | D20: BS
A21: 12 | B21: AMD | C21: =B21&TkrSuffix -> AMD US Equity | D21: BZ
A22: 13 | B22: MU | C22: =B22&TkrSuffix -> MU US Equity | D22: CG
A23: 14 | B23: MSTR | C23: =B23&TkrSuffix -> MSTR US Equity | D23: CN
A24: 15 | B24: COIN | C24: =B24&TkrSuffix -> COIN US Equity | D24: CU
A25: 16 | B25: HOOD | C25: =B25&TkrSuffix -> HOOD US Equity | D25: DB
... A36: 27 | B36: XOM | C36: =B36&TkrSuffix -> XOM US Equity | D36: GA

Sheet Earnings_Data
A1: =Control!$B$10 -> AAPL | H1: =Control!$B$11 -> AMZN | O1: =Control!$B$12 -> GOOGL | V1: =Control!$B$13 -> META | AC1: =Control!$B$14 -> MSFT | AJ1: =Control!$B$15 -> NFLX | AQ1: =Control!$B$16 -> NVDA | AX1: =Control!$B$17 -> PLTR | BE1: =Control!$B$18 -> TSLA | BL1: =Control!$B$19 -> TSM | BS1: =Control!$B$20 -> AVGO | BZ1: =Control!$B$21 -> AMD | CG1: =Control!$B$22 -> MU | CN1: =Control!$B$23 -> MSTR | CU1: =Control!$B$24 -> COIN | DB1: =Control!$B$25 -> HOOD | DI1: =Control!$B$26 -> SHOP | DP1: =Control!$B$27 -> SMCI | DW1: =Control!$B$28 -> ORCL | ED1: =Control!$B$29 -> CRM | EK1: =Control!$B$30 -> ADBE | ER1: =Control!$B$31 -> NOW | EY1: =Control!$B$32 -> LLY | FF1: =Control!$B$33 -> UNH | FM1: =Control!$B$34 -> JPM | FT1: =Control!$B$35 -> COST | GA1: =Control!$B$36 -> XOM
A2: =Control!$C$10 -> AAPL US Equity | H2: =Control!$C$11 -> AMZN US Equity | O2: =Control!$C$12 -> GOOGL US Equity | V2: =Control!$C$13 -> META US Equity | AC2: =Control!$C$14 -> MSFT US Equity | AJ2: =Control!$C$15 -> NFLX US Equity | AQ2: =Control!$C$16 -> NVDA US Equity | AX2: =Control!$C$17 -> PLTR US Equity | BE2: =Control!$C$18 -> TSLA US Equity | BL2: =Control!$C$19 -> TSM US Equity | BS2: =Control!$C$20 -> AVGO US Equity | BZ2: =Control!$C$21 -> AMD US Equity | CG2: =Control!$C$22 -> MU US Equity | CN2: =Control!$C$23 -> MSTR US Equity | CU2: =Control!$C$24 -> COIN US Equity | DB2: =Control!$C$25 -> HOOD US Equity | DI2: =Control!$C$26 -> SHOP US Equity | DP2: =Control!$C$27 -> SMCI US Equity | DW2: =Control!$C$28 -> ORCL US Equity | ED2: =Control!$C$29 -> CRM US Equity | EK2: =Control!$C$30 -> ADBE US Equity | ER2: =Control!$C$31 -> NOW US Equity | EY2: =Control!$C$32 -> LLY US Equity | FF2: =Control!$C$33 -> UNH US Equity | FM2: =Control!$C$34 -> JPM US Equity | FT2: =Control!$C$35 -> COST US Equity | GA2: =Control!$C$36 -> XOM US Equity
A3: Year/Period | B3: Announcement Date | C3: Announcement Time | D3: Earnings EPS | E3: Comparable EPS | F3: Estimate EPS | H3: Year/Period | I3: Announcement Date | J3: Announcement Time | K3: Earnings EPS | L3: Comparable EPS | M3: Estimate EPS | O3: Year/Period | P3: Announcement Date | Q3: Announcement Time | R3: Earnings EPS | S3: Comparable EPS | T3: Estimate EPS | V3: Year/Period | W3: Announcement Date | X3: Announcement Time | Y3: Earnings EPS | Z3: Comparable EPS | AA3: Estimate EPS | AC3: Year/Period | AD3: Announcement Date | AE3: Announcement Time | AF3: Earnings EPS | AG3: Comparable EPS | AH3: Estimate EPS | AJ3: Year/Period | AK3: Announcement Date | AL3: Announcement Time | AM3: Earnings EPS | AN3: Comparable EPS | AO3: Estimate EPS | AQ3: Year/Period | AR3: Announcement Date | AS3: Announcement Time | AT3: Earnings EPS | AU3: Comparable EPS | AV3: Estimate EPS | AX3: Year/Period | AY3: Announcement Date | AZ3: Announcement Time | BA3: Earnings EPS | BB3: Comparable EPS | BC3: Estimate EPS | BE3: Year/Period | BF3: Announcement Date | BG3: Announcement Time | BH3: Earnings EPS | BI3: Comparable EPS | BJ3: Estimate EPS | BL3: Year/Period | BM3: Announcement Date | BN3: Announcement Time | BO3: Earnings EPS | BP3: Comparable EPS | BQ3: Estimate EPS | BS3: Year/Period | BT3: Announcement Date | BU3: Announcement Time | BV3: Earnings EPS | BW3: Comparable EPS | BX3: Estimate EPS | BZ3: Year/Period | CA3: Announcement Date | CB3: Announcement Time | CC3: Earnings EPS | CD3: Comparable EPS | CE3: Estimate EPS | CG3: Year/Period | CH3: Announcement Date | CI3: Announcement Time | CJ3: Earnings EPS | CK3: Comparable EPS | CL3: Estimate EPS | CN3: Year/Period | CO3: Announcement Date | CP3: Announcement Time | CQ3: Earnings EPS | CR3: Comparable EPS | CS3: Estimate EPS | CU3: Year/Period | CV3: Announcement Date | CW3: Announcement Time | CX3: Earnings EPS | CY3: Comparable EPS | CZ3: Estimate EPS | DB3: Year/Period | DC3: Announcement Date | DD3: Announcement Time | DE3: Earnings EPS | DF3: Comparable EPS | DG3: Estimate EPS | DI3: Year/Period | DJ3: Announcement Date | DK3: Announcement Time | DL3: Earnings EPS | DM3: Comparable EPS | DN3: Estimate EPS | DP3: Year/Period | DQ3: Announcement Date | DR3: Announcement Time | DS3: Earnings EPS | DT3: Comparable EPS | DU3: Estimate EPS | DW3: Year/Period | DX3: Announcement Date | DY3: Announcement Time | DZ3: Earnings EPS | EA3: Comparable EPS | EB3: Estimate EPS | ED3: Year/Period | EE3: Announcement Date | EF3: Announcement Time | EG3: Earnings EPS | EH3: Comparable EPS | EI3: Estimate EPS | EK3: Year/Period | EL3: Announcement Date | EM3: Announcement Time | EN3: Earnings EPS | EO3: Comparable EPS | EP3: Estimate EPS | ER3: Year/Period | ES3: Announcement Date | ET3: Announcement Time | EU3: Earnings EPS | EV3: Comparable EPS | EW3: Estimate EPS | EY3: Year/Period | EZ3: Announcement Date | FA3: Announcement Time | FB3: Earnings EPS | FC3: Comparable EPS | FD3: Estimate EPS | FF3: Year/Period | FG3: Announcement Date | FH3: Announcement Time | FI3: Earnings EPS | FJ3: Comparable EPS | FK3: Estimate EPS | FM3: Year/Period | FN3: Announcement Date | FO3: Announcement Time | FP3: Earnings EPS | FQ3: Comparable EPS | FR3: Estimate EPS | FT3: Year/Period | FU3: Announcement Date | FV3: Announcement Time | FW3: Earnings EPS | FX3: Comparable EPS | FY3: Estimate EPS | GA3: Year/Period | GB3: Announcement Date | GC3: Announcement Time | GD3: Earnings EPS | GE3: Comparable EPS | GF3: Estimate EPS
A4: =_xll.BDS(A$2,EarnField,"cols=6;rows=126") -> 2026:Q3 | B4: 46233 | C4: 0.6875 | D4: 2.02 | E4: 2.02 | F4: 1.886 | H4: =_xll.BDS(H$2,EarnField,"cols=6;rows=112") -> 2026:Q2 | I4: 46233 | J4: 0.66736111 | K4: 5.75 | L4: 5.75 | M4: 1.828 | O4: =_xll.BDS(O$2,EarnField,"cols=6;rows=88") -> 2026:Q2 | P4: 46225 | Q4: 0.66736111 | R4: 9.11 | S4: 9.11 | T4: 2.903 | V4: =_xll.BDS(V$2,EarnField,"cols=6;rows=60") -> 2026:Q2 | W4: 46232 | X4: 0.66736111 | Y4: 6.18 | Z4: 6.18 | AA4: 7.147 | AC4: =_xll.BDS(AC$2,EarnField,"cols=6;rows=141") -> 2026:Q4 | AD4: 46232 | AE4: 0.67291667 | AF4: 4.4322 | AG4: 4.74 | AH4: 4.25 | AJ4: =_xll.BDS(AJ$2,EarnField,"cols=6;rows=98") -> 2026:Q3 | AK4: 46315 | AL4: 0.66736111 | AM4: -2.4245363e-14 | AN4: -2.4245363e-14 | AO4: 0.819 | AQ4: =_xll.BDS(AQ$2,EarnField,"cols=6;rows=109") -> 2027:Q2 | AR4: 46260 | AS4: 0.68055556 | AT4: 2.2142 | AU4: 2.22 | AV4: 2.087 | AX4: =_xll.BDS(AX$2,EarnField,"cols=6;rows=24") -> 2026:Q2 | AY4: 46237 | AZ4: 0.67013889 | BA4: 0.3909 | BB4: 0.41 | BC4: 0.347 | BE4: =_xll.BDS(BE$2,EarnField,"cols=6;rows=65") -> 2026:Q2 | BF4: 46225 | BG4: 0.66944444 | BH4: 0.0513 | BI4: 0.33 | BJ4: 0.506 | BL4: =_xll.BDS(BL$2,EarnField,"cols=6;rows=111") -> 2026:Q2 | BM4: 46219 | BN4: 0.57291667 | BO4: 126.2501 | BP4: 136.25 | BQ4: 120.489 | BS4: =_xll.BDS(BS$2,EarnField,"cols=6;rows=101") -> 2026:Q3 | BT4: 46267 | BU4: 0.67708333 | BV4: 2.7103 | BW4: 3.32 | BX4: 3.23 | BZ4: =_xll.BDS(BZ$2,EarnField,"cols=6;rows=110") -> 2026:Q2 | CA4: 46238 | CB4: 0.67708333 | CC4: 1.2008 | CD4: 1.66 | CE4: 1.616 | CG4: =_xll.BDS(CG$2,EarnField,"cols=6;rows=127") -> 2026:Q3 | CH4: 46197 | CI4: 0.66736111 | CJ4: 24.971 | CK4: 25.11 | CL4: 20.492 | CN4: =_xll.BDS(CN$2,EarnField,"cols=6;rows=110") -> 2026:Q2 | CO4: 46233 | CP4: 0.66736111 | CQ4: -6.0736 | CR4: -2.4245363e-14 | CS4: 1.545 | CU4: =_xll.BDS(CU$2,EarnField,"cols=6;rows=22") -> 2026:Q2 | CV4: 46233 | CW4: 0.67777778 | CX4: 0.4053 | CY4: -0.3982 | CZ4: -0.05 | DB4: =_xll.BDS(DB$2,EarnField,"cols=6;rows=21") -> 2026:Q2 | DC4: 46232 | DD4: 0.67222222 | DE4: 0.5282 | DF4: 0.62 | DG4: 0.445 | DI4: =_xll.BDS(DI$2,EarnField,"cols=6;rows=51") -> 2026:Q2 | DJ4: 46239 | DK4: 0.29375 | DL4: 0.3332 | DM4: 0.42 | DN4: 0.406 | DP4: =_xll.BDS(DP$2,EarnField,"cols=6;rows=78") -> 2026:Q4 | DQ4: 46245 | DR4: 0.67013889 | DS4: 1.6378 | DT4: 1.7 | DU4: 1.592 | DW4: =_xll.BDS(DW$2,EarnField,"cols=6;rows=111") -> 2027:Q1 | DX4: 46275 | DY4: 0.67361111 | DZ4: 1.5838 | EA4: 1.92 | EB4: 1.746 | ED4: =_xll.BDS(ED$2,EarnField,"cols=6;rows=89") -> 2027:Q2 | EE4: 46260 | EF4: 0.66736111 | EG4: 1.9955 | EH4: 5.9 | EI4: 3.279 | EK4: =_xll.BDS(EK$2,EarnField,"cols=6;rows=111") -> 2026:Q3 | EL4: 46275 | EM4: 0.67013889 | EN4: 4.6124 | EO4: 6.13 | EP4: 6.078 | ER4: =_xll.BDS(ER$2,EarnField,"cols=6;rows=57") -> 2026:Q2 | ES4: 46225 | ET4: 0.67361111 | EU4: 0.1175 | EV4: 0.9 | EW4: 0.869 | EY4: =_xll.BDS(EY$2,EarnField,"cols=6;rows=124") -> 2026:Q2 | EZ4: 46239 | FA4: 0.28125 | FB4: 11.27 | FC4: 8.38 | FD4: 6.005 | FF4: =_xll.BDS(FF$2,EarnField,"cols=6;rows=111") -> 2026:Q3 | FG4: 46308 | FH4: Bef-mkt | FI4: -2.4245363e-14 | FJ4: -2.4245363e-14 | FK4: 4.133 | FM4: =_xll.BDS(FM$2,EarnField,"cols=6;rows=122") -> 2027:Q4 | FN4: 46766 | FO4: 0.28125 | FP4: -2.4245363e-14 | FQ4: -2.4245363e-14 | FR4: 6.367 | FT4: =_xll.BDS(FT$2,EarnField,"cols=6;rows=114") -> 2026:Q4 | FU4: 46289 | FV4: 0.67708333 | FW4: -2.4245363e-14 | FX4: -2.4245363e-14 | FY4: 6.525 | GA4: =_xll.BDS(GA$2,EarnField,"cols=6;rows=122") -> 2026:Q2 | GB4: 46234 | GC4: 0.27083333 | GD4: 4.1119 | GE4: 3.52 | GF4: 3.538
A5: 2026:Q2 | B5: 46142 | C5: 0.6875 | D5: 2.01 | E5: 2.01 | F5: 1.964 | H5: 2026:Q1 | I5: 46141 | J5: 0.66736111 | K5: 2.78 | L5: 2.78 | M5: 1.623 | O5: 2026:Q1 | P5: 46141 | Q5: 0.66805556 | R5: 5.11 | S5: 5.11 | T5: 2.624 | V5: 2026:Q1 | W5: 46141 | X5: 0.68263889 | Y5: 10.44 | Z5: 10.44 | AA5: 6.646 | AC5: 2026:Q3 | AD5: 46141 | AE5: 0.68055556 | AF5: 4.2712 | AG5: 4.27 | AH5: 4.037 | AJ5: 2026:Q2 | AK5: 46219 | AL5: 0.66736111 | AM5: 0.8 | AN5: 0.8 | AO5: 0.788 | AQ5: 2027:Q1 | AR5: 46162 | AS5: 0.68055556 | AT5: 1.8645 | AU5: 1.87 | AV5: 1.775 | AX5: 2026:Q1 | AY5: 46146 | AZ5: 0.67013889 | BA5: 0.34 | BB5: 0.33 | BC5: 0.278 | BE5: 2026:Q1 | BF5: 46134 | BG5: 0.67152778 | BH5: 0.1789 | BI5: 0.41 | BJ5: 0.341 | BL5: 2026:Q1 | BM5: 46128 | BN5: 0.56597222 | BO5: 111.1863 | BP5: 110.4 | BQ5: 104.424 | BS5: 2026:Q2 | BT5: 46176 | BU5: 0.67708333 | BV5: 1.9383 | BW5: 2.44 | BX5: 2.395 | BZ5: 2026:Q1 | CA5: 46147 | CB5: 0.67708333 | CC5: 0.8088 | CD5: 1.37 | CE5: 1.283 | CG5: 2026:Q2 | CH5: 46099 | CI5: 0.66736111 | CJ5: 12.0712 | CK5: 12.2 | CL5: 9.125 | CN5: 2026:Q1 | CO5: 46147 | CP5: 0.66736111 | CQ5: -4.0501 | CR5: -38.25 | CS5: -18.153 | CU5: 2026:Q1 | CV5: 46149 | CW5: 0.67569444 | CX5: 0.5157 | CY5: -0.17 | CZ5: 0.295 | DB5: 2026:Q1 | DC5: 46140 | DD5: 0.67013889 | DE5: 0.38 | DF5: 0.38 | DG5: 0.424 | DI5: 2026:Q1 | DJ5: 46147 | DK5: 0.29166667 | DL5: 0.2641 | DM5: 0.36 | DN5: 0.329 | DP5: 2026:Q3 | DQ5: 46147 | DR5: 0.67013889 | DS5: 0.72 | DT5: 0.84 | DU5: 0.629 | DW5: 2026:Q4 | DX5: 46183 | DY5: 0.67013889 | DZ5: 1.5696 | EA5: 2.11 | EB5: 1.974 | ED5: 2027:Q1 | EE5: 46169 | EF5: 0.66736111 | EG5: 1.9872 | EH5: 3.88 | EI5: 3.125 | EK5: 2026:Q2 | EL5: 46184 | EM5: 0.67013889 | EN5: 4.4664 | EO5: 5.96 | EP5: 5.831 | ER5: 2026:Q1 | ES5: 46134 | ET5: 0.67361111 | EU5: 0.4277 | EV5: 0.97 | EW5: 0.972 | EY5: 2026:Q1 | EZ5: 46142 | FA5: 0.28125 | FB5: 8.9567 | FC5: 8.55 | FD5: 6.836 | FF5: 2026:Q2 | FG5: 46219 | FH5: 0.24652778 | FI5: 6.0822 | FJ5: 6.38 | FK5: 4.894 | FM5: 2027:Q3 | FN5: 46672 | FO5: 0.28125 | FP5: -2.4245363e-14 | FQ5: -2.4245363e-14 | FR5: 6.247 | FT5: 2026:Q3 | FU5: 46170 | FV5: 0.67708333 | FW5: 4.93 | FX5: 4.93 | FY5: 4.982 | GA5: 2026:Q1 | GB5: 46143 | GC5: 0.27083333 | GD5: 0.8275 | GE5: 1.16 | GF5: 0.953
A6: 2026:Q1 | B6: 46051 | C6: 0.6875 | D6: 2.84 | E6: 2.84 | F6: 2.68 | H6: 2025:Q4 | I6: 46058 | J6: 0.66736111 | K6: 1.95 | L6: 1.95 | M6: 1.958 | O6: 2025:Q4 | P6: 46057 | Q6: 0.66736111 | R6: 2.82 | S6: 2.82 | T6: 2.645 | V6: 2025:Q4 | W6: 46050 | X6: 0.66736111 | Y6: 8.88 | Z6: 8.88 | AA6: 8.186 | AC6: 2026:Q2 | AD6: 46050 | AE6: 0.66666667 | AF6: 4.109 | AG6: 4.14 | AH6: 3.922 | AJ6: 2026:Q1 | AK6: 46128 | AL6: 0.66805556 | AM6: 1.23 | AN6: 1.23 | AO6: 0.779 | AQ6: 2026:Q4 | AR6: 46078 | AS6: 0.69166667 | AT6: 1.5565 | AU6: 1.62 | AV6: 1.532 | AX6: 2025:Q4 | AY6: 46055 | AZ6: 0.67013889 | BA6: 0.245 | BB6: 0.25 | BC6: 0.229 | BE6: 2025:Q4 | BF6: 46050 | BG6: 0.66944444 | BH6: 0.3437 | BI6: 0.5 | BJ6: 0.447 | BL6: 2025:A | BM6: 46037 | BN6: 0.56458333 | BO6: 332.5793 | BP6: 331.25 | BQ6: 323.661 | BS6: 2026:Q1 | BT6: 46085 | BU6: 0.67708333 | BV6: 1.5258 | BW6: 2.05 | BX6: 2.03 | BZ6: 2025:Q4 | CA6: 46056 | CB6: 0.67708333 | CC6: 0.8672 | CD6: 1.53 | CE6: 1.323 | CG6: 2026:Q1 | CH6: 46008 | CI6: 0.66736111 | CJ6: 4.6183 | CK6: 4.78 | CL6: 3.951 | CN6: 2025:Q4 | CO6: 46058 | CP6: 0.66666667 | CQ6: 3.9217 | CR6: -42.93 | CS6: -0.05 | CU6: 2025:Q4 | CV6: 46065 | CW6: 0.67291667 | CX6: 1.3933 | CY6: 0.66 | CZ6: 0.886 | DB6: 2025:Q4 | DC6: 46063 | DD6: 0.67013889 | DE6: 0.66 | DF6: 0.66 | DG6: 0.638 | DI6: 2025:Q4 | DJ6: 46064 | DK6: 0.29305556 | DL6: 0.2804 | DM6: 0.48 | DN6: 0.513 | DP6: 2026:Q2 | DQ6: 46056 | DR6: 0.70208333 | DS6: 0.6 | DT6: 0.69 | DU6: 0.485 | DW6: 2026:Q3 | DX6: 46091 | DY6: 0.67013889 | DZ6: 1.3239 | EA6: 1.79 | EB6: 1.698 | ED6: 2026:Q4 | EE6: 46078 | EF6: 0.66736111 | EG6: 3.0577 | EH6: 3.81 | EI6: 3.055 | EK6: 2026:Q1 | EL6: 46093 | EM6: 0.67013889 | EN6: 4.7405 | EO6: 6.06 | EP6: 5.881 | ER6: 2025:Q4 | ES6: 46050 | ET6: 0.67361111 | EU6: 0.4796 | EV6: 0.92 | EW6: 0.889 | EY6: 2025:Q4 | EZ6: 46057 | FA6: 0.28125 | FB6: 7.8951 | FC6: 7.54 | FD6: 6.733 | FF6: 2026:Q1 | FG6: 46133 | FH6: 0.24652778 | FI6: 6.9229 | FJ6: 7.23 | FK6: 6.571 | FM6: 2027:Q2 | FN6: 46581 | FO6: 0.28125 | FP6: -2.4245363e-14 | FQ6: -2.4245363e-14 | FR6: 6.212 | FT6: 2026:Q2 | FU6: 46086 | FV6: 0.67708333 | FW6: 4.579 | FX6: 4.58 | FY6: 4.549 | GA6: 2025:Q4 | GB6: 46052 | GC6: 0.27083333 | GD6: 1.7084 | GE6: 1.71 | GF6: 1.701
A7: 2025:Q4 | B7: 45960 | C7: 0.6875 | D7: 1.85 | E7: 1.85 | F7: 1.774 | H7: 2025:Q3 | I7: 45960 | J7: 0.66736111 | K7: 1.95 | L7: 1.95 | M7: 1.556 | O7: 2025:Q3 | P7: 45959 | Q7: 0.66805556 | R7: 2.87 | S7: 2.87 | T7: 2.268 | V7: 2025:Q3 | W7: 45959 | X7: 0.67013889 | Y7: 1.05 | Z7: 1.05 | AA7: 6.742 | AC7: 2026:Q1 | AD7: 45959 | AE7: 0.66805556 | AF7: 3.7805 | AG7: 4.13 | AH7: 3.676 | AJ7: 2025:Q4 | AK7: 46042 | AL7: 0.67222222 | AM7: 0.56 | AN7: 0.56 | AO7: 0.546 | AQ7: 2026:Q3 | AR7: 45980 | AS7: 0.68055556 | AT7: 1.319 | AU7: 1.3 | AV7: 1.259 | AX7: 2025:Q3 | AY7: 45964 | AZ7: 0.67013889 | BA7: 0.1817 | BB7: 0.21 | BC7: 0.168 | BE7: 2025:Q3 | BF7: 45952 | BG7: 0.66875 | BH7: 0.4257 | BI7: 0.5 | BJ7: 0.537 | BL7: 2025:Q3 | BM7: 45946 | BN7: 0.56388889 | BO7: 88.3511 | BP7: 87.2 | BQ7: 79 | BS7: 2025:Q4 | BT7: 46002 | BU7: 0.67708333 | BV7: 2.162 | BW7: 1.95 | BX7: 1.867 | BZ7: 2025:Q3 | CA7: 45965 | CB7: 0.67708333 | CC7: 0.7248 | CD7: 1.2 | CE7: 1.168 | CG7: 2025:Q4 | CH7: 45923 | CI7: 0.66736111 | CJ7: 2.884 | CK7: 3.03 | CL7: 2.842 | CN7: 2025:Q3 | CO7: 45960 | CP7: 0.68194444 | CQ7: -1.5073 | CR7: 8.8301 | CS7: 15.865 | CU7: 2025:Q3 | CV7: 45960 | CW7: 0.675 | CX7: 1.9516 | CY7: 1.44 | CZ7: 1.206 | DB7: 2025:Q3 | DC7: 45966 | DD7: 0.67013889 | DE7: 0.61 | DF7: 0.61 | DG7: 0.526 | DI7: 2025:Q3 | DJ7: 45965 | DK7: 0.29236111 | DL7: 0.2539 | DM7: 0.34 | DN7: 0.328 | DP7: 2026:Q1 | DQ7: 45965 | DR7: 0.67013889 | DS7: 0.2743 | DT7: 0.35 | DU7: 0.416 | DW7: 2026:Q2 | DX7: 46001 | DY7: 0.67013889 | DZ7: 2.1397 | EA7: 2.26 | EB7: 1.638 | ED7: 2026:Q3 | EE7: 45994 | EF7: 0.66736111 | EG7: 2.1609 | EH7: 3.25 | EI7: 2.86 | EK7: 2025:Q4 | EL7: 46001 | EM7: 0.67013889 | EN7: 4.429 | EO7: 5.5 | EP7: 5.39 | ER7: 2025:Q3 | ES7: 45959 | ET7: 0.67361111 | EU7: 0.5167 | EV7: 0.964 | EW7: 0.854 | EY7: 2025:Q3 | EZ7: 45960 | FA7: 0.28125 | FB7: 7.4826 | FC7: 7.02 | FD7: 5.711 | FF7: 2025:Q4 | FG7: 46049 | FH7: 0.25 | FI7: 2.1415 | FJ7: 2.11 | FK7: 2.102 | FM7: 2027:Q1 | FN7: 46490 | FO7: 0.28125 | FP7: -2.4245363e-14 | FQ7: -2.4245363e-14 | FR7: 6.176 | FT7: 2026:Q1 | FU7: 46002 | FV7: 0.67708333 | FW7: 4.5 | FX7: 4.5 | FY7: 4.278 | GA7: 2025:Q3 | GB7: 45961 | GC7: 0.27083333 | GD7: 1.641 | GE7: 1.88 | GF7: 1.813
A8: 2025:Q3 | B8: 45869 | C8: 0.6875 | D8: 1.57 | E8: 1.57 | F8: 1.433 | H8: 2025:Q2 | I8: 45869 | J8: 0.66736111 | K8: 1.68 | L8: 1.68 | M8: 1.32 | O8: 2025:Q2 | P8: 45861 | Q8: 0.67013889 | R8: 2.31 | S8: 2.31 | T8: 2.177 | V8: 2025:Q2 | W8: 45868 | X8: 0.67638889 | Y8: 7.14 | Z8: 7.14 | AA8: 5.887 | AC8: 2025:Q4 | AD8: 45868 | AE8: 0.66805556 | AF8: 3.6633 | AG8: 3.65 | AH8: 3.373 | AJ8: 2025:Q3 | AK8: 45951 | AL8: 0.66805556 | AM8: 0.587 | AN8: 0.587 | AO8: 0.695 | AQ8: 2026:Q2 | AR8: 45896 | AS8: 0.68055556 | AT8: 0.972 | AU8: 1.05 | AV8: 1.014 | AX8: 2025:Q2 | AY8: 45873 | AZ8: 0.67013889 | BA8: 0.1266 | BB8: 0.16 | BC8: 0.139 | BE8: 2025:Q2 | BF8: 45861 | BG8: 0.67361111 | BH8: 0.2669 | BI8: 0.4 | BJ8: 0.423 | BL8: 2025:Q2 | BM8: 45855 | BN8: 0.56805556 | BO8: 75.1121 | BP8: 76.8 | BQ8: 72.765 | BS8: 2025:Q3 | BT8: 45904 | BU8: 0.67708333 | BV8: 0.9153 | BW8: 1.69 | BX8: 1.666 | BZ8: 2025:Q2 | CA8: 45874 | CB8: 0.67708333 | CC8: 0.489 | CD8: 0.48 | CE8: 0.488 | CG8: 2025:Q3 | CH8: 45833 | CI8: 0.66736111 | CJ8: 1.7584 | CK8: 1.91 | CL8: 1.599 | CN8: 2025:Q2 | CO8: 45869 | CP8: 0.66736111 | CQ8: -4.0902 | CR8: 32.52 | CS8: -0.092 | CU8: 2025:Q2 | CV8: 45869 | CW8: 0.67013889 | CX8: 1.6746 | CY8: 0.12 | CZ8: 1.303 | DB8: 2025:Q2 | DC8: 45868 | DD8: 0.67013889 | DE8: 0.42 | DF8: 0.42 | DG8: 0.314 | DI8: 2025:Q2 | DJ8: 45875 | DK8: 0.29583333 | DL8: 0.2492 | DM8: 0.35 | DN8: 0.289 | DP8: 2025:Q4 | DQ8: 45874 | DR8: 0.67013889 | DS8: 0.31 | DT8: 0.41 | DU8: 0.441 | DW8: 2026:Q1 | DX8: 45909 | DY8: 0.67013889 | DZ8: 1.1087 | EA8: 1.47 | EB8: 1.48 | ED8: 2026:Q2 | EE8: 45903 | EF8: 0.66736111 | EG8: 1.9583 | EH8: 2.91 | EI8: 2.777 | EK8: 2025:Q3 | EL8: 45911 | EM8: 0.67013889 | EN8: 4.1349 | EO8: 5.31 | EP8: 5.179 | ER8: 2025:Q2 | ES8: 45861 | ET8: 0.67361111 | EU8: 0.4228 | EV8: 0.818 | EW8: 0.716 | EY8: 2025:Q2 | EZ8: 45876 | FA8: 0.28125 | FB8: 6.3372 | FC8: 6.31 | FD8: 5.566 | FF8: 2025:Q3 | FG8: 45958 | FH8: 0.24652778 | FI8: 2.6622 | FJ8: 2.92 | FK8: 2.826 | FM8: 2026:Q4 | FN8: 46401 | FO8: 0.28125 | FP8: -2.4245363e-14 | FQ8: -2.4245363e-14 | FR8: 5.92 | FT8: 2025:Q4 | FU8: 45925 | FV8: 0.67708333 | FW8: 5.6888 | FX8: 5.87 | FY8: 5.816 | GA8: 2025:Q2 | GB8: 45870 | GC8: 0.27083333 | GD8: 1.64 | GE8: 1.64 | GF8: 1.575
A9: 2025:Q2 | B9: 45778 | C9: 0.6875 | D9: 1.65 | E9: 1.65 | F9: 1.625 | H9: 2025:Q1 | I9: 45778 | J9: 0.66736111 | K9: 1.59 | L9: 1.59 | M9: 1.358 | O9: 2025:Q1 | P9: 45771 | Q9: 0.66736111 | R9: 2.81 | S9: 2.81 | T9: 2.007 | V9: 2025:Q1 | W9: 45777 | X9: 0.67013889 | Y9: 6.43 | Z9: 6.43 | AA9: 5.256 | AC9: 2025:Q3 | AD9: 45777 | AE9: 0.66666667 | AF9: 3.4489 | AG9: 3.46 | AH9: 3.214 | AJ9: 2025:Q2 | AK9: 45855 | AL9: 0.67013889 | AM9: 0.719 | AN9: 0.719 | AO9: 0.707 | AQ9: 2026:Q1 | AR9: 45805 | AS9: 0.68055556 | AT9: 0.7684 | AU9: 0.81 | AV9: 0.927 | AX9: 2025:Q1 | AY9: 45782 | AZ9: 0.67013889 | BA9: 0.0833 | BB9: 0.13 | BC9: 0.129 | BE9: 2025:Q1 | BF9: 45769 | BG9: 0.67013889 | BH9: 0.1686 | BI9: 0.27 | BJ9: 0.434 | BL9: 2025:Q1 | BM9: 45764 | BN9: 0.57152778 | BO9: 70.2373 | BP9: 69.7 | BQ9: 67.881 | BS9: 2025:Q2 | BT9: 45813 | BU9: 0.67708333 | BV9: 1.0787 | BW9: 1.58 | BX9: 1.56 | BZ9: 2025:Q1 | CA9: 45783 | CB9: 0.67708333 | CC9: 0.4617 | CD9: 0.96 | CE9: 0.943 | CG9: 2025:Q2 | CH9: 45736 | CI9: 0.66666667 | CJ9: 1.4242 | CK9: 1.56 | CL9: 1.403 | CN9: 2025:Q1 | CO9: 45778 | CP9: 0.66736111 | CQ9: 1.702 | CR9: -16.53 | CS9: -0.042 | CU9: 2025:Q1 | CV9: 45785 | CW9: 0.67569444 | CX9: 2.9222 | CY9: 1.94 | CZ9: 2.072 | DB9: 2025:Q1 | DC9: 45777 | DD9: 0.67013889 | DE9: 0.37 | DF9: 0.37 | DG9: 0.336 | DI9: 2025:Q1 | DJ9: 45785 | DK9: 0.29166667 | DL9: 0.1682 | DM9: 0.25 | DN9: 0.257 | DP9: 2025:Q3 | DQ9: 45783 | DR9: 0.67013889 | DS9: 0.2061 | DT9: 0.31 | DU9: 0.373 | DW9: 2025:Q4 | DX9: 45819 | DY9: 0.67013889 | DZ9: 1.2883 | EA9: 1.7 | EB9: 1.643 | ED9: 2026:Q1 | EE9: 45805 | EF9: 0.66805556 | EG9: 1.6702 | EH9: 2.58 | EI9: 2.549 | EK9: 2025:Q2 | EL9: 45820 | EM9: 0.67013889 | EN9: 3.936 | EO9: 5.06 | EP9: 4.975 | ER9: 2025:Q1 | ES9: 45770 | ET9: 0.67361111 | EU9: 0.4481 | EV9: 0.808 | EW9: 0.767 | EY9: 2025:Q1 | EZ9: 45778 | FA9: 0.28125 | FB9: 4.6028 | FC9: 3.34 | FD9: 3.102 | FF9: 2025:Q2 | FG9: 45867 | FH9: 0.24652778 | FI9: 3.7756 | FJ9: 4.08 | FK9: 4.589 | FM9: 2026:Q3 | FN9: 46308 | FO9: 0.29166667 | FP9: -2.4245363e-14 | FQ9: -2.4245363e-14 | FR9: 5.822 | FT9: 2025:Q3 | FU9: 45806 | FV9: 0.67708333 | FW9: 4.28 | FX9: 4.28 | FY9: -2.4245363e-14 | GA9: 2025:Q1 | GB9: 45779 | GC9: 0.27083333 | GD9: 1.76 | GE9: 1.76 | GF9: 1.763
A10: 2025:Q1 | B10: 45687 | C10: 0.6875 | D10: 2.4 | E10: 2.4 | F10: 2.35 | H10: 2024:Q4 | I10: 45694 | J10: 0.66736111 | K10: 1.86 | L10: 1.86 | M10: 1.474 | O10: 2024:Q4 | P10: 45692 | Q10: 0.66736111 | R10: 2.15 | S10: 2.15 | T10: 2.133 | V10: 2024:Q4 | W10: 45686 | X10: 0.69444444 | Y10: 8.02 | Z10: 8.02 | AA10: 6.783 | AC10: 2025:Q2 | AD10: 45686 | AE10: 0.66666667 | AF10: 3.2331 | AG10: 3.23 | AH10: 3.124 | AJ10: 2025:Q1 | AK10: 45764 | AL10: 0.66875 | AM10: 0.661 | AN10: 0.661 | AO10: 0.569 | AQ10: 2025:Q4 | AR10: 45714 | AS10: 0.68055556 | AT10: 0.8908 | AU10: 0.89 | AV10: 0.839 | AX10: 2024:Q4 | AY10: 45691 | AZ10: 0.67013889 | BA10: 0.0279 | BB10: 0.14 | BC10: 0.111 | BE10: 2024:Q4 | BF10: 45686 | BG10: 0.66875 | BH10: 0.5293 | BI10: 0.73 | BJ10: 0.752 | BL10: 2024:A | BM10: 45673 | BN10: 0.56458333 | BO10: 227.6366 | BP10: 226.25 | BQ10: 224.592 | BS10: 2025:Q1 | BT10: 45722 | BU10: 0.67708333 | BV10: 1.184 | BW10: 1.6 | BX10: 1.503 | BZ10: 2024:Q4 | CA10: 45692 | CB10: 0.67708333 | CC10: 0.4078 | CD10: 1.09 | CE10: 1.088 | CG10: 2025:Q1 | CH10: 45644 | CI10: 0.66736111 | CJ10: 1.6661 | CK10: 1.79 | CL10: 1.763 | CN10: 2024:Q4 | CO10: 45693 | CP10: 0.66875 | CQ10: 0.5564 | CR10: -3.2 | CS10: 0.04 | CU10: 2024:Q4 | CV10: 45701 | CW10: 0.67013889 | CX10: 4.1795 | CY10: 4.68 | CZ10: 2.211 | DB10: 2024:Q4 | DC10: 45700 | DD10: 0.67013889 | DE10: 0.9665 | DF10: 1.01 | DG10: 0.433 | DI10: 2024:Q4 | DJ10: 45699 | DK10: 0.29513889 | DL10: 0.3405 | DM10: 0.44 | DN10: 0.425 | DP10: 2025:Q2 | DQ10: 45713 | DR10: 0.70138889 | DS10: 0.51 | DT10: 0.51 | DU10: 0.618 | DW10: 2025:Q3 | DX10: 45726 | DY10: 0.67013889 | DZ10: 1.0423 | EA10: 1.47 | EB10: 1.49 | ED10: 2025:Q4 | EE10: 45714 | EF10: 0.66736111 | EG10: 1.8782 | EH10: 2.78 | EI10: 2.612 | EK10: 2025:Q1 | EL10: 45728 | EM10: 0.67013889 | EN10: 4.1296 | EO10: 5.08 | EP10: 4.972 | ER10: 2024:Q4 | ES10: 45686 | ET10: 0.67361111 | EU10: 0.3815 | EV10: 0.734 | EW10: 0.735 | EY10: 2024:Q4 | EZ10: 45694 | FA10: 0.28125 | FB10: 5.3638 | FC10: 5.32 | FD10: 5.035 | FF10: 2025:Q1 | FG10: 45764 | FH10: 0.24652778 | FI10: 6.8629 | FJ10: 7.2 | FK10: 7.274 | FM10: 2026:Q2 | FN10: 46217 | FO10: 0.27638889 | FP10: 7.7469 | FQ10: 6.14 | FR10: 5.729 | FT10: 2025:Q2 | FU10: 45722 | FV10: 0.67708333 | FW10: 4.02 | FX10: 4.02 | FY10: 4.113 | GA10: 2024:Q4 | GB10: 45688 | GC10: 0.27083333 | GD10: 1.6711 | GE10: 1.67 | GF10: 1.548
A11: 2024:Q4 | B11: 45596 | C11: 0.6875 | D11: 1.6422 | E11: 1.64 | F11: 1.516 | H11: 2024:Q3 | I11: 45596 | J11: 0.66736111 | K11: 1.43 | L11: 1.43 | M11: 1.143 | O11: 2024:Q3 | P11: 45594 | Q11: 0.66805556 | R11: 2.12 | S11: 2.12 | T11: 1.84 | V11: 2024:Q3 | W11: 45595 | X11: 0.67013889 | Y11: 6.03 | Z11: 6.03 | AA11: 5.251 | AC11: 2025:Q1 | AD11: 45595 | AE11: 0.66666667 | AF11: 3.3367 | AG11: 3.3 | AH11: 3.11 | AJ11: 2024:Q4 | AK11: 45678 | AL11: 0.66805556 | AM11: 0.427 | AN11: 0.427 | AO11: 0.417 | AQ11: 2025:Q3 | AR11: 45616 | AS11: 0.68055556 | AT11: 0.7824 | AU11: 0.81 | AV11: 0.745 | AX11: 2024:Q3 | AY11: 45600 | AZ11: 0.67013889 | BA11: 0.0619 | BB11: 0.1 | BC11: 0.09 | BE11: 2024:Q3 | BF11: 45588 | BG11: 0.66875 | BH11: 0.6541 | BI11: 0.72 | BJ11: 0.596 | BL11: 2024:Q3 | BM11: 45582 | BN11: 0.56597222 | BO11: 62.4804 | BP11: 62.7 | BQ11: 57.77 | BS11: 2024:Q4 | BT11: 45638 | BU11: 0.67708333 | BV11: 0.942 | BW11: 1.42 | BX11: 1.359 | BZ11: 2024:Q3 | CA11: 45594 | CB11: 0.67708333 | CC11: 0.4877 | CD11: 0.92 | CE11: 0.919 | CG11: 2024:Q4 | CH11: 45560 | CI11: 0.67152778 | CJ11: 0.8477 | CK11: 1.18 | CL11: 1.116 | CN11: 2024:Q3 | CO11: 45595 | CP11: 0.66736111 | CQ11: 0.0074 | CR11: -1.56 | CS11: -0.003 | CU11: 2024:Q3 | CV11: 45595 | CW11: 0.67083333 | CX11: 1.143 | CY11: 0.28 | CZ11: 0.423 | DB11: 2024:Q3 | DC11: 45595 | DD11: 0.67013889 | DE11: 0.1786 | DF11: 0.17 | DG11: 0.178 | DI11: 2024:Q3 | DJ11: 45608 | DK11: 0.29166667 | DL11: 0.2416 | DM11: 0.33 | DN11: 0.269 | DP11: 2025:Q1 | DQ11: 45601 | DR11: 0.67708333 | DS11: 0.067 | DT11: 0.073 | DU11: 0.752 | DW11: 2025:Q2 | DX11: 45635 | DY11: 0.67013889 | DZ11: 1.1226 | EA11: 1.47 | EB11: 1.48 | ED11: 2025:Q3 | EE11: 45629 | EF11: 0.66736111 | EG11: 1.7951 | EH11: 2.41 | EI11: 2.44 | EK11: 2024:Q4 | EL11: 45637 | EM11: 0.67013889 | EN11: 3.9098 | EO11: 4.81 | EP11: 4.669 | ER11: 2024:Q3 | ES11: 45588 | ET11: 0.67361111 | EU11: 0.4169 | EV11: 0.744 | EW11: 0.691 | EY11: 2024:Q3 | EZ11: 45595 | FA11: 0.28125 | FB11: 3.5184 | FC11: 1.18 | FD11: 1.527 | FF11: 2024:Q4 | FG11: 45673 | FH11: 0.24652778 | FI11: 6.4449 | FJ11: 6.81 | FK11: 6.709 | FM11: 2026:Q1 | FN11: 46126 | FO11: 0.27291667 | FP11: 6.035 | FQ11: 5.94 | FR11: 5.406 | FT11: 2025:Q1 | FU11: 45638 | FV11: 0.67708333 | FW11: 4.04 | FX11: 4.04 | FY11: 3.809 | GA11: 2024:Q3 | GB11: 45597 | GC11: 0.27083333 | GD11: 1.92 | GE11: 1.92 | GF11: 1.866
A12: 2024:Q3 | B12: 45505 | C12: 0.6875 | D12: 1.4 | E12: 1.4 | F12: 1.347 | H12: 2024:Q2 | I12: 45505 | J12: 0.66736111 | K12: 1.26 | L12: 1.26 | M12: 1.018 | O12: 2024:Q2 | P12: 45496 | Q12: 0.66805556 | R12: 1.89 | S12: 1.89 | T12: 1.844 | V12: 2024:Q2 | W12: 45504 | X12: 0.67013889 | Y12: 5.16 | Z12: 5.16 | AA12: 4.752 | AC12: 2024:Q4 | AD12: 45503 | AE12: 0.66666667 | AF12: 2.9558 | AG12: 2.95 | AH12: 2.939 | AJ12: 2024:Q3 | AK12: 45582 | AL12: 0.66666667 | AM12: 0.54 | AN12: 0.54 | AO12: 0.512 | AQ12: 2025:Q2 | AR12: 45532 | AS12: 0.68055556 | AT12: 0.6693 | AU12: 0.68 | AV12: 0.616 | AX12: 2024:Q2 | AY12: 45509 | AZ12: 0.67013889 | BA12: 0.0625 | BB12: 0.09 | BC12: 0.081 | BE12: 2024:Q2 | BF12: 45496 | BG12: 0.66875 | BH12: 0.5636 | BI12: 0.52 | BJ12: 0.615 | BL12: 2024:Q2 | BM12: 45491 | BN12: 0.56319444 | BO12: 48.1339 | BP12: 47.8 | BQ12: 45.552 | BS12: 2024:Q3 | BT12: 45540 | BU12: 0.67708333 | BV12: 0.7303 | BW12: 1.24 | BX12: 1.564 | BZ12: 2024:Q2 | CA12: 45503 | CB12: 0.67708333 | CC12: 0.1797 | CD12: 0.69 | CE12: 0.684 | CG12: 2024:Q3 | CH12: 45469 | CI12: 0.66944444 | CJ12: 0.449 | CK12: 0.62 | CL12: 0.501 | CN12: 2024:Q2 | CO12: 45505 | CP12: 0.66736111 | CQ12: 0.2223 | CR12: -0.762 | CS12: 0.018 | CU12: 2024:Q2 | CV12: 45505 | CW12: 0.67569444 | CX12: 1.8626 | CY12: 0.14 | CZ12: 0.867 | DB12: 2024:Q2 | DC12: 45511 | DD12: 0.67013889 | DE12: 0.21 | DF12: 0.21 | DG12: 0.148 | DI12: 2024:Q2 | DJ12: 45511 | DK12: 0.29305556 | DL12: 0.1458 | DM12: 0.26 | DN12: 0.202 | DP12: 2024:Q4 | DQ12: 45510 | DR12: 0.67916667 | DS12: 0.4633 | DT12: 0.625 | DU12: 0.812 | DW12: 2025:Q1 | DX12: 45544 | DY12: 0.67013889 | DZ12: 1.0482 | EA12: 1.39 | EB12: 1.334 | ED12: 2025:Q2 | EE12: 45532 | EF12: 0.66736111 | EG12: 1.5797 | EH12: 2.56 | EI12: 2.353 | EK12: 2024:Q3 | EL12: 45547 | EM12: 0.67013889 | EN12: 3.6438 | EO12: 4.65 | EP12: 4.535 | ER12: 2024:Q2 | ES12: 45497 | ET12: 0.67361111 | EU12: 0.2614 | EV12: 0.626 | EW12: 0.573 | EY12: 2024:Q2 | EZ12: 45512 | FA12: 0.28125 | FB12: 3.9275 | FC12: 3.92 | FD12: 2.619 | FF12: 2024:Q3 | FG12: 45580 | FH12: 0.24652778 | FI12: 6.8046 | FJ12: 7.15 | FK12: 6.987 | FM12: 2025:Q4 | FN12: 46035 | FO12: 0.27847222 | FP12: 4.6484 | FQ12: 5.23 | FR12: 5.005 | FT12: 2024:Q4 | FU12: 45561 | FV12: 0.67708333 | FW12: 5.3362 | FX12: 5.29 | FY12: 5.067 | GA12: 2024:Q2 | GB12: 45506 | GC12: 0.27083333 | GD12: 2.14 | GE12: 2.14 | GF12: 2.052
A13: 2024:Q2 | B13: 45414 | C13: 0.6875 | D13: 1.53 | E13: 1.53 | F13: 1.502 | H13: 2024:Q1 | I13: 45412 | J13: 0.66736111 | K13: 0.98 | L13: 0.98 | M13: 0.823 | O13: 2024:Q1 | P13: 45407 | Q13: 0.66805556 | R13: 1.89 | S13: 1.89 | T13: 1.523 | V13: 2024:Q1 | W13: 45406 | X13: 0.67013889 | Y13: 4.71 | Z13: 4.71 | AA13: 4.273 | AC13: 2024:Q3 | AD13: 45407 | AE13: 0.66666667 | AF13: 2.9384 | AG13: 2.94 | AH13: 2.831 | AJ13: 2024:Q2 | AK13: 45491 | AL13: 0.66805556 | AM13: 0.488 | AN13: 0.488 | AO13: 0.474 | AQ13: 2025:Q1 | AR13: 45434 | AS13: 0.68055556 | AT13: 0.5989 | AU13: 0.612 | AV13: 0.563 | AX13: 2024:Q1 | AY13: 45418 | AZ13: 0.67013889 | BA13: 0.0441 | BB13: 0.08 | BC13: 0.079 | BE13: 2024:Q1 | BF13: 45405 | BG13: 0.66875 | BH13: 0.3351 | BI13: 0.45 | BJ13: 0.531 | BL13: 2024:Q1 | BM13: 45400 | BN13: 0.56388889 | BO13: 43.9798 | BP13: 43.5 | BQ13: 40.318 | BS13: 2024:Q2 | BT13: 45455 | BU13: 0.67708333 | BV13: 0.5174 | BW13: 1.096 | BX13: 1.081 | BZ13: 2024:Q1 | CA13: 45412 | CB13: 0.67708333 | CC13: 0.0846 | CD13: 0.62 | CE13: 0.622 | CG13: 2024:Q2 | CH13: 45371 | CI13: 0.67083333 | CJ13: 0.2712 | CK13: 0.42 | CL13: -0.24 | CN13: 2024:Q1 | CO13: 45411 | CP13: 0.66736111 | CQ13: 0.5715 | CR13: -0.826 | CS13: 0.034 | CU13: 2024:Q1 | CV13: 45414 | CW13: 0.66875 | CX13: 2.9313 | CY13: 4.4 | CZ13: 1.072 | DB13: 2024:Q1 | DC13: 45420 | DD13: 0.67013889 | DE13: 0.18 | DF13: 0.18 | DG13: 0.064 | DI13: 2024:Q1 | DJ13: 45420 | DK13: 0.29166667 | DL13: 0.1012 | DM13: 0.2 | DN13: 0.172 | DP13: 2024:Q3 | DQ13: 45412 | DR13: 0.67013889 | DS13: 0.656 | DT13: 0.7365 | DU13: 0.558 | DW13: 2024:Q4 | DX13: 45454 | DY13: 0.67013889 | DZ13: 1.1603 | EA13: 1.63 | EB13: 1.645 | ED13: 2025:Q1 | EE13: 45441 | EF13: 0.66736111 | EG13: 1.5361 | EH13: 2.44 | EI13: 2.369 | EK13: 2024:Q2 | EL13: 45456 | EM13: 0.67013889 | EN13: 3.481 | EO13: 4.48 | EP13: 4.4 | ER13: 2024:Q1 | ES13: 45406 | ET13: 0.67361111 | EU13: 0.3583 | EV13: 0.682 | EW13: 0.631 | EY13: 2024:Q1 | EZ13: 45412 | FA13: 0.28125 | FB13: 2.5559 | FC13: 2.58 | FD13: 2.436 | FF13: 2024:Q2 | FG13: 45489 | FH13: 0.24652778 | FI13: 6.3309 | FJ13: 6.8 | FK13: 6.604 | FM13: 2025:Q3 | FN13: 45944 | FO13: 0.27152778 | FP13: 5.0797 | FQ13: 5.07 | FR13: 4.831 | FT13: 2024:Q3 | FU13: 45442 | FV13: 0.67708333 | FW13: 3.7178 | FX13: 3.78 | FY13: -2.4245363e-14 | GA13: 2024:Q1 | GB13: 45408 | GC13: 0.27083333 | GD13: 2.06 | GE13: 2.06 | GF13: 2.168
A14: 2024:Q1 | B14: 45323 | C14: 0.6875 | D14: 2.18 | E14: 2.18 | F14: 2.102 | H14: 2023:Q4 | I14: 45323 | J14: 0.66736111 | K14: 1 | L14: 1.0088 | M14: 0.791 | O14: 2023:Q4 | P14: 45321 | Q14: 0.66805556 | R14: 1.64 | S14: 1.64 | T14: 1.591 | V14: 2023:Q4 | W14: 45323 | X14: 0.67013889 | Y14: 5.33 | Z14: 5.33 | AA14: 4.924 | AC14: 2024:Q2 | AD14: 45321 | AE14: 0.66666667 | AF14: 2.9681 | AG14: 2.93 | AH14: 2.778 | AJ14: 2024:Q1 | AK14: 45400 | AL14: 0.66666667 | AM14: 0.528 | AN14: 0.528 | AO14: 0.451 | AQ14: 2024:Q4 | AR14: 45343 | AS14: 0.68055556 | AT14: 0.49 | AU14: 0.516 | AV14: 0.462 | AX14: 2023:Q4 | AY14: 45327 | AZ14: 0.67013889 | BA14: 0.0405 | BB14: 0.08 | BC14: 0.076 | BE14: 2023:Q4 | BF14: 45315 | BG14: 0.67152778 | BH14: 0.5727 | BI14: 0.71 | BJ14: 0.733 | BL14: 2023:A | BM14: 45309 | BN14: 0.56527778 | BO14: 160.7596 | BP14: 161.7 | BQ14: 158.772 | BS14: 2024:Q1 | BT14: 45358 | BU14: 0.67708333 | BV14: 0.4482 | BW14: 1.099 | BX14: 1.042 | BZ14: 2023:Q4 | CA14: 45321 | CB14: 0.67708333 | CC14: 0.4284 | CD14: 0.77 | CE14: 0.771 | CG14: 2024:Q1 | CH14: 45280 | CI14: 0.66944444 | CJ14: -1.0834 | CK14: -0.95 | CL14: -0.994 | CN14: 2023:Q4 | CO14: 45328 | CP14: 0.66736111 | CQ14: 0.6647 | CR14: 0.562 | CS14: 0.064 | CU14: 2023:Q4 | CV14: 45337 | CW14: 0.67638889 | CX14: 1.6105 | CY14: 1.04 | CZ14: 0.004 | DB14: 2023:Q4 | DC14: 45335 | DD14: 0.66944444 | DE14: 0.03 | DF14: 0.03 | DG14: -0.009 | DI14: 2023:Q4 | DJ14: 45335 | DK14: 0.29166667 | DL14: 0.2482 | DM14: 0.34 | DN14: 0.301 | DP14: 2024:Q2 | DQ14: 45320 | DR14: 0.67013889 | DS14: 0.51 | DT14: 0.559 | DU14: 0.507 | DW14: 2024:Q3 | DX14: 45362 | DY14: 0.67013889 | DZ14: 0.9173 | EA14: 1.41 | EB14: 1.378 | ED14: 2024:Q4 | EE14: 45350 | EF14: 0.66736111 | EG14: 1.6073 | EH14: 2.29 | EI14: 2.266 | EK14: 2024:Q1 | EL14: 45365 | EM14: 0.67013889 | EN14: 3.3452 | EO14: 4.48 | EP14: 4.376 | ER14: 2023:Q4 | ES14: 45315 | ET14: 0.67361111 | EU14: 0.2966 | EV14: 0.622 | EW14: 0.557 | EY14: 2023:Q4 | EZ14: 45328 | FA14: 0.28125 | FB14: 3.1255 | FC14: 2.49 | FD14: 2.235 | FF14: 2024:Q1 | FG14: 45398 | FH14: 0.24652778 | FI14: 6.6457 | FJ14: 6.91 | FK14: 6.589 | FM14: 2025:Q2 | FN14: 45853 | FO14: 0.27152778 | FP14: 5.0153 | FQ14: 4.96 | FR14: 4.474 | FT14: 2024:Q2 | FU14: 45358 | FV14: 0.67708333 | FW14: 3.92 | FX14: 3.92 | FY14: 3.617 | GA14: 2023:Q4 | GB14: 45324 | GC14: 0.27083333 | GD14: 2.4845 | GE14: 2.48 | GF14: 2.199
A15: 2023:Q4 | B15: 45232 | C15: 0.6875 | D15: 1.46 | E15: 1.46 | F15: 1.395 | H15: 2023:Q3 | I15: 45225 | J15: 0.66736111 | K15: 0.94 | L15: 0.8266 | M15: 0.574 | O15: 2023:Q3 | P15: 45223 | Q15: 0.66736111 | R15: 1.55 | S15: 1.55 | T15: 1.444 | V15: 2023:Q3 | W15: 45224 | X15: 0.67777778 | Y15: 4.39 | Z15: 4.39 | AA15: 3.574 | AC15: 2024:Q1 | AD15: 45223 | AE15: 0.66944444 | AF15: 2.9753 | AG15: 2.99 | AH15: 2.654 | AJ15: 2023:Q4 | AK15: 45314 | AL15: 0.66666667 | AM15: 0.211 | AN15: 0.211 | AO15: 0.219 | AQ15: 2024:Q3 | AR15: 45251 | AS15: 0.68055556 | AT15: 0.3769 | AU15: 0.402 | AV15: 0.336 | AX15: 2023:Q3 | AY15: 45232 | AZ15: 0.29166667 | BA15: 0.0302 | BB15: 0.07 | BC15: 0.057 | BE15: 2023:Q3 | BF15: 45217 | BG15: 0.66736111 | BH15: 0.53 | BI15: 0.66 | BJ15: 0.742 | BL15: 2023:Q3 | BM15: 45218 | BN15: 0.56388889 | BO15: 40.5319 | BP15: 40.7 | BQ15: 36.986 | BS15: 2023:Q4 | BT15: 45267 | BU15: 0.67708333 | BV15: 0.8459 | BW15: 1.106 | BX15: 1.093 | BZ15: 2023:Q3 | CA15: 45230 | CB15: 0.67708333 | CC15: 0.1938 | CD15: 0.7 | CE15: 0.676 | CG15: 2023:Q4 | CH15: 45196 | CI15: 0.66736111 | CJ15: -1.1923 | CK15: -1.07 | CL15: -1.174 | CN15: 2023:Q3 | CO15: 45231 | CP15: 0.66736111 | CQ15: -0.8226 | CR15: -0.898 | CS15: 0.069 | CU15: 2023:Q3 | CV15: 45232 | CW15: 0.67569444 | CX15: -0.1581 | CY15: -0.01 | CZ15: -0.571 | DB15: 2023:Q3 | DC15: 45237 | DD15: 0.67013889 | DE15: 0.0074 | DF15: -0.09 | DG15: -0.101 | DI15: 2023:Q3 | DJ15: 45232 | DK15: 0.29166667 | DL15: 0.1571 | DM15: 0.24 | DN15: 0.146 | DP15: 2024:Q1 | DQ15: 45231 | DR15: 0.67569444 | DS15: 0.275 | DT15: 0.343 | DU15: 0.322 | DW15: 2024:Q2 | DX15: 45271 | DY15: 0.67013889 | DZ15: 0.9204 | EA15: 1.34 | EB15: 1.325 | ED15: 2024:Q3 | EE15: 45259 | EF15: 0.66805556 | EG15: 1.3469 | EH15: 2.11 | EI15: 2.062 | EK15: 2023:Q4 | EL15: 45273 | EM15: 0.67013889 | EN15: 3.3536 | EO15: 4.27 | EP15: 4.136 | ER15: 2023:Q3 | ES15: 45224 | ET15: 0.67361111 | EU15: 0.2431 | EV15: 0.584 | EW15: 0.511 | EY15: 2023:Q3 | EZ15: 45232 | FA15: 0.27083333 | FB15: 2.6063 | FC15: 0.1 | FD15: -0.162 | FF15: 2023:Q4 | FG15: 45303 | FH15: 0.24652778 | FI15: 5.83 | FJ15: 6.16 | FK15: 5.97 | FM15: 2025:Q1 | FN15: 45758 | FO15: 0.28194444 | FP15: 5.1094 | FQ15: 5.07 | FR15: 4.613 | FT15: 2024:Q1 | FU15: 45274 | FV15: 0.67708333 | FW15: 3.58 | FX15: 3.58 | FY15: 3.418 | GA15: 2023:Q3 | GB15: 45226 | GC15: 0.27083333 | GD15: 2.2617 | GE15: 2.27 | GF15: 2.36
A16: 2023:Q3 | B16: 45141 | C16: 0.6875 | D16: 1.26 | E16: 1.26 | F16: 1.219 | H16: 2023:Q2 | I16: 45141 | J16: 0.66736111 | K16: 0.65 | L16: 0.6309 | M16: 0.34 | O16: 2023:Q2 | P16: 45132 | Q16: 0.66736111 | R16: 1.44 | S16: 1.44 | T16: 1.324 | V16: 2023:Q2 | W16: 45133 | X16: 0.67013889 | Y16: 2.98 | Z16: 2.98 | AA16: 2.887 | AC16: 2023:Q4 | AD16: 45132 | AE16: 0.66666667 | AF16: 2.6734 | AG16: 2.69 | AH16: 2.567 | AJ16: 2023:Q3 | AK16: 45217 | AL16: 0.66805556 | AM16: 0.373 | AN16: 0.373 | AO16: 0.348 | AQ16: 2024:Q2 | AR16: 45161 | AS16: 0.68055556 | AT16: 0.2498 | AU16: 0.27 | AV16: 0.205 | AX16: 2023:Q2 | AY16: 45145 | AZ16: 0.67013889 | BA16: 0.0109 | BB16: 0.05 | BC16: 0.05 | BE16: 2023:Q2 | BF16: 45126 | BG16: 0.67013889 | BH16: 0.78 | BI16: 0.91 | BJ16: 0.809 | BL16: 2023:Q2 | BM16: 45127 | BN16: 0.5625 | BO16: 34.8219 | BP16: 35.05 | BQ16: 33.466 | BS16: 2023:Q3 | BT16: 45169 | BU16: 0.67708333 | BV16: 0.8209 | BW16: 1.054 | BX16: 1.043 | BZ16: 2023:Q2 | CA16: 45139 | CB16: 0.67708333 | CC16: 0.0392 | CD16: 0.58 | CE16: 0.578 | CG16: 2023:Q3 | CH16: 45105 | CI16: 0.66944444 | CJ16: -1.5616 | CK16: -1.43 | CL16: -1.42 | CN16: 2023:Q2 | CO16: 45139 | CP16: 0.66736111 | CQ16: 0.2705 | CR16: 0.235 | CS16: 0.046 | CU16: 2023:Q2 | CV16: 45141 | CW16: 0.67013889 | CX16: -0.1383 | CY16: -0.42 | CZ16: -0.764 | DB16: 2023:Q2 | DC16: 45140 | DD16: 0.66875 | DE16: 0.03 | DF16: 0.03 | DG16: -0.018 | DI16: 2023:Q2 | DJ16: 45140 | DK16: 0.67361111 | DL16: -0.0888 | DM16: 0.14 | DN16: 0.051 | DP16: 2023:Q4 | DQ16: 45146 | DR16: 0.67013889 | DS16: 0.343 | DT16: 0.351 | DU16: 0.284 | DW16: 2024:Q1 | DX16: 45180 | DY16: 0.67013889 | DZ16: 0.8881 | EA16: 1.19 | EB16: 1.152 | ED16: 2024:Q2 | EE16: 45168 | EF16: 0.67013889 | EG16: 1.3939 | EH16: 2.12 | EI16: 1.889 | EK16: 2023:Q3 | EL16: 45183 | EM16: 0.67013889 | EN16: 3.0887 | EO16: 4.09 | EP16: 3.978 | ER16: 2023:Q2 | ES16: 45133 | ET16: 0.67361111 | EU16: 0.1361 | EV16: 0.474 | EW16: 0.411 | EY16: 2023:Q2 | EZ16: 45146 | FA16: 0.28125 | FB16: 2.0817 | FC16: 2.11 | FD16: 1.994 | FF16: 2023:Q3 | FG16: 45212 | FH16: 0.24652778 | FI16: 6.24 | FJ16: 6.56 | FK16: 6.334 | FM16: 2024:Q4 | FN16: 45672 | FO16: 0.28194444 | FP16: 4.8848 | FQ16: 4.81 | FR16: 4.1 | FT16: 2023:Q4 | FU16: 45195 | FV16: 0.67708333 | FW16: 4.86 | FX16: 4.86 | FY16: 4.77 | GA16: 2023:Q2 | GB16: 45135 | GC16: 0.27083333 | GD16: 1.9395 | GE16: 1.94 | GF16: 2.001
... A20: 2022:Q3 | B20: 44770 | C20: 0.6875 | D20: 1.2 | E20: 1.2 | F20: 1.162 | H20: 2022:Q2 | I20: 44770 | J20: 0.66736111 | K20: -0.2 | L20: 0.1035 | M20: 0.148 | O20: 2022:Q2 | P20: 44768 | Q20: 0.67013889 | R20: 1.21 | S20: 1.21 | T20: 1.341 | V20: 2022:Q2 | W20: 44769 | X20: 0.67013889 | Y20: 2.46 | Z20: 2.46 | AA20: 2.541 | AC20: 2022:Q4 | AD20: 44768 | AE20: 0.66666667 | AF20: 2.2563 | AG20: 2.23 | AH20: 2.294 | AJ20: 2022:Q3 | AK20: 44852 | AL20: 0.66666667 | AM20: 0.31 | AN20: 0.31 | AO20: 0.212 | AQ20: 2023:Q2 | AR20: 44797 | AS20: 0.68055556 | AT20: 0.03 | AU20: 0.051 | AV20: 0.05 | AX20: 2022:Q2 | AY20: 44781 | AZ20: 0.29166667 | BA20: -0.09 | BB20: -0.01 | BC20: 0.029 | BE20: 2022:Q2 | BF20: 44762 | BG20: 0.67152778 | BH20: 0.6824 | BI20: 0.7567 | BJ20: 0.611 | BL20: 2022:Q2 | BM20: 44756 | BN20: 0.56527778 | BO20: 46.8081 | BP20: 45.7 | BQ20: 42.482 | BS20: 2022:Q3 | BT20: 44805 | BU20: 0.67708333 | BV20: 0.7242 | BW20: 0.973 | BX20: 0.949 | BZ20: 2022:Q2 | CA20: 44775 | CB20: 0.67013889 | CC20: 0.3643 | CD20: 1.05 | CE20: 1.04 | CG20: 2022:Q3 | CH20: 44742 | CI20: 0.66736111 | CJ20: 2.5037 | CK20: 2.59 | CL20: 2.448 | CN20: 2022:Q2 | CO20: 44775 | CP20: 0.66736111 | CQ20: -2.9843 | CR20: -9.281 | CS20: -2.4245363e-14 | CU20: 2022:Q2 | CV20: 44782 | CW20: 0.67916667 | CX20: -2.5694 | CY20: -4.98 | CZ20: -2.4 | DB20: 2022:Q2 | DC20: 44775 | DD20: 0.67708333 | DE20: -0.3156 | DF20: -0.34 | DG20: -0.364 | DI20: 2022:Q2 | DJ20: 44769 | DK20: 0.29166667 | DL20: -0.1481 | DM20: -0.03 | DN20: 0.024 | DP20: 2022:Q4 | DQ20: 44782 | DR20: 0.67013889 | DS20: 0.2602 | DT20: 0.262 | DU20: 0.233 | DW20: 2023:Q1 | DX20: 44816 | DY20: 0.67013889 | DZ20: 0.6065 | EA20: 1.03 | EB20: 1.062 | ED20: 2023:Q2 | EE20: 44797 | EF20: 0.67013889 | EG20: 0.0325 | EH20: 1.19 | EI20: 1.028 | EK20: 2022:Q3 | EL20: 44819 | EM20: 0.33333333 | EN20: 2.4424 | EO20: 3.4 | EP20: 3.334 | ER20: 2022:Q2 | ES20: 44769 | ET20: 0.67361111 | EU20: 0.024 | EV20: 0.324 | EW20: 0.312 | EY20: 2022:Q2 | EZ20: 44777 | FA20: 0.26736111 | FB20: 1.5278 | FC20: 1.25 | FD20: 1.637 | FF20: 2022:Q3 | FG20: 44848 | FH20: 0.24652778 | FI20: 5.55 | FJ20: 5.79 | FK20: 5.417 | FM20: 2023:Q4 | FN20: 45303 | FO20: 0.29097222 | FP20: 3.115 | FQ20: 3.97 | FR20: 3.618 | FT20: 2022:Q4 | FU20: 44826 | FV20: 0.67708333 | FW20: 4.2 | FX20: 4.2 | FY20: 4.144 | GA20: 2022:Q2 | GB20: 44771 | GC20: 0.27083333 | GD20: 4.1394 | GE20: 4.14 | GF20: 3.975
A21: 2022:Q2 | B21: 44679 | C21: 0.6875 | D21: 1.52 | E21: 1.52 | F21: 1.423 | H21: 2022:Q1 | I21: 44679 | J21: 0.66736111 | K21: -0.378 | L21: 0.2122 | M21: 0.423 | O21: 2022:Q1 | P21: 44677 | Q21: 0.66736111 | R21: 1.231 | S21: 1.231 | T21: 1.274 | V21: 2022:Q1 | W21: 44678 | X21: 0.67013889 | Y21: 2.72 | Z21: 2.72 | AA21: 2.564 | AC21: 2022:Q3 | AD21: 44677 | AE21: 0.66944444 | AF21: 2.2269 | AG21: 2.22 | AH21: 2.189 | AJ21: 2022:Q2 | AK21: 44761 | AL21: 0.66666667 | AM21: 0.32 | AN21: 0.32 | AO21: 0.292 | AQ21: 2023:Q1 | AR21: 44706 | AS21: 0.68055556 | AT21: 0.1111 | AU21: 0.1357 | AV21: 0.131 | AX21: 2022:Q1 | AY21: 44690 | AZ21: 0.29166667 | BA21: -0.05 | BB21: 0.02 | BC21: 0.034 | BE21: 2022:Q1 | BF21: 44671 | BG21: 0.67291667 | BH21: 0.9533 | BI21: 1.0733 | BJ21: 0.757 | BL21: 2022:Q1 | BM21: 44665 | BO21: 39.295 | BP21: 39.1 | BQ21: 36.059 | BS21: 2022:Q2 | BT21: 44707 | BU21: 0.29236111 | BV21: 0.6432 | BW21: 0.907 | BX21: 0.873 | BZ21: 2022:Q1 | CA21: 44684 | CB21: 0.67361111 | CC21: 0.6837 | CD21: 1.13 | CE21: 0.903 | CG21: 2022:Q2 | CH21: 44649 | CI21: 0.67083333 | CJ21: 2.0714 | CK21: 2.14 | CL21: 1.993 | CN21: 2022:Q1 | CO21: 44684 | CP21: 0.66736111 | CQ21: 0.3194 | CR21: -1.0307 | CS21: 0.15 | CU21: 2022:Q1 | CV21: 44691 | CW21: 0.67361111 | CX21: -0.1939 | CY21: -1.98 | CZ21: 0.201 | DB21: 2022:Q1 | DC21: 44679 | DD21: 0.66736111 | DE21: -0.4426 | DF21: -0.45 | DG21: -0.412 | DI21: 2022:Q1 | DJ21: 44686 | DK21: 0.29236111 | DL21: -0.0718 | DM21: 0.02 | DN21: 0.064 | DP21: 2022:Q3 | DQ21: 44684 | DR21: 0.67013889 | DS21: 0.1486 | DT21: 0.155 | DU21: 0.112 | DW21: 2022:Q4 | DX21: 44725 | DY21: 0.67013889 | DZ21: 1.1972 | EA21: 1.54 | EB21: 1.377 | ED21: 2023:Q1 | EE21: 44712 | EF21: 0.67013889 | EG21: 0.0227 | EH21: 0.98 | EI21: 0.952 | EK21: 2022:Q2 | EL21: 44728 | EM21: 0.67013889 | EN21: 2.5052 | EO21: 3.35 | EP21: 3.309 | ER21: 2022:Q1 | ES21: 44678 | ET21: 0.67361111 | EU21: 0.0779 | EV21: 0.346 | EW21: 0.341 | EY21: 2022:Q1 | EZ21: 44679 | FA21: 0.26736111 | FB21: 2.5838 | FC21: 2.77 | FD21: 2.36 | FF21: 2022:Q2 | FG21: 44757 | FH21: 0.24652778 | FI21: 5.34 | FJ21: 5.57 | FK21: 5.189 | FM21: 2023:Q3 | FN21: 45212 | FO21: 0.28333333 | FP21: 4.4927 | FQ21: 4.33 | FR21: 3.946 | FT21: 2022:Q3 | FU21: 44707 | FV21: 0.67708333 | FW21: 3.17 | FX21: 3.04 | FY21: 3.022 | GA21: 2022:Q1 | GB21: 44680 | GC21: 0.27083333 | GD21: 2.066 | GE21: 2.07 | GF21: 2.243
A22: 2022:Q1 | B22: 44588 | C22: 0.6875 | D22: 2.1 | E22: 2.1 | F22: 1.9 | H22: 2021:Q4 | I22: 44595 | J22: 0.66736111 | K22: 1.3875 | L22: 0.4846 | M22: 0.188 | O22: 2021:Q4 | P22: 44593 | Q22: 0.66944444 | R22: 1.5345 | S22: 2.0075 | T22: 1.373 | V22: 2021:Q4 | W22: 44594 | X22: 0.67013889 | Y22: 3.67 | Z22: 3.67 | AA22: 3.836 | AC22: 2022:Q2 | AD22: 44586 | AE22: 0.66736111 | AF22: 2.4486 | AG22: 2.48 | AH22: 2.316 | AJ22: 2022:Q1 | AK22: 44670 | AL22: 0.66666667 | AM22: 0.353 | AN22: 0.353 | AO22: 0.292 | AQ22: 2022:Q4 | AR22: 44608 | AS22: 0.68055556 | AT22: 0.1221 | AU22: 0.132 | AV22: 0.121 | AX22: 2021:Q4 | AY22: 44609 | AZ22: 0.25 | BA22: -0.0541 | BB22: 0.0855 | BC22: 0.034 | BE22: 2021:Q4 | BF22: 44587 | BG22: 0.66944444 | BH22: 0.6833 | BI22: 0.8467 | BJ22: 0.788 | BL22: 2021:A | BM22: 44574 | BN22: 0.57013889 | BO22: 116.2801 | BP22: 115.05 | BQ22: 114.164 | BS22: 2022:Q1 | BT22: 44623 | BU22: 0.67708333 | BV22: 0.5685 | BW22: 0.839 | BX22: 0.813 | BZ22: 2021:Q4 | CA22: 44593 | CB22: 0.67708333 | CC22: 0.8026 | CD22: 0.92 | CE22: 0.751 | CG22: 2022:Q1 | CH22: 44550 | CI22: 0.66805556 | CJ22: 2.0986 | CK22: 2.16 | CL22: 2.116 | CN22: 2021:Q4 | CO22: 44593 | CP22: 0.66736111 | CQ22: 0.2414 | CR22: 0.2418 | CS22: 0.153 | CU22: 2021:Q4 | CV22: 44616 | CW22: 0.66666667 | CX22: 4.998 | CY22: 3.32 | CZ22: 2.342 | DB22: 2021:Q4 | DC22: 44588 | DD22: 0.66736111 | DE22: -1.8265 | DF22: -0.49 | DG22: -0.423 | DI22: 2021:Q4 | DJ22: 44608 | DK22: 0.29166667 | DL22: 0.0574 | DM22: 0.136 | DN22: 0.126 | DP22: 2022:Q2 | DQ22: 44593 | DR22: 0.68194444 | DS22: 0.078 | DT22: 0.088 | DU22: 0.077 | DW22: 2022:Q3 | DX22: 44630 | DY22: 0.67013889 | DZ22: 0.8512 | EA22: 1.13 | EB22: 1.178 | ED22: 2022:Q4 | EE22: 44621 | EF22: 0.67013889 | EG22: -0.0572 | EH22: 0.84 | EI22: 0.745 | EK22: 2022:Q1 | EL22: 44642 | EM22: 0.67013889 | EN22: 2.7467 | EO22: 3.37 | EP22: 3.343 | ER22: 2021:Q4 | ES22: 44587 | ET22: 0.67361111 | EU22: 0.0308 | EV22: 0.292 | EW22: 0.287 | EY22: 2021:Q4 | EZ22: 44595 | FA22: 0.26736111 | FB22: 2.2405 | FC22: 2.49 | FD22: 2.483 | FF22: 2022:Q1 | FG22: 44665 | FH22: 0.24652778 | FI22: 5.27 | FJ22: 5.49 | FK22: 5.352 | FM22: 2023:Q2 | FN22: 45121 | FO22: 0.28402778 | FP22: 4.8529 | FQ22: 4.37 | FR22: 3.829 | FT22: 2022:Q2 | FU22: 44623 | FV22: 0.67708333 | FW22: 2.92 | FX22: 2.92 | FY22: 2.754 | GA22: 2021:Q4 | GB22: 44593 | GC22: 0.31319444 | GD22: 1.9988 | GE22: 2.05 | GF22: 1.929
A23: 2021:Q4 | B23: 44497 | C23: 0.6875 | D23: 1.24 | E23: 1.2354 | F23: 1.236 | H23: 2021:Q3 | I23: 44497 | J23: 0.66736111 | K23: 0.306 | L23: 0.306 | M23: 0.448 | O23: 2021:Q3 | P23: 44495 | Q23: 0.66805556 | R23: 1.3995 | S23: 1.3045 | T23: 1.175 | V23: 2021:Q3 | W23: 44494 | X23: 0.67013889 | Y23: 3.22 | Z23: 3.22 | AA23: 3.174 | AC23: 2022:Q1 | AD23: 44495 | AE23: 0.66736111 | AF23: 2.2522 | AG23: 2.27 | AH23: 2.072 | AJ23: 2021:Q4 | AK23: 44581 | AL23: 0.66666667 | AM23: 0.133 | AN23: 0.133 | AO23: 0.081 | AQ23: 2022:Q3 | AR23: 44517 | AS23: 0.68055556 | AT23: 0.1033 | AU23: 0.117 | AV23: 0.11 | AX23: 2021:Q3 | AY23: 44509 | AZ23: 0.29166667 | BA23: -0.039 | BB23: 0.04 | BC23: 0.037 | BE23: 2021:Q3 | BF23: 44489 | BG23: 0.67222222 | BH23: 0.492 | BI23: 0.62 | BJ23: 0.557 | BL23: 2021:Q3 | BM23: 44483 | BO23: 30.5232 | BP23: 30.15 | BQ23: 28.942 | BS23: 2021:Q4 | BT23: 44539 | BU23: 0.67708333 | BV23: 0.4551 | BW23: 0.781 | BX23: 0.777 | BZ23: 2021:Q3 | CA23: 44495 | CB23: 0.67708333 | CC23: 0.7763 | CD23: 0.73 | CE23: 0.667 | CG23: 2021:Q4 | CH23: 44467 | CI23: 0.66736111 | CJ23: 2.3709 | CK23: 2.42 | CL23: 2.348 | CN23: 2021:Q3 | CO23: 44497 | CP23: 0.66736111 | CQ23: 0.0874 | CR23: -0.2397 | CS23: 0.122 | CU23: 2021:Q3 | CV23: 44509 | CW23: 0.66666667 | CX23: 2.2891 | CY23: 1.696 | CZ23: 1.705 | DB23: 2021:Q3 | DC23: 44495 | DD23: 0.66875 | DE23: -2.0946 | DF23: -2.0632 | DG23: -0.853 | DI23: 2021:Q3 | DJ23: 44497 | DK23: 0.29166667 | DL23: 0.0025 | DM23: -2.4245363e-14 | DN23: 0.114 | DP23: 2022:Q1 | DQ23: 44502 | DR23: 0.67013889 | DS23: 0.0503 | DT23: 0.058 | DU23: 0.038 | DW23: 2022:Q2 | DX23: 44539 | DY23: 0.67013889 | DZ23: 0.9583 | EA23: 1.21 | EB23: 1.112 | ED23: 2022:Q3 | EE23: 44530 | EF23: 0.67013889 | EG23: 0.2609 | EH23: 1.2784 | EI23: 0.92 | EK23: 2021:Q4 | EL23: 44546 | EM23: 0.33680556 | EN23: 2.577 | EO23: 3.2 | EP23: 3.192 | ER23: 2021:Q3 | ES23: 44496 | ET23: 0.67361111 | EU23: 0.0674 | EV23: 0.31 | EW23: 0.277 | EY23: 2021:Q3 | EZ23: 44495 | FA23: 0.26736111 | FB23: 1.8086 | FC23: 1.94 | FD23: 1.946 | FF23: 2021:Q4 | FG23: 44580 | FH23: 0.24652778 | FI23: 4.26 | FJ23: 4.48 | FK23: 4.295 | FM23: 2023:Q1 | FN23: 45030 | FO23: 0.28402778 | FP23: 4.1874 | FQ23: 4.1 | FR23: 3.379 | FT23: 2022:Q1 | FU23: 44539 | FV23: 0.67708333 | FW23: 3.1897 | FX23: 2.98 | FY23: 2.618 | GA23: 2021:Q3 | GB23: 44498 | GC23: 0.31319444 | GD23: 1.57 | GE23: 1.58 | GF23: 1.559
A24: 2021:Q3 | B24: 44404 | C24: 0.6875 | D24: 1.3 | E24: 1.2957 | F24: 1.013 | H24: 2021:Q2 | I24: 44406 | J24: 0.66736111 | K24: 0.76 | L24: 0.756 | M24: 0.615 | O24: 2021:Q2 | P24: 44404 | Q24: 0.67569444 | R24: 1.363 | S24: 1.363 | T24: 0.956 | V24: 2021:Q2 | W24: 44405 | X24: 0.67013889 | Y24: 3.61 | Z24: 3.61 | AA24: 3.018 | AC24: 2021:Q4 | AD24: 44404 | AE24: 0.66944444 | AF24: 2.1288 | AG24: 2.17 | AH24: 1.921 | AJ24: 2021:Q3 | AK24: 44488 | AL24: 0.66666667 | AM24: 0.319 | AN24: 0.319 | AO24: 0.257 | AQ24: 2022:Q2 | AR24: 44426 | AS24: 0.68055556 | AT24: 0.1018 | AU24: 0.104 | AV24: 0.1 | AX24: 2021:Q2 | AY24: 44420 | AZ24: 0.29166667 | BA24: -0.07 | BB24: 0.04 | BC24: 0.034 | BE24: 2021:Q2 | BF24: 44403 | BG24: 0.67152778 | BH24: 0.3454 | BI24: 0.4833 | BJ24: 0.325 | BL24: 2021:Q2 | BM24: 44392 | BN24: 0.5875 | BO24: 25.7348 | BP24: 25.9 | BQ24: 26.161 | BS24: 2021:Q3 | BT24: 44441 | BU24: 0.67708333 | BV24: 0.4293 | BW24: 0.696 | BX24: 0.685 | BZ24: 2021:Q2 | CA24: 44404 | CB24: 0.67708333 | CC24: 0.593 | CD24: 0.6832 | CE24: 0.54 | CG24: 2021:Q3 | CH24: 44377 | CI24: 0.67222222 | CJ24: 1.799 | CK24: 1.88 | CL24: 1.721 | CN24: 2021:Q2 | CO24: 44406 | CP24: 0.66736111 | CQ24: 0.0762 | CR24: -2.9576 | CS24: 0.1 | CU24: 2021:Q2 | CV24: 44418 | CW24: 0.66666667 | CX24: 7.7606 | CY24: 7.7606 | CZ24: 2.48 | DB24: 2021:Q2 | DC24: 44426 | DD24: 0.67013889 | DE24: -3.9056 | DF24: -2.1092 | DG24: -0.26 | DI24: 2021:Q2 | DJ24: 44405 | DK24: 0.29166667 | DL24: 0.1569 | DM24: 0.2233 | DN24: 0.097 | DP24: 2021:Q4 | DQ24: 44418 | DR24: 0.67013889 | DS24: 0.0746 | DT24: 0.081 | DU24: 0.078 | DW24: 2022:Q1 | DX24: 44452 | DY24: 0.67013889 | DZ24: 0.8711 | EA24: 1.03 | EB24: 0.97 | ED24: 2022:Q2 | EE24: 44433 | EF24: 0.67013889 | EG24: 0.1226 | EH24: 1.48 | EI24: 0.922 | EK24: 2021:Q3 | EL24: 44460 | EM24: 0.67013889 | EN24: 2.502 | EO24: 3.11 | EP24: 3.011 | ER24: 2021:Q2 | ES24: 44405 | ET24: 0.67361111 | EU24: 0.0617 | EV24: 0.284 | EW24: 0.242 | EY24: 2021:Q2 | EZ24: 44411 | FA24: 0.26736111 | FB24: 1.9171 | FC24: 1.87 | FD24: 1.893 | FF24: 2021:Q3 | FG24: 44483 | FH24: 0.24652778 | FI24: 4.28 | FJ24: 4.52 | FK24: 4.391 | FM24: 2022:Q4 | FN24: 44939 | FO24: 0.28194444 | FP24: 3.594 | FQ24: 3.57 | FR24: 3.096 | FT24: 2021:Q4 | FU24: 44462 | FV24: 0.67708333 | FW24: 3.9 | FX24: 3.76 | FY24: 3.554 | GA24: 2021:Q2 | GB24: 44407 | GC24: 0.3125 | GD24: 1.0996 | GE24: 1.1 | GF24: 0.972
A25: 2021:Q2 | B25: 44314 | C25: 0.6875 | D25: 1.3955 | E25: 1.3958 | F25: 0.991 | H25: 2021:Q1 | I25: 44315 | J25: 0.66736111 | K25: 0.7895 | L25: 0.7895 | M25: 0.485 | O25: 2021:Q1 | P25: 44313 | Q25: 0.66805556 | R25: 1.3145 | S25: 1.3145 | T25: 0.782 | V25: 2021:Q1 | W25: 44314 | X25: 0.67013889 | Y25: 3.3 | Z25: 3.3 | AA25: 2.343 | AC25: 2021:Q3 | AD25: 44313 | AE25: 0.67083333 | AF25: 1.9117 | AG25: 1.95 | AH25: 1.781 | AJ25: 2021:Q2 | AK25: 44397 | AL25: 0.66666667 | AM25: 0.297 | AN25: 0.297 | AO25: 0.316 | AQ25: 2022:Q1 | AR25: 44342 | AS25: 0.68055556 | AT25: 0.0811 | AU25: 0.0915 | AV25: 0.082 | AX25: 2021:Q1 | AY25: 44327 | AZ25: 0.29166667 | BA25: -0.07 | BB25: 0.04 | BC25: 0.035 | BE25: 2021:Q1 | BF25: 44312 | BG25: 0.67013889 | BH25: 0.1065 | BI25: 0.31 | BJ25: 0.268 | BL25: 2021:Q1 | BM25: 44301 | BO25: 27.4927 | BP25: 26.95 | BQ25: 26.3 | BS25: 2021:Q2 | BT25: 44350 | BU25: 0.67708333 | BV25: 0.3538 | BW25: 0.662 | BX25: 0.645 | BZ25: 2021:Q1 | CA25: 44313 | CB25: 0.67569444 | CC25: 0.4657 | CD25: 0.52 | CE25: 0.442 | CG25: 2021:Q2 | CH25: 44286 | CI25: 0.66736111 | CJ25: 0.6699 | CK25: 0.98 | CL25: 0.938 | CN25: 2021:Q1 | CO25: 44315 | CP25: 0.66736111 | CQ25: 0.0975 | CR25: -1.0605 | CS25: 0.082 | CU25: 2021:Q1 | CV25: 44329 | CW25: 0.66666667 | CX25: 7.4963 | CY25: 3.05 | CZ25: 3.101 | DI25: 2021:Q1 | DJ25: 44314 | DL25: 0.1383 | DM25: 1.0485 | DN25: 0.078 | DP25: 2021:Q3 | DQ25: 44320 | DR25: 0.67013889 | DS25: 0.0405 | DT25: 0.05 | DU25: 0.047 | DW25: 2021:Q4 | DX25: 44362 | DY25: 0.67013889 | DZ25: 1.3928 | EA25: 1.6902 | EB25: 1.31 | ED25: 2022:Q1 | EE25: 44343 | EF25: 0.67013889 | EG25: 0.258 | EH25: 1.2164 | EI25: 0.885 | EK25: 2021:Q2 | EL25: 44364 | EM25: 0.67013889 | EN25: 2.3038 | EO25: 3.03 | EP25: 2.82 | ER25: 2021:Q1 | ES25: 44314 | ET25: 0.67638889 | EU25: 0.0852 | EV25: 0.304 | EW25: 0.269 | EY25: 2021:Q1 | EZ25: 44313 | FA25: 0.26736111 | FB25: 1.7634 | FC25: 1.87 | FD25: 2.113 | FF25: 2021:Q2 | FG25: 44392 | FH25: 0.24652778 | FI25: 4.46 | FJ25: 4.7 | FK25: 4.429 | FM25: 2022:Q3 | FN25: 44848 | FO25: 0.28611111 | FP25: 3.1408 | FQ25: 3.12 | FR25: 2.878 | FT25: 2021:Q3 | FU25: 44343 | FV25: 0.67708333 | FW25: 2.7928 | FX25: 2.75 | FY25: 2.406 | GA25: 2021:Q1 | GB25: 44316 | GC25: 0.31180556 | GD25: 0.6463 | GE25: 0.65 | GF25: 0.611
A26: 2021:Q1 | B26: 44223 | C26: 0.6875 | D26: 1.6746 | E26: 1.6802 | F26: 1.417 | H26: 2020:Q4 | I26: 44229 | J26: 0.66875 | K26: 0.7045 | L26: 0.7045 | M26: 0.368 | O26: 2020:Q4 | P26: 44229 | Q26: 0.66805556 | R26: 1.115 | S26: 1.115 | T26: 0.78 | V26: 2020:Q4 | W26: 44223 | X26: 0.67013889 | Y26: 3.88 | Z26: 3.88 | AA26: 3.217 | AC26: 2021:Q2 | AD26: 44222 | AE26: 0.66944444 | AF26: 1.9928 | AG26: 2.0303 | AH26: 1.625 | AJ26: 2021:Q1 | AK26: 44306 | AL26: 0.66666667 | AM26: 0.375 | AN26: 0.375 | AO26: 0.299 | AQ26: 2021:Q4 | AR26: 44251 | AS26: 0.68055556 | AT26: 0.0631 | AU26: 0.0775 | AV26: 0.07 | AX26: 2020:Q4 | AY26: 44243 | AZ26: 0.29166667 | BA26: -0.08 | BB26: 0.0637 | BC26: 0.018 | BE26: 2020:Q4 | BF26: 44223 | BG26: 0.67222222 | BH26: 0.0917 | BI26: 0.2667 | BJ26: 0.342 | BL26: 2020:A | BM26: 44210 | BN26: 0.61111111 | BO26: 98.373 | BP26: 99.85 | BQ26: 98.827 | BS26: 2021:Q1 | BT26: 44259 | BU26: 0.67708333 | BV26: 0.339 | BW26: 0.661 | BX26: 0.657 | BZ26: 2020:Q4 | CA26: 44222 | CB26: 0.67361111 | CC26: 0.4082 | CD26: 0.52 | CE26: 0.472 | CG26: 2021:Q1 | CH26: 44203 | CI26: 0.66875 | CJ26: 0.7239 | CK26: 0.78 | CL26: 0.66 | CN26: 2020:Q4 | CO26: 44224 | CP26: 0.66736111 | CQ26: 0.1792 | CR26: 0.0601 | CS26: -2.4245363e-14 | DI26: 2020:Q4 | DJ26: 44244 | DK26: 0.29166667 | DL26: 0.0977 | DM26: 0.1585 | DN26: 0.121 | DP26: 2021:Q2 | DQ26: 44229 | DR26: 0.69027778 | DS26: 0.0557 | DT26: 0.063 | DU26: 0.038 | DW26: 2021:Q3 | DX26: 44265 | DY26: 0.67013889 | DZ26: 0.9375 | EA26: 1.16 | EB26: 1.11 | ED26: 2021:Q4 | EE26: 44252 | EF26: 0.67013889 | EG26: 0.0613 | EH26: 1.04 | EI26: 0.749 | EK26: 2021:Q1 | EL26: 44278 | EM26: 0.67013889 | EN26: 2.6029 | EO26: 3.14 | EP26: 2.786 | ER26: 2020:Q4 | ES26: 44223 | ET26: 0.67361111 | EU26: 0.0217 | EV26: 0.234 | EW26: 0.212 | EY26: 2020:Q4 | EZ26: 44225 | FA26: 0.26388889 | FB26: 2.6388 | FC26: 2.75 | FD26: 2.382 | FF26: 2021:Q1 | FG26: 44301 | FH26: 0.24652778 | FI26: 5.08 | FJ26: 5.31 | FK26: 4.4 | FM26: 2022:Q2 | FN26: 44756 | FO26: 0.28194444 | FP26: 2.8375 | FQ26: 2.76 | FR26: 2.883 | FT26: 2021:Q2 | FU26: 44259 | FV26: 0.67708333 | FW26: 2.14 | FX26: 2.14 | FY26: 2.447 | GA26: 2020:Q4 | GB26: 44229 | GC26: 0.3125 | GD26: -0.1122 | GE26: 0.03 | GF26: 0.017
A27: 2020:Q4 | B27: 44133 | C27: 0.6875 | D27: 0.7258 | E27: 0.7344 | F27: 0.702 | H27: 2020:Q3 | I27: 44133 | J27: 0.66736111 | K27: 0.6185 | L27: 0.6185 | M27: 0.377 | O27: 2020:Q3 | P27: 44133 | Q27: 0.66805556 | R27: 0.82 | S27: 0.7185 | T27: 0.57 | V27: 2020:Q3 | W27: 44133 | X27: 0.67013889 | Y27: 2.71 | Z27: 2.4 | AA27: 1.906 | AC27: 2021:Q1 | AD27: 44131 | AE27: 0.67569444 | AF27: 1.8077 | AG27: 1.8192 | AH27: 1.546 | AJ27: 2020:Q4 | AK27: 44215 | AL27: 0.66666667 | AM27: 0.119 | AN27: 0.119 | AO27: 0.139 | AQ27: 2021:Q3 | AR27: 44153 | AS27: 0.68055556 | AT27: 0.06 | AU27: 0.0728 | AV27: 0.065 | AX27: 2020:Q3 | AY27: 44147 | AZ27: 0.67013889 | BA27: -0.94 | BB27: 0.0746 | BC27: 0.034 | BE27: 2020:Q3 | BF27: 44125 | BG27: 0.67708333 | BH27: 0.113 | BI27: 0.2533 | BJ27: 0.183 | BL27: 2020:Q3 | BM27: 44119 | BN27: 0.62152778 | BO27: 25.5497 | BP27: 26.5 | BQ27: 24.343 | BS27: 2020:Q4 | BT27: 44175 | BU27: 0.67708333 | BV27: 0.3116 | BW27: 0.635 | BX27: 0.625 | BZ27: 2020:Q3 | CA27: 44131 | CB27: 0.27083333 | CC27: 0.3447 | CD27: 0.41 | CE27: 0.354 | CG27: 2020:Q4 | CH27: 44103 | CI27: 0.66736111 | CJ27: 1.0188 | CK27: 1.08 | CL27: 0.995 | CN27: 2020:Q3 | CO27: 44131 | CP27: 0.66736111 | CQ27: 0.2155 | CR27: -0.148 | CS27: -2.4245363e-14 | DI27: 2020:Q3 | DJ27: 44133 | DK27: 0.29166667 | DL27: 0.0503 | DM27: 0.113 | DN27: 0.051 | DP27: 2021:Q1 | DQ27: 44138 | DR27: 0.67013889 | DS27: 0.0461 | DT27: 0.055 | DU27: 0.013 | DW27: 2021:Q2 | DX27: 44175 | DY27: 0.66805556 | DZ27: 0.864 | EA27: 1.06 | EB27: 0.999 | ED27: 2021:Q3 | EE27: 44166 | EF27: 0.67083333 | EG27: 0.2784 | EH27: 1.74 | EI27: 0.749 | EK27: 2020:Q4 | EL27: 44175 | EM27: 0.33333333 | EN27: 4.6747 | EO27: 2.81 | EP27: 2.656 | ER27: 2020:Q3 | ES27: 44132 | ET27: 0.67361111 | EU27: 0.0454 | EV27: 0.242 | EW27: 0.205 | EY27: 2020:Q3 | EZ27: 44131 | FA27: 0.27083333 | FB27: 1.3087 | FC27: 1.54 | FD27: 1.745 | FF27: 2020:Q4 | FG27: 44216 | FH27: 0.24652778 | FI27: 2.3 | FJ27: 2.52 | FK27: 2.408 | FM27: 2022:Q1 | FN27: 44664 | FO27: 0.29305556 | FP27: 2.7915 | FQ27: 2.63 | FR27: 2.721 | FT27: 2021:Q1 | FU27: 44175 | FV27: 0.67708333 | FW27: 2.62 | FX27: 2.62 | FY27: 2.06 | GA27: 2020:Q3 | GB27: 44134 | GC27: 0.31180556 | GD27: -0.148 | GE27: -0.18 | GF27: -0.255
