Workbook
Name EndDate: Control!$B$5
Name OptDays: Control!$B$7
Name OptFill: Control!$B$8
Name PxField: Control!$B$6
Name StartDate: Control!$B$4

Sheet README
A1: README — Volatility, correlation & short-rate indices (Bloomberg BDH)
A2: For human readers and AI models: read this sheet before using the data.
A4: Key | B4: Value
A5: content | B5: Daily PX_LAST history for 9 indices, one 2-column block (Date, Value) per index. Units per index are listed on Control.
A6: bloomberg_formula | B6: =_xll.BDH(security,"PX_LAST",StartDate,EndDate,"Days=T","Fill=P") — parameters on Control -> #NAME?
A7: frequency | B7: Daily, trading days (Days=T).
A8: fill | B8: Fill=P: on a trading day with no print, the PREVIOUS value is carried forward. Consecutive identical values may be fills, not real observations.
A9: start_date | B9: Control!B4 (default 20100101). Some series start later than 2010 (e.g. VIX9D, DSPX, COR1M, VIX3M) — they begin at their first available date.
A10: alignment | B10: Each index has its own Date column; rows are NOT aligned across blocks. Align by date before combining.
A11: adjustment | B11: Not applicable (indices and yields have no splits/dividends).
A12: layout | B12: Data sheet: row 1 index name, row 2 Bloomberg security, row 3 headers, data from row 4; 1 blank spacer column between blocks.
A13: refresh | B13: Bloomberg formulas refresh when the workbook is opened with the Bloomberg add-in active (or via Bloomberg ribbon > Refresh Worksheet).
A14: source | B14: Bloomberg BDH via Excel add-in

Sheet Control
A1: Vol / Rates Index Pull — Control Panel
A2: Yellow cells are inputs (blue text).
A4: Start date | B4: 20100101 | C4: yyyymmdd
A5: End date | C5: Blank = up to today
A6: Field | B6: PX_LAST
A7: Days | B7: Days=T | C7: Trading days
A8: Fill | B8: Fill=P | C8: Carry previous value forward
A10: Index list
A11: # | B11: Ticker | C11: Bloomberg security | D11: Description | E11: Units | F11: Block col
A12: 1 | B12: VIX | C12: =B12&" Index" -> VIX Index | D12: Cboe S&P 500 Volatility Index (30-day) | E12: Vol points (annualised %) | F12: A
A13: 2 | B13: VXN | C13: =B13&" Index" -> VXN Index | D13: Cboe Nasdaq-100 Volatility Index (30-day) | E13: Vol points (annualised %) | F13: D
A14: 3 | B14: VVIX | C14: =B14&" Index" -> VVIX Index | D14: Cboe VIX of VIX (30-day implied vol of VIX) | E14: Vol points (annualised %) | F14: G
A15: 4 | B15: VIX9D | C15: =B15&" Index" -> VIX9D Index | D15: Cboe S&P 500 9-Day Volatility Index | E15: Vol points (annualised %) | F15: J
A16: 5 | B16: DSPX | C16: =B16&" Index" -> DSPX Index | D16: Cboe S&P 500 Dispersion Index | E16: Index level | F16: M
A17: 6 | B17: VIX3M | C17: =B17&" Index" -> VIX3M Index | D17: Cboe S&P 500 3-Month Volatility Index | E17: Vol points (annualised %) | F17: P
A18: 7 | B18: SKEW | C18: =B18&" Index" -> SKEW Index | D18: Cboe SKEW Index (S&P 500 tail risk) | E18: Index level (100 = normal-like tails) | F18: S
A19: 8 | B19: COR1M | C19: =B19&" Index" -> COR1M Index | D19: Cboe 1-Month Implied Correlation Index | E19: Index level (implied correlation x100) | F19: V
A20: 9 | B20: USGG1M | C20: =B20&" Index" -> USGG1M Index | D20: US Generic Govt 1-Month Yield | E20: Yield in percent (e.g. 4.25 = 4.25%) | F20: Y

Sheet Index_Data
A1: =Control!$B$12 -> VIX | D1: =Control!$B$13 -> VXN | G1: =Control!$B$14 -> VVIX | J1: =Control!$B$15 -> VIX9D | M1: =Control!$B$16 -> DSPX | P1: =Control!$B$17 -> VIX3M | S1: =Control!$B$18 -> SKEW | V1: =Control!$B$19 -> COR1M | Y1: =Control!$B$20 -> USGG1M
A2: =Control!$C$12 -> VIX Index | D2: =Control!$C$13 -> VXN Index | G2: =Control!$C$14 -> VVIX Index | J2: =Control!$C$15 -> VIX9D Index | M2: =Control!$C$16 -> DSPX Index | P2: =Control!$C$17 -> VIX3M Index | S2: =Control!$C$18 -> SKEW Index | V2: =Control!$C$19 -> COR1M Index | Y2: =Control!$C$20 -> USGG1M Index
A3: Date | B3: PX_LAST (Vol points) | D3: Date | E3: PX_LAST (Vol points) | G3: Date | H3: PX_LAST (Vol points) | J3: Date | K3: PX_LAST (Vol points) | M3: Date | N3: PX_LAST (Index level) | P3: Date | Q3: PX_LAST (Vol points) | S3: Date | T3: PX_LAST (Index level) | V3: Date | W3: PX_LAST (Index level) | Y3: Date | Z3: PX_LAST (Yield in percent)
A4: =_xll.BDH(A$2,PxField,StartDate,IF(EndDate="","",EndDate),OptDays,OptFill,"cols=2;rows=4236") -> 40182 | B4: 20.04 | D4: =_xll.BDH(D$2,PxField,StartDate,IF(EndDate="","",EndDate),OptDays,OptFill,"cols=2;rows=4206") -> 40182 | E4: 21.2 | G4: =_xll.BDH(G$2,PxField,StartDate,IF(EndDate="","",EndDate),OptDays,OptFill,"cols=2;rows=4198") -> 40182 | H4: 73.3 | J4: =_xll.BDH(J$2,PxField,StartDate,IF(EndDate="","",EndDate),OptDays,OptFill,"cols=2;rows=3951") -> 40546 | K4: 16.04 | M4: =_xll.BDH(M$2,PxField,StartDate,IF(EndDate="","",EndDate),OptDays,OptFill,"cols=2;rows=3081") -> 41809 | N4: 17.81 | P4: =_xll.BDH(P$2,PxField,StartDate,IF(EndDate="","",EndDate),OptDays,OptFill,"cols=2;rows=4203") -> 40182 | Q4: 22.77 | S4: =_xll.BDH(S$2,PxField,StartDate,IF(EndDate="","",EndDate),OptDays,OptFill,"cols=2;rows=4201") -> 40182 | T4: 123.84 | V4: =_xll.BDH(V$2,PxField,StartDate,IF(EndDate="","",EndDate),OptDays,OptFill,"cols=2;rows=4203") -> 40182 | W4: 41 | Y4: =_xll.BDH(Y$2,PxField,StartDate,IF(EndDate="","",EndDate),OptDays,OptFill,"cols=2;rows=4361") -> 40179 | Z4: 0.0264
A5: 40183 | B5: 19.35 | D5: 40183 | E5: 20.5 | G5: 40183 | H5: 70.36 | J5: 40547 | K5: 16.06 | M5: 41810 | N5: 17.37 | P5: 40183 | Q5: 22.39 | S5: 40183 | T5: 122.99 | V5: 40183 | W5: 37.69 | Y5: 40182 | Z5: 0.0395
A6: 40184 | B6: 19.16 | D6: 40184 | E6: 20.21 | G6: 40184 | H6: 67.65 | J6: 40548 | K6: 15.57 | M6: 41813 | N6: 17.7 | P6: 40184 | Q6: 21.8 | S6: 40184 | T6: 121.63 | V6: 40184 | W6: 36.43 | Y6: 40183 | Z6: 0.0243
A7: 40185 | B7: 19.06 | D7: 40185 | E7: 19.99 | G7: 40185 | H7: 67.15 | J7: 40549 | K7: 15.71 | M7: 41814 | N7: 16.59 | P7: 40185 | Q7: 21.6 | S7: 40185 | T7: 120.17 | V7: 40185 | W7: 34.52 | Y7: 40184 | Z7: 0.0152
A8: 40186 | B8: 18.13 | D8: 40186 | E8: 18.92 | G8: 40186 | H8: 65.71 | J8: 40550 | K8: 15.01 | M8: 41815 | N8: 17.78 | P8: 40186 | Q8: 21 | S8: 40186 | T8: 120.15 | V8: 40186 | W8: 33.4 | Y8: 40185 | Z8: 0.0101
A9: 40189 | B9: 17.55 | D9: 40189 | E9: 18.47 | G9: 40189 | H9: 64.87 | J9: 40553 | K9: 15.81 | M9: 41816 | N9: 17.43 | P9: 40189 | Q9: 21.27 | S9: 40189 | T9: 119.1 | V9: 40189 | W9: 32.58 | Y9: 40186 | Z9: 0.0101
A10: 40190 | B10: 18.25 | D10: 40190 | E10: 19.29 | G10: 40190 | H10: 70.42 | J10: 40554 | K10: 14.93 | M10: 41817 | N10: 18.09 | P10: 40190 | Q10: 21.79 | S10: 40190 | T10: 120.66 | V10: 40190 | W10: 31.84 | Y10: 40189 | Z10: 0.0091
A11: 40191 | B11: 17.85 | D11: 40191 | E11: 18.4 | G11: 40191 | H11: 75.53 | J11: 40555 | K11: 14.82 | M11: 41820 | N11: 19.41 | P11: 40191 | Q11: 21.29 | S11: 40191 | T11: 125.89 | V11: 40191 | W11: 33.16 | Y11: 40190 | Z11: 0.0101
A12: 40192 | B12: 17.63 | D12: 40192 | E12: 18.2 | G12: 40192 | H12: 74.52 | J12: 40556 | K12: 14.92 | M12: 41821 | N12: 19.43 | P12: 40192 | Q12: 20.71 | S12: 40192 | T12: 125.06 | V12: 40192 | W12: 28.18 | Y12: 40191 | Z12: 0.0101
A13: 40193 | B13: 17.91 | D13: 40193 | E13: 18.73 | G13: 40193 | H13: 74.27 | J13: 40557 | K13: 14.3 | M13: 41822 | N13: 19.54 | P13: 40193 | Q13: 21.48 | S13: 40193 | T13: 124.32 | V13: 40193 | W13: 25.41 | Y13: 40192 | Z13: 0.0101
A14: 40197 | B14: 17.58 | D14: 40197 | E14: 18.74 | G14: 40197 | H14: 73.5 | J14: 40561 | K14: 16.34 | M14: 41823 | N14: 20.6 | P14: 40197 | Q14: 20.89 | S14: 40197 | T14: 124.28 | V14: 40197 | W14: 38.92 | Y14: 40193 | Z14: 0.0101
A15: 40198 | B15: 18.68 | D15: 40198 | E15: 20.01 | G15: 40198 | H15: 80.36 | J15: 40562 | K15: 17.74 | M15: 41827 | N15: 20.27 | P15: 40198 | Q15: 21.4 | S15: 40198 | T15: 124.1 | V15: 40198 | W15: 42.17 | Y15: 40196 | Z15: 0.0101
A16: 40199 | B16: 22.27 | D16: 40199 | E16: 23.19 | G16: 40199 | H16: 88.82 | J16: 40563 | K16: 16.98 | M16: 41828 | N16: 21.15 | P16: 40199 | Q16: 23.15 | S16: 40199 | T16: 121.99 | V16: 40199 | W16: 50.72 | Y16: 40197 | Z16: 0.0203
... A3084: 44649 | B3084: 18.9 | D3084: 44644 | E3084: 27.89 | G3084: 44656 | H3084: 116.27 | J3084: 45015 | K3084: 17.3 | M3084: 46283 | N3084: 33.19 | P3084: 44649 | Q3084: 23.19 | S3084: 44649 | T3084: 140 | V3084: 44649 | W3084: 24.44 | Y3084: 44491 | Z3084: 0.0355
A3085: 44650 | B3085: 19.33 | D3085: 44645 | E3085: 27.34 | G3085: 44657 | H3085: 114.84 | J3085: 45016 | K3085: 16.51 | P3085: 44650 | Q3085: 23.57 | S3085: 44650 | T3085: 139.28 | V3085: 44650 | W3085: 25.48 | Y3085: 44494 | Z3085: 0.0482
A3086: 44651 | B3086: 20.56 | D3086: 44648 | E3086: 26.53 | G3086: 44658 | H3086: 113.33 | J3086: 45019 | K3086: 17.03 | P3086: 44651 | Q3086: 24.46 | S3086: 44651 | T3086: 140.73 | V3086: 44651 | W3086: 27.96 | Y3086: 44495 | Z3086: 0.0482
A3087: 44652 | B3087: 19.63 | D3087: 44649 | E3087: 25.87 | G3087: 44659 | H3087: 112.14 | J3087: 45020 | K3087: 17.42 | P3087: 44652 | Q3087: 24.21 | S3087: 44652 | T3087: 145.51 | V3087: 44652 | W3087: 23.33 | Y3087: 44496 | Z3087: 0.0482
A3088: 44655 | B3088: 18.57 | D3088: 44650 | E3088: 26.4 | G3088: 44662 | H3088: 117.35 | J3088: 45021 | K3088: 16.99 | P3088: 44655 | Q3088: 23.03 | S3088: 44655 | T3088: 146.48 | V3088: 44655 | W3088: 21.3 | Y3088: 44497 | Z3088: 0.0482
A3089: 44656 | B3089: 21.03 | D3089: 44651 | E3089: 26.99 | G3089: 44663 | H3089: 117.26 | J3089: 45022 | K3089: 15.68 | P3089: 44656 | Q3089: 24.9 | S3089: 44656 | T3089: 141.33 | V3089: 44656 | W3089: 27.38 | Y3089: 44498 | Z3089: 0.0482
A3090: 44657 | B3090: 22.1 | D3090: 44652 | E3090: 25.91 | G3090: 44664 | H3090: 113.76 | J3090: 45026 | K3090: 16.8 | P3090: 44657 | Q3090: 25.8 | S3090: 44657 | T3090: 144.27 | V3090: 44657 | W3090: 28.22 | Y3090: 44501 | Z3090: 0.0456
A3091: 44658 | B3091: 21.55 | D3091: 44655 | E3091: 24.93 | G3091: 44665 | H3091: 114.75 | J3091: 45027 | K3091: 16.86 | P3091: 44658 | Q3091: 25.23 | S3091: 44658 | T3091: 139.55 | V3091: 44658 | W3091: 26.56 | Y3091: 44502 | Z3091: 0.0355
A3092: 44659 | B3092: 21.16 | D3092: 44656 | E3092: 27.4 | G3092: 44669 | H3092: 110.9 | J3092: 45028 | K3092: 15.9 | P3092: 44659 | Q3092: 25.17 | S3092: 44659 | T3092: 141.51 | V3092: 44659 | W3092: 24.75 | Y3092: 44503 | Z3092: 0.038
A3093: 44662 | B3093: 24.37 | D3093: 44657 | E3093: 28.91 | G3093: 44670 | H3093: 106.06 | J3093: 45029 | K3093: 14.65 | P3093: 44662 | Q3093: 27 | S3093: 44662 | T3093: 137.91 | V3093: 44662 | W3093: 32.12 | Y3093: 44504 | Z3093: 0.0304
A3094: 44663 | B3094: 24.26 | D3094: 44658 | E3094: 28.48 | G3094: 44671 | H3094: 103.03 | J3094: 45030 | K3094: 13.35 | P3094: 44663 | Q3094: 27.17 | S3094: 44663 | T3094: 137.62 | V3094: 44663 | W3094: 33.8 | Y3094: 44505 | Z3094: 0.0304
A3095: 44664 | B3095: 21.82 | D3095: 44659 | E3095: 28.06 | G3095: 44672 | H3095: 110.93 | J3095: 45033 | K3095: 14.51 | P3095: 44664 | Q3095: 25.54 | S3095: 44664 | T3095: 139.86 | V3095: 44664 | W3095: 29.8 | Y3095: 44508 | Z3095: 0.033
A3096: 44665 | B3096: 22.7 | D3096: 44662 | E3096: 30.75 | G3096: 44673 | H3096: 122.37 | J3096: 45034 | K3096: 14.71 | P3096: 44665 | Q3096: 26.03 | S3096: 44665 | T3096: 134.39 | V3096: 44665 | W3096: 32.78 | Y3096: 44509 | Z3096: 0.038
... A3954: 45881 | B3954: 14.73 | D3954: 45912 | E3954: 18.18 | G3954: 45924 | H3954: 99.99 | J3954: 46283 | K3954: 12.27 | P3954: 45917 | Q3954: 18.44 | S3954: 45919 | T3954: 146.97 | V3954: 45917 | W3954: 14.1 | Y3954: 45709 | Z3954: 4.306
A3955: 45882 | B3955: 14.49 | D3955: 45915 | E3955: 19.12 | G3955: 45925 | H3955: 100.34 | P3955: 45918 | Q3955: 18.52 | S3955: 45922 | T3955: 145.46 | V3955: 45918 | W3955: 13.49 | Y3955: 45712 | Z3955: 4.308
A3956: 45883 | B3956: 14.83 | D3956: 45916 | E3956: 19.57 | G3956: 45926 | H3956: 93.4 | P3956: 45919 | Q3956: 18.48 | S3956: 45923 | T3956: 146.53 | V3956: 45919 | W3956: 13.29 | Y3956: 45713 | Z3956: 4.2845
A3957: 45884 | B3957: 15.09 | D3957: 45917 | E3957: 19.02 | G3957: 45929 | H3957: 96.74 | P3957: 45922 | Q3957: 18.95 | S3957: 45924 | T3957: 145.87 | V3957: 45922 | W3957: 12.55 | Y3957: 45714 | Z3957: 4.2866
A3958: 45887 | B3958: 14.99 | D3958: 45918 | E3958: 18.86 | G3958: 45930 | H3958: 95.89 | P3958: 45923 | Q3958: 19.44 | S3958: 45925 | T3958: 145.89 | V3958: 45923 | W3958: 14.08 | Y3958: 45715 | Z3958: 4.3039
A3959: 45888 | B3959: 15.57 | D3959: 45919 | E3959: 18.74 | G3959: 45931 | H3959: 93.22 | P3959: 45924 | Q3959: 19.14 | S3959: 45926 | T3959: 141.51 | V3959: 45924 | W3959: 13.38 | Y3959: 45716 | Z3959: 4.2932
A3960: 45889 | B3960: 15.69 | D3960: 45922 | E3960: 19.42 | G3960: 45932 | H3960: 94.1 | P3960: 45925 | Q3960: 19.46 | S3960: 45929 | T3960: 143.03 | V3960: 45925 | W3960: 13.47 | Y3960: 45719 | Z3960: 4.3106
A3961: 45890 | B3961: 16.6 | D3961: 45923 | E3961: 20.13 | G3961: 45933 | H3961: 94.79 | P3961: 45926 | Q3961: 18.41 | S3961: 45930 | T3961: 143.44 | V3961: 45926 | W3961: 10.59 | Y3961: 45720 | Z3961: 4.3177
A3962: 45891 | B3962: 14.22 | D3962: 45924 | E3962: 19.93 | G3962: 45936 | H3962: 95.38 | P3962: 45929 | Q3962: 18.76 | S3962: 45931 | T3962: 143.68 | V3962: 45929 | W3962: 10.47 | Y3962: 45721 | Z3962: 4.3044
A3963: 45894 | B3963: 14.79 | D3963: 45925 | E3963: 20.54 | G3963: 45937 | H3963: 98.7 | P3963: 45930 | Q3963: 18.77 | S3963: 45932 | T3963: 145.93 | V3963: 45930 | W3963: 9.82 | Y3963: 45722 | Z3963: 4.3014
A3964: 45895 | B3964: 14.62 | D3964: 45926 | E3964: 19.33 | G3964: 45938 | H3964: 96.22 | P3964: 45931 | Q3964: 18.76 | S3964: 45933 | T3964: 144.65 | V3964: 45931 | W3964: 9.14 | Y3964: 45723 | Z3964: 4.2856
...

Sheet Latest
A1: Latest values (auto-updates after the pull)
A2: Term-structure ratios: <1 = contango (normal), >1 = backwardation (stress).
A4: Index | B4: Last date | C4: Last value | D4: Units
A5: =Control!$B$12 -> VIX | B5: =IFERROR(LOOKUP(2,1/ISNUMBER(Index_Data!$A$4:$A$6000),Index_Data!$A$4:$A$6000),"") -> 46283 | C5: =IFERROR(LOOKUP(2,1/ISNUMBER(Index_Data!$B$4:$B$6000),Index_Data!$B$4:$B$6000),"") -> 14.81 | D5: =Control!$E$12 -> Vol points (annualised %)
A6: =Control!$B$13 -> VXN | B6: =IFERROR(LOOKUP(2,1/ISNUMBER(Index_Data!$D$4:$D$6000),Index_Data!$D$4:$D$6000),"") -> 46283 | C6: =IFERROR(LOOKUP(2,1/ISNUMBER(Index_Data!$E$4:$E$6000),Index_Data!$E$4:$E$6000),"") -> 19.29 | D6: =Control!$E$13 -> Vol points (annualised %)
A7: =Control!$B$14 -> VVIX | B7: =IFERROR(LOOKUP(2,1/ISNUMBER(Index_Data!$G$4:$G$6000),Index_Data!$G$4:$G$6000),"") -> 46283 | C7: =IFERROR(LOOKUP(2,1/ISNUMBER(Index_Data!$H$4:$H$6000),Index_Data!$H$4:$H$6000),"") -> 87.38 | D7: =Control!$E$14 -> Vol points (annualised %)
A8: =Control!$B$15 -> VIX9D | B8: =IFERROR(LOOKUP(2,1/ISNUMBER(Index_Data!$J$4:$J$6000),Index_Data!$J$4:$J$6000),"") -> 46283 | C8: =IFERROR(LOOKUP(2,1/ISNUMBER(Index_Data!$K$4:$K$6000),Index_Data!$K$4:$K$6000),"") -> 12.27 | D8: =Control!$E$15 -> Vol points (annualised %)
A9: =Control!$B$16 -> DSPX | B9: =IFERROR(LOOKUP(2,1/ISNUMBER(Index_Data!$M$4:$M$6000),Index_Data!$M$4:$M$6000),"") -> 46283 | C9: =IFERROR(LOOKUP(2,1/ISNUMBER(Index_Data!$N$4:$N$6000),Index_Data!$N$4:$N$6000),"") -> 33.19 | D9: =Control!$E$16 -> Index level
A10: =Control!$B$17 -> VIX3M | B10: =IFERROR(LOOKUP(2,1/ISNUMBER(Index_Data!$P$4:$P$6000),Index_Data!$P$4:$P$6000),"") -> 46283 | C10: =IFERROR(LOOKUP(2,1/ISNUMBER(Index_Data!$Q$4:$Q$6000),Index_Data!$Q$4:$Q$6000),"") -> 18.24 | D10: =Control!$E$17 -> Vol points (annualised %)
A11: =Control!$B$18 -> SKEW | B11: =IFERROR(LOOKUP(2,1/ISNUMBER(Index_Data!$S$4:$S$6000),Index_Data!$S$4:$S$6000),"") -> 46283 | C11: =IFERROR(LOOKUP(2,1/ISNUMBER(Index_Data!$T$4:$T$6000),Index_Data!$T$4:$T$6000),"") -> 148.1 | D11: =Control!$E$18 -> Index level (100 = normal-like tails)
A12: =Control!$B$19 -> COR1M | B12: =IFERROR(LOOKUP(2,1/ISNUMBER(Index_Data!$V$4:$V$6000),Index_Data!$V$4:$V$6000),"") -> 46283 | C12: =IFERROR(LOOKUP(2,1/ISNUMBER(Index_Data!$W$4:$W$6000),Index_Data!$W$4:$W$6000),"") -> 9.23 | D12: =Control!$E$19 -> Index level (implied correlation x100)
A13: =Control!$B$20 -> USGG1M | B13: =IFERROR(LOOKUP(2,1/ISNUMBER(Index_Data!$Y$4:$Y$6000),Index_Data!$Y$4:$Y$6000),"") -> 46283 | C13: =IFERROR(LOOKUP(2,1/ISNUMBER(Index_Data!$Z$4:$Z$6000),Index_Data!$Z$4:$Z$6000),"") -> 3.8625 | D13: =Control!$E$20 -> Yield in percent (e.g. 4.25 = 4.25%)
A15: Derived
A16: VIX9D / VIX | C16: =IFERROR(C8/C5,"") -> 0.82849426
A17: VIX / VIX3M | C17: =IFERROR(C5/C10,"") -> 0.81195175
A18: VXN − VIX | C18: =IFERROR(C6-C5,"") -> 4.48
