Workbook
Name DvdEnd: Control!$B$6
Name DvdField: Control!$B$4
Name DvdStart: Control!$B$5
Name TkrSuffix: Control!$B$3

Sheet README
A1: README — Dividend history (Bloomberg BDS DVD_HIST_ALL)
A2: For human readers and AI models: read this sheet before using the data.
A4: Key | B4: Value
A5: content | B5: Full dividend/corporate-action history per security from Bloomberg DVD_HIST_ALL, 31 securities (27 stocks + SPY, QQQ, XLK, SMH).
A6: bloomberg_formula | B6: =_xll.BDS(security,"DVD_HIST_ALL","DVD_START_DT=20100101","DVD_END_DT=20261231") — dates on Control!B5:B6 -> #NAME?
A7: columns | B7: Declared Date | Ex-Date | Record Date | Payable Date | Dividend Amount | Dividend Frequency | Dividend Type
A8: dividend_announcement_date
A9: IMPORTANT_dividend_type | B9: DVD_HIST_ALL includes ALL dividend-type corporate actions, not only cash dividends. Rows can include stock splits, spin-offs, special cash, return of capital, etc. ALWAYS filter on the 'Dividend Type' column before summing or computing yield. For stock splits the 'Dividend Amount' is a split ratio, not a cash amount.
A10: ETF_distributions | B10: SPY/QQQ/XLK/SMH rows are fund distributions (may include income and capital-gain distributions, labelled by Dividend Type).
A11: amount_basis | B11: Per-share amount as declared at the time; treat as NOT back-adjusted for later splits unless verified on the terminal. Check before building a continuous per-share dividend series across splits (e.g. NVDA, AAPL, AVGO, GOOGL).
A12: non_payers | B12: Expected no regular cash dividends over the window: AMZN, TSLA, PLTR, MSTR, COIN, HOOD, SHOP, SMCI, NFLX, AMD, ADBE, NOW (flagged on Control col E). Their blocks may be EMPTY (#N/A-type result) or show only non-cash rows such as stock splits. An empty block is expected, NOT a failed pull.
A13: late_initiators | B13: META and GOOGL initiated dividends in 2024, CRM in 2024 — history starts there.
A14: row_order | B14: As returned by Bloomberg (not re-sorted).
A15: currency | B15: Amount currency as returned by Bloomberg per row; TSM is the NYSE ADR (check USD vs TWD and ADR ratio).
A16: layout | B16: Data sheet: row 1 ticker, row 2 Bloomberg security, row 3 payer flag, row 4 headers, data from row 5; 7 columns + 1 spacer per security. Rows NOT aligned across securities.
A17: source | B17: Bloomberg BDS via Excel add-in

Sheet Control
A1: Dividend History Pull — Control Panel
A2: Yellow cells are inputs (blue text).
A3: Ticker suffix | B3: US Equity | C3: Leading space.
A4: BDS field | B4: DVD_HIST_ALL
A5: Override: start | B5: DVD_START_DT=20100101 | C5: Keep the 'DVD_START_DT=' prefix; change the date only.
A6: Override: end | B6: DVD_END_DT=20261231 | C6: Keep the 'DVD_END_DT=' prefix.
A9: Security list
A10: # | B10: Ticker | C10: Bloomberg security | D10: Block col | E10: Regular cash dividend payer?
A11: 1 | B11: SPY | C11: =B11&TkrSuffix -> SPY US Equity | D11: A | E11: YES - ETF distributions
A12: 2 | B12: QQQ | C12: =B12&TkrSuffix -> QQQ US Equity | D12: I | E12: YES - ETF distributions
A13: 3 | B13: XLK | C13: =B13&TkrSuffix -> XLK US Equity | D13: Q | E13: YES - ETF distributions
A14: 4 | B14: SMH | C14: =B14&TkrSuffix -> SMH US Equity | D14: Y | E14: YES - ETF distributions
A15: 5 | B15: AAPL | C15: =B15&TkrSuffix -> AAPL US Equity | D15: AG | E15: YES
A16: 6 | B16: AMZN | C16: =B16&TkrSuffix -> AMZN US Equity | D16: AO | E16: NO - expected empty / non-cash rows only
A17: 7 | B17: GOOGL | C17: =B17&TkrSuffix -> GOOGL US Equity | D17: AW | E17: YES
A18: 8 | B18: META | C18: =B18&TkrSuffix -> META US Equity | D18: BE | E18: YES
A19: 9 | B19: MSFT | C19: =B19&TkrSuffix -> MSFT US Equity | D19: BM | E19: YES
A20: 10 | B20: NFLX | C20: =B20&TkrSuffix -> NFLX US Equity | D20: BU | E20: NO - expected empty / non-cash rows only
A21: 11 | B21: NVDA | C21: =B21&TkrSuffix -> NVDA US Equity | D21: CC | E21: YES
A22: 12 | B22: PLTR | C22: =B22&TkrSuffix -> PLTR US Equity | D22: CK | E22: NO - expected empty / non-cash rows only
... A41: 31 | B41: XOM | C41: =B41&TkrSuffix -> XOM US Equity | D41: IG | E41: YES

Sheet Dividend_Data
A1: =Control!$B$11 -> SPY | I1: =Control!$B$12 -> QQQ | Q1: =Control!$B$13 -> XLK | Y1: =Control!$B$14 -> SMH | AG1: =Control!$B$15 -> AAPL | AO1: =Control!$B$16 -> AMZN | AW1: =Control!$B$17 -> GOOGL | BE1: =Control!$B$18 -> META | BM1: =Control!$B$19 -> MSFT | BU1: =Control!$B$20 -> NFLX | CC1: =Control!$B$21 -> NVDA | CK1: =Control!$B$22 -> PLTR | CS1: =Control!$B$23 -> TSLA | DA1: =Control!$B$24 -> TSM | DI1: =Control!$B$25 -> AVGO | DQ1: =Control!$B$26 -> AMD | DY1: =Control!$B$27 -> MU | EG1: =Control!$B$28 -> MSTR | EO1: =Control!$B$29 -> COIN | EW1: =Control!$B$30 -> HOOD | FE1: =Control!$B$31 -> SHOP | FM1: =Control!$B$32 -> SMCI | FU1: =Control!$B$33 -> ORCL | GC1: =Control!$B$34 -> CRM | GK1: =Control!$B$35 -> ADBE | GS1: =Control!$B$36 -> NOW | HA1: =Control!$B$37 -> LLY | HI1: =Control!$B$38 -> UNH | HQ1: =Control!$B$39 -> JPM | HY1: =Control!$B$40 -> COST | IG1: =Control!$B$41 -> XOM
A2: =Control!$C$11 -> SPY US Equity | I2: =Control!$C$12 -> QQQ US Equity | Q2: =Control!$C$13 -> XLK US Equity | Y2: =Control!$C$14 -> SMH US Equity | AG2: =Control!$C$15 -> AAPL US Equity | AO2: =Control!$C$16 -> AMZN US Equity | AW2: =Control!$C$17 -> GOOGL US Equity | BE2: =Control!$C$18 -> META US Equity | BM2: =Control!$C$19 -> MSFT US Equity | BU2: =Control!$C$20 -> NFLX US Equity | CC2: =Control!$C$21 -> NVDA US Equity | CK2: =Control!$C$22 -> PLTR US Equity | CS2: =Control!$C$23 -> TSLA US Equity | DA2: =Control!$C$24 -> TSM US Equity | DI2: =Control!$C$25 -> AVGO US Equity | DQ2: =Control!$C$26 -> AMD US Equity | DY2: =Control!$C$27 -> MU US Equity | EG2: =Control!$C$28 -> MSTR US Equity | EO2: =Control!$C$29 -> COIN US Equity | EW2: =Control!$C$30 -> HOOD US Equity | FE2: =Control!$C$31 -> SHOP US Equity | FM2: =Control!$C$32 -> SMCI US Equity | FU2: =Control!$C$33 -> ORCL US Equity | GC2: =Control!$C$34 -> CRM US Equity | GK2: =Control!$C$35 -> ADBE US Equity | GS2: =Control!$C$36 -> NOW US Equity | HA2: =Control!$C$37 -> LLY US Equity | HI2: =Control!$C$38 -> UNH US Equity | HQ2: =Control!$C$39 -> JPM US Equity | HY2: =Control!$C$40 -> COST US Equity | IG2: =Control!$C$41 -> XOM US Equity
A3: ="Cash dividend payer: "&Control!$E$11 -> Cash dividend payer: YES - ETF distributions | I3: ="Cash dividend payer: "&Control!$E$12 -> Cash dividend payer: YES - ETF distributions | Q3: ="Cash dividend payer: "&Control!$E$13 -> Cash dividend payer: YES - ETF distributions | Y3: ="Cash dividend payer: "&Control!$E$14 -> Cash dividend payer: YES - ETF distributions | AG3: ="Cash dividend payer: "&Control!$E$15 -> Cash dividend payer: YES | AO3: ="Cash dividend payer: "&Control!$E$16 -> Cash dividend payer: NO - expected empty / non-cash rows only | AW3: ="Cash dividend payer: "&Control!$E$17 -> Cash dividend payer: YES | BE3: ="Cash dividend payer: "&Control!$E$18 -> Cash dividend payer: YES | BM3: ="Cash dividend payer: "&Control!$E$19 -> Cash dividend payer: YES | BU3: ="Cash dividend payer: "&Control!$E$20 -> Cash dividend payer: NO - expected empty / non-cash rows only | CC3: ="Cash dividend payer: "&Control!$E$21 -> Cash dividend payer: YES | CK3: ="Cash dividend payer: "&Control!$E$22 -> Cash dividend payer: NO - expected empty / non-cash rows only | CS3: ="Cash dividend payer: "&Control!$E$23 -> Cash dividend payer: NO - expected empty / non-cash rows only | DA3: ="Cash dividend payer: "&Control!$E$24 -> Cash dividend payer: YES | DI3: ="Cash dividend payer: "&Control!$E$25 -> Cash dividend payer: YES | DQ3: ="Cash dividend payer: "&Control!$E$26 -> Cash dividend payer: NO - expected empty / non-cash rows only | DY3: ="Cash dividend payer: "&Control!$E$27 -> Cash dividend payer: YES | EG3: ="Cash dividend payer: "&Control!$E$28 -> Cash dividend payer: NO - expected empty / non-cash rows only | EO3: ="Cash dividend payer: "&Control!$E$29 -> Cash dividend payer: NO - expected empty / non-cash rows only | EW3: ="Cash dividend payer: "&Control!$E$30 -> Cash dividend payer: NO - expected empty / non-cash rows only | FE3: ="Cash dividend payer: "&Control!$E$31 -> Cash dividend payer: NO - expected empty / non-cash rows only | FM3: ="Cash dividend payer: "&Control!$E$32 -> Cash dividend payer: NO - expected empty / non-cash rows only | FU3: ="Cash dividend payer: "&Control!$E$33 -> Cash dividend payer: YES | GC3: ="Cash dividend payer: "&Control!$E$34 -> Cash dividend payer: YES | GK3: ="Cash dividend payer: "&Control!$E$35 -> Cash dividend payer: NO - expected empty / non-cash rows only | GS3: ="Cash dividend payer: "&Control!$E$36 -> Cash dividend payer: NO - expected empty / non-cash rows only | HA3: ="Cash dividend payer: "&Control!$E$37 -> Cash dividend payer: YES | HI3: ="Cash dividend payer: "&Control!$E$38 -> Cash dividend payer: YES | HQ3: ="Cash dividend payer: "&Control!$E$39 -> Cash dividend payer: YES | HY3: ="Cash dividend payer: "&Control!$E$40 -> Cash dividend payer: YES | IG3: ="Cash dividend payer: "&Control!$E$41 -> Cash dividend payer: YES
A4: Declared Date | B4: Ex-Date | C4: Record Date | D4: Payable Date | E4: Dividend Amount | F4: Dividend Frequency | G4: Dividend Type | I4: Declared Date | J4: Ex-Date | K4: Record Date | L4: Payable Date | M4: Dividend Amount | N4: Dividend Frequency | O4: Dividend Type | Q4: Declared Date | R4: Ex-Date | S4: Record Date | T4: Payable Date | U4: Dividend Amount | V4: Dividend Frequency | W4: Dividend Type | Y4: Declared Date | Z4: Ex-Date | AA4: Record Date | AB4: Payable Date | AC4: Dividend Amount | AD4: Dividend Frequency | AE4: Dividend Type | AG4: Declared Date | AH4: Ex-Date | AI4: Record Date | AJ4: Payable Date | AK4: Dividend Amount | AL4: Dividend Frequency | AM4: Dividend Type | AO4: Declared Date | AP4: Ex-Date | AQ4: Record Date | AR4: Payable Date | AS4: Dividend Amount | AT4: Dividend Frequency | AU4: Dividend Type | AW4: Declared Date | AX4: Ex-Date | AY4: Record Date | AZ4: Payable Date | BA4: Dividend Amount | BB4: Dividend Frequency | BC4: Dividend Type | BE4: Declared Date | BF4: Ex-Date | BG4: Record Date | BH4: Payable Date | BI4: Dividend Amount | BJ4: Dividend Frequency | BK4: Dividend Type | BM4: Declared Date | BN4: Ex-Date | BO4: Record Date | BP4: Payable Date | BQ4: Dividend Amount | BR4: Dividend Frequency | BS4: Dividend Type | BU4: Declared Date | BV4: Ex-Date | BW4: Record Date | BX4: Payable Date | BY4: Dividend Amount | BZ4: Dividend Frequency | CA4: Dividend Type | CC4: Declared Date | CD4: Ex-Date | CE4: Record Date | CF4: Payable Date | CG4: Dividend Amount | CH4: Dividend Frequency | CI4: Dividend Type | CK4: Declared Date | CL4: Ex-Date | CM4: Record Date | CN4: Payable Date | CO4: Dividend Amount | CP4: Dividend Frequency | CQ4: Dividend Type | CS4: Declared Date | CT4: Ex-Date | CU4: Record Date | CV4: Payable Date | CW4: Dividend Amount | CX4: Dividend Frequency | CY4: Dividend Type | DA4: Declared Date | DB4: Ex-Date | DC4: Record Date | DD4: Payable Date | DE4: Dividend Amount | DF4: Dividend Frequency | DG4: Dividend Type | DI4: Declared Date | DJ4: Ex-Date | DK4: Record Date | DL4: Payable Date | DM4: Dividend Amount | DN4: Dividend Frequency | DO4: Dividend Type | DQ4: Declared Date | DR4: Ex-Date | DS4: Record Date | DT4: Payable Date | DU4: Dividend Amount | DV4: Dividend Frequency | DW4: Dividend Type | DY4: Declared Date | DZ4: Ex-Date | EA4: Record Date | EB4: Payable Date | EC4: Dividend Amount | ED4: Dividend Frequency | EE4: Dividend Type | EG4: Declared Date | EH4: Ex-Date | EI4: Record Date | EJ4: Payable Date | EK4: Dividend Amount | EL4: Dividend Frequency | EM4: Dividend Type | EO4: Declared Date | EP4: Ex-Date | EQ4: Record Date | ER4: Payable Date | ES4: Dividend Amount | ET4: Dividend Frequency | EU4: Dividend Type | EW4: Declared Date | EX4: Ex-Date | EY4: Record Date | EZ4: Payable Date | FA4: Dividend Amount | FB4: Dividend Frequency | FC4: Dividend Type | FE4: Declared Date | FF4: Ex-Date | FG4: Record Date | FH4: Payable Date | FI4: Dividend Amount | FJ4: Dividend Frequency | FK4: Dividend Type | FM4: Declared Date | FN4: Ex-Date | FO4: Record Date | FP4: Payable Date | FQ4: Dividend Amount | FR4: Dividend Frequency | FS4: Dividend Type | FU4: Declared Date | FV4: Ex-Date | FW4: Record Date | FX4: Payable Date | FY4: Dividend Amount | FZ4: Dividend Frequency | GA4: Dividend Type | GC4: Declared Date | GD4: Ex-Date | GE4: Record Date | GF4: Payable Date | GG4: Dividend Amount | GH4: Dividend Frequency | GI4: Dividend Type | GK4: Declared Date | GL4: Ex-Date | GM4: Record Date | GN4: Payable Date | GO4: Dividend Amount | GP4: Dividend Frequency | GQ4: Dividend Type | GS4: Declared Date | GT4: Ex-Date | GU4: Record Date | GV4: Payable Date | GW4: Dividend Amount | GX4: Dividend Frequency | GY4: Dividend Type | HA4: Declared Date | HB4: Ex-Date | HC4: Record Date | HD4: Payable Date | HE4: Dividend Amount | HF4: Dividend Frequency | HG4: Dividend Type | HI4: Declared Date | HJ4: Ex-Date | HK4: Record Date | HL4: Payable Date | HM4: Dividend Amount | HN4: Dividend Frequency | HO4: Dividend Type | HQ4: Declared Date | HR4: Ex-Date | HS4: Record Date | HT4: Payable Date | HU4: Dividend Amount | HV4: Dividend Frequency | HW4: Dividend Type | HY4: Declared Date | HZ4: Ex-Date | IA4: Record Date | IB4: Payable Date | IC4: Dividend Amount | ID4: Dividend Frequency | IE4: Dividend Type | IG4: Declared Date | IH4: Ex-Date | II4: Record Date | IJ4: Payable Date | IK4: Dividend Amount | IL4: Dividend Frequency | IM4: Dividend Type
A5: =_xll.BDS(A$2,DvdField,DvdStart,DvdEnd,"cols=7;rows=67") -> 46282 | B5: 46283 | C5: 46283 | D5: 46325 | E5: 1.888834 | F5: Quarter | G5: Income | I5: =_xll.BDS(I$2,DvdField,DvdStart,DvdEnd,"cols=7;rows=69") -> 46283 | J5: 46286 | K5: 46286 | L5: 46303 | M5: 0.75143 | N5: Quarter | O5: Income | Q5: =_xll.BDS(Q$2,DvdField,DvdStart,DvdEnd,"cols=7;rows=68") -> 46283 | R5: 46286 | S5: 46286 | T5: 46288 | U5: 0.220686 | V5: Quarter | W5: Income | Y5: =_xll.BDS(Y$2,DvdField,DvdStart,DvdEnd,"cols=7;rows=17") -> 46010 | Z5: 46013 | AA5: 46013 | AB5: 46017 | AC5: 1.1047 | AD5: Annual | AE5: Income | AG5: =_xll.BDS(AG$2,DvdField,DvdStart,DvdEnd,"cols=7;rows=59") -> 46233 | AH5: 46244 | AI5: 46244 | AJ5: 46247 | AK5: 0.27 | AL5: Quarter | AM5: Regular Cash | AO5: =_xll.BDS(AO$2,DvdField,DvdStart,DvdEnd,"cols=7;rows=1") -> 44629 | AP5: 44718 | AQ5: 44708 | AR5: 44715 | AS5: 20 | AT5: None | AU5: Stock Split | AW5: =_xll.BDS(AW$2,DvdField,DvdStart,DvdEnd,"cols=7;rows=12") -> 46225 | AX5: 46269 | AY5: 46272 | AZ5: 46279 | BA5: 0.22 | BB5: Quarter | BC5: Regular Cash | BE5: =_xll.BDS(BE$2,DvdField,DvdStart,DvdEnd,"cols=7;rows=12") -> 46275 | BF5: 46286 | BG5: 46286 | BH5: 46293 | BI5: 0.525 | BJ5: Quarter | BK5: Regular Cash | BM5: =_xll.BDS(BM$2,DvdField,DvdStart,DvdEnd,"cols=7;rows=68") -> 46280 | BN5: 46345 | BO5: 46345 | BP5: 46366 | BQ5: 0.98 | BR5: Quarter | BS5: Regular Cash | BU5: =_xll.BDS(BU$2,DvdField,DvdStart,DvdEnd,"cols=7;rows=3") -> 45960 | BV5: 45978 | BW5: 45971 | BX5: 45975 | BY5: 10 | BZ5: None | CA5: Stock Split | CC5: =_xll.BDS(CC$2,DvdField,DvdStart,DvdEnd,"cols=7;rows=58") -> 46260 | CD5: 46275 | CE5: 46275 | CF5: 46296 | CG5: 0.25 | CH5: Quarter | CI5: Regular Cash | CK5: =_xll.BDS(CK$2,DvdField,DvdStart,DvdEnd) -> #N/A Field Not Applicable | CS5: =_xll.BDS(CS$2,DvdField,DvdStart,DvdEnd,"cols=7;rows=2") -> 44778 | CT5: 44798 | CU5: 44790 | CV5: 44797 | CW5: 3 | CX5: None | CY5: Stock Split | DA5: =_xll.BDS(DA$2,DvdField,DvdStart,DvdEnd,"cols=7;rows=40") -> 46245 | DB5: 46366 | DC5: 46366 | DD5: 46394 | DE5: 0.857497 | DF5: Quarter | DG5: Regular Cash | DI5: =_xll.BDS(DI$2,DvdField,DvdStart,DvdEnd,"cols=7;rows=65") -> 46267 | DJ5: 46286 | DK5: 46286 | DL5: 46295 | DM5: 0.65 | DN5: Quarter | DO5: Regular Cash | DQ5: =_xll.BDS(DQ$2,DvdField,DvdStart,DvdEnd) -> #N/A Field Not Applicable | DY5: =_xll.BDS(DY$2,DvdField,DvdStart,DvdEnd,"cols=7;rows=21") -> 46197 | DZ5: 46209 | EA5: 46209 | EB5: 46224 | EC5: 0.15 | ED5: Quarter | EE5: Regular Cash | EG5: =_xll.BDS(EG$2,DvdField,DvdStart,DvdEnd,"cols=7;rows=1") -> 45484 | EH5: 45512 | EI5: 45505 | EJ5: 45511 | EK5: 10 | EL5: None | EM5: Stock Split | EO5: =_xll.BDS(EO$2,DvdField,DvdStart,DvdEnd) -> #N/A Field Not Applicable | EW5: =_xll.BDS(EW$2,DvdField,DvdStart,DvdEnd) -> #N/A Field Not Applicable | FE5: =_xll.BDS(FE$2,DvdField,DvdStart,DvdEnd,"cols=7;rows=1") -> 44662 | FF5: 44741 | FG5: 44734 | FH5: 44740 | FI5: 10 | FJ5: None | FK5: Stock Split | FM5: =_xll.BDS(FM$2,DvdField,DvdStart,DvdEnd,"cols=7;rows=1") -> 45510 | FN5: 45566 | FO5: #N/A N/A | FP5: #N/A N/A | FQ5: 10 | FR5: None | FS5: Stock Split | FU5: =_xll.BDS(FU$2,DvdField,DvdStart,DvdEnd,"cols=7;rows=69") -> 46275 | FV5: 46304 | FW5: 46304 | FX5: 46318 | FY5: 0.5 | FZ5: Quarter | GA5: Regular Cash | GC5: =_xll.BDS(GC$2,DvdField,DvdStart,DvdEnd,"cols=7;rows=12") -> 46268 | GD5: 46282 | GE5: 46282 | GF5: 46303 | GG5: 0.44 | GH5: Quarter | GI5: Regular Cash | GK5: =_xll.BDS(GK$2,DvdField,DvdStart,DvdEnd) -> #N/A Field Not Applicable | GS5: =_xll.BDS(GS$2,DvdField,DvdStart,DvdEnd,"cols=7;rows=1") -> 45959 | GT5: 46009 | GU5: 46007 | GV5: 46008 | GW5: 5 | GX5: None | GY5: Stock Split | HA5: =_xll.BDS(HA$2,DvdField,DvdStart,DvdEnd,"cols=7;rows=68") -> 46195 | HB5: 46248 | HC5: 46248 | HD5: 46275 | HE5: 1.73 | HF5: Quarter | HG5: Regular Cash | HI5: =_xll.BDS(HI$2,DvdField,DvdStart,DvdEnd,"cols=7;rows=67") -> 46246 | HJ5: 46279 | HK5: 46279 | HL5: 46287 | HM5: 2.32 | HN5: Quarter | HO5: Regular Cash | HQ5: =_xll.BDS(HQ$2,DvdField,DvdStart,DvdEnd,"cols=7;rows=68") -> 46280 | HR5: 46301 | HS5: 46301 | HT5: 46326 | HU5: 1.65 | HV5: Quarter | HW5: Regular Cash | HY5: =_xll.BDS(HY$2,DvdField,DvdStart,DvdEnd,"cols=7;rows=72") -> 46211 | HZ5: 46227 | IA5: 46227 | IB5: 46241 | IC5: 1.47 | ID5: Quarter | IE5: Regular Cash | IG5: =_xll.BDS(IG$2,DvdField,DvdStart,DvdEnd,"cols=7;rows=67") -> 46234 | IH5: 46251 | II5: 46251 | IJ5: 46275 | IK5: 1.03 | IL5: Quarter | IM5: Regular Cash
A6: 46190 | B6: 46191 | C6: 46191 | D6: 46234 | E6: 1.903516 | F6: Quarter | G6: Income | I6: 46191 | J6: 46195 | K6: 46195 | L6: 46213 | M6: 0.81349 | N6: Quarter | O6: Income | Q6: 46191 | R6: 46195 | S6: 46195 | T6: 46197 | U6: 0.227918 | V6: Quarter | W6: Income | Y6: 45652 | Z6: 45653 | AA6: 45653 | AB6: 45656 | AC6: -2.4245363e-14 | AD6: Annual | AE6: Omitted | AG6: 46142 | AH6: 46153 | AI6: 46153 | AJ6: 46156 | AK6: 0.27 | AL6: Quarter | AM6: Regular Cash | AW6: 46139 | AX6: 46181 | AY6: 46181 | AZ6: 46188 | BA6: 0.22 | BB6: Quarter | BC6: Regular Cash | BE6: 46170 | BF6: 46188 | BG6: 46188 | BH6: 46198 | BI6: 0.525 | BJ6: Quarter | BK6: Regular Cash | BM6: 46183 | BN6: 46254 | BO6: 46254 | BP6: 46275 | BQ6: 0.91 | BR6: Quarter | BS6: Regular Cash | BU6: 42178 | BV6: 42200 | BW6: 42187 | BX6: 42199 | BY6: 7 | BZ6: None | CA6: Stock Split | CC6: 46162 | CD6: 46177 | CE6: 46177 | CF6: 46199 | CG6: 0.25 | CH6: Quarter | CI6: Regular Cash | CS6: 44054 | CT6: 44074 | CU6: 44064 | CV6: 44071 | CW6: 5 | CX6: None | CY6: Stock Split | DA6: 46154 | DB6: 46281 | DC6: 46281 | DD6: 46303 | DE6: 0.874889 | DF6: Quarter | DG6: Regular Cash | DI6: 46176 | DJ6: 46195 | DK6: 46195 | DL6: 46203 | DM6: 0.65 | DN6: Quarter | DO6: Regular Cash | DY6: 46099 | DZ6: 46111 | EA6: 46111 | EB6: 46127 | EC6: 0.15 | ED6: Quarter | EE6: Regular Cash | FU6: 46183 | FV6: 46213 | FW6: 46213 | FX6: 46227 | FY6: 0.5 | FZ6: Quarter | GA6: Regular Cash | GC6: 46170 | GD6: 46184 | GE6: 46184 | GF6: 46205 | GG6: 0.44 | GH6: Quarter | GI6: Regular Cash | HA6: 46146 | HB6: 46157 | HC6: 46157 | HD6: 46183 | HE6: 1.73 | HF6: Quarter | HG6: Regular Cash | HI6: 46176 | HJ6: 46188 | HK6: 46188 | HL6: 46196 | HM6: 2.32 | HN6: Quarter | HO6: Regular Cash | HQ6: 46160 | HR6: 46209 | HS6: 46209 | HT6: 46234 | HU6: 1.5 | HV6: Quarter | HW6: Regular Cash | HY6: 46127 | HZ6: 46143 | IA6: 46143 | IB6: 46157 | IC6: 1.47 | ID6: Quarter | IE6: Regular Cash | IG6: 46143 | IH6: 46157 | II6: 46157 | IJ6: 46183 | IK6: 1.03 | IL6: Quarter | IM6: Regular Cash
A7: 46100 | B7: 46101 | C7: 46101 | D7: 46142 | E7: 1.796999 | F7: Quarter | G7: Income | I7: 46101 | J7: 46104 | K7: 46104 | L7: 46108 | M7: 0.73282 | N7: Quarter | O7: Income | Q7: 46101 | R7: 46104 | S7: 46104 | T7: 46106 | U7: 0.167505 | V7: Quarter | W7: Income | Y7: 45646 | Z7: 45649 | AA7: 45649 | AB7: 45650 | AC7: 1.0713 | AD7: Annual | AE7: Income | AG7: 46051 | AH7: 46062 | AI7: 46062 | AJ7: 46065 | AK7: 0.26 | AL7: Quarter | AM7: Regular Cash | AW7: 46057 | AX7: 46090 | AY7: 46090 | AZ7: 46097 | BA7: 0.21 | BB7: Quarter | BC7: Regular Cash | BE7: 46065 | BF7: 46097 | BG7: 46097 | BH7: 46107 | BI7: 0.525 | BJ7: Quarter | BK7: Regular Cash | BM7: 46091 | BN7: 46163 | BO7: 46163 | BP7: 46184 | BQ7: 0.91 | BR7: Quarter | BS7: Regular Cash | BU7: 41218 | BV7: 41218 | BW7: 41215 | BX7: #N/A N/A | BY7: 1 | BZ7: None | CA7: Poison Pill Rights | CC7: 46078 | CD7: 46092 | CE7: 46092 | CF7: 46113 | CG7: 0.01 | CH7: Quarter | CI7: Regular Cash | DA7: 46063 | DB7: 46184 | DC7: 46184 | DD7: 46212 | DE7: 0.742067 | DF7: Quarter | DG7: Regular Cash | DI7: 46085 | DJ7: 46104 | DK7: 46104 | DL7: 46112 | DM7: 0.65 | DN7: Quarter | DO7: Regular Cash | DY7: 46008 | DZ7: 46020 | EA7: 46020 | EB7: 46036 | EC7: 0.115 | ED7: Quarter | EE7: Regular Cash | FU7: 46091 | FV7: 46121 | FW7: 46121 | FX7: 46136 | FY7: 0.5 | FZ7: Quarter | GA7: Regular Cash | GC7: 46078 | GD7: 46121 | GE7: 46121 | GF7: 46135 | GG7: 0.44 | GH7: Quarter | GI7: Regular Cash | HA7: 45999 | HB7: 46066 | HC7: 46066 | HD7: 46091 | HE7: 1.73 | HF7: Quarter | HG7: Regular Cash | HI7: 46078 | HJ7: 46090 | HK7: 46090 | HL7: 46098 | HM7: 2.21 | HN7: Quarter | HO7: Regular Cash | HQ7: 46098 | HR7: 46118 | HS7: 46118 | HT7: 46142 | HU7: 1.5 | HV7: Quarter | HW7: Regular Cash | HY7: 46037 | HZ7: 46052 | IA7: 46052 | IB7: 46066 | IC7: 1.3 | ID7: Quarter | IE7: Regular Cash | IG7: 46052 | IH7: 46065 | II7: 46065 | IJ7: 46091 | IK7: 1.03 | IL7: Quarter | IM7: Regular Cash
A8: 46009 | B8: 46010 | C8: 46010 | D8: 46052 | E8: 1.993368 | F8: Quarter | G8: Income | I8: 46010 | J8: 46013 | K8: 46013 | L8: 46022 | M8: 0.79408 | N8: Quarter | O8: Income | Q8: 46010 | R8: 46013 | S8: 46013 | T8: 46015 | U8: 0.218827 | V8: Quarter | W8: Income | Y8: 45286 | Z8: 45287 | AA8: 45288 | AB8: 45289 | AC8: -2.4245363e-14 | AD8: Annual | AE8: Omitted | AG8: 45960 | AH8: 45971 | AI8: 45971 | AJ8: 45974 | AK8: 0.26 | AL8: Quarter | AM8: Regular Cash | AW8: 45964 | AX8: 45999 | AY8: 45999 | AZ8: 46006 | BA8: 0.21 | BB8: Quarter | BC8: Regular Cash | BE8: 45994 | BF8: 46006 | BG8: 46006 | BH8: 46014 | BI8: 0.525 | BJ8: Quarter | BK8: Regular Cash | BM8: 45993 | BN8: 46072 | BO8: 46072 | BP8: 46093 | BQ8: 0.91 | BR8: Quarter | BS8: Regular Cash | CC8: 45980 | CD8: 45995 | CE8: 45995 | CF8: 46017 | CG8: 0.01 | CH8: Quarter | CI8: Regular Cash | DA8: 45973 | DB8: 46098 | DC8: 46098 | DD8: 46121 | DE8: 0.741788 | DF8: Quarter | DG8: Regular Cash | DI8: 46002 | DJ8: 46013 | DK8: 46013 | DL8: 46022 | DM8: 0.65 | DN8: Quarter | DO8: Regular Cash | DY8: 45923 | DZ8: 45933 | EA8: 45933 | EB8: 45951 | EC8: 0.115 | ED8: Quarter | EE8: Regular Cash | FU8: 46001 | FV8: 46031 | FW8: 46031 | FX8: 46045 | FY8: 0.5 | FZ8: Quarter | GA8: Regular Cash | GC8: 45995 | GD8: 46009 | GE8: 46009 | GF8: 46030 | GG8: 0.416 | GH8: Quarter | GI8: Regular Cash | HA8: 45957 | HB8: 45975 | HC8: 45975 | HD8: 46001 | HE8: 1.5 | HF8: Quarter | HG8: Regular Cash | HI8: 45968 | HJ8: 45999 | HK8: 45999 | HL8: 46007 | HM8: 2.21 | HN8: Quarter | HO8: Regular Cash | HQ8: 46000 | HR8: 46028 | HS8: 46028 | HT8: 46053 | HU8: 1.5 | HV8: Quarter | HW8: Regular Cash | HY8: 45945 | HZ8: 45961 | IA8: 45961 | IB8: 45975 | IC8: 1.3 | ID8: Quarter | IE8: Regular Cash | IG8: 45961 | IH8: 45975 | II8: 45975 | IJ8: 46001 | IK8: 1.03 | IL8: Quarter | IM8: Regular Cash
A9: 45918 | B9: 45919 | C9: 45919 | D9: 45961 | E9: 1.831114 | F9: Quarter | G9: Income | I9: 45919 | J9: 45922 | K9: 45922 | L9: 45961 | M9: 0.69395 | N9: Quarter | O9: Income | Q9: 45981 | R9: 45996 | S9: 45993 | T9: 45995 | U9: 2 | V9: None | W9: Stock Split | Y9: 45275 | Z9: 45278 | AA9: 45279 | AB9: 45282 | AC9: 1.0427 | AD9: Annual | AE9: Income | AG9: 45869 | AH9: 45880 | AI9: 45880 | AJ9: 45883 | AK9: 0.26 | AL9: Quarter | AM9: Regular Cash | AW9: 45861 | AX9: 45908 | AY9: 45908 | AZ9: 45915 | BA9: 0.21 | BB9: Quarter | BC9: Regular Cash | BE9: 45911 | BF9: 45922 | BG9: 45922 | BH9: 45929 | BI9: 0.525 | BJ9: Quarter | BK9: Regular Cash | BM9: 45915 | BN9: 45981 | BO9: 45981 | BP9: 46002 | BQ9: 0.91 | BR9: Quarter | BS9: Regular Cash | CC9: 45896 | CD9: 45911 | CE9: 45911 | CF9: 45932 | CG9: 0.01 | CH9: Quarter | CI9: Regular Cash | DA9: 45881 | DB9: 46002 | DC9: 46002 | DD9: 46030 | DE9: 0.628382 | DF9: Quarter | DG9: Regular Cash | DI9: 45904 | DJ9: 45922 | DK9: 45922 | DL9: 45930 | DM9: 0.59 | DN9: Quarter | DO9: Regular Cash | DY9: 45833 | DZ9: 45845 | EA9: 45845 | EB9: 45860 | EC9: 0.115 | ED9: Quarter | EE9: Regular Cash | FU9: 45909 | FV9: 45939 | FW9: 45939 | FX9: 45953 | FY9: 0.5 | FZ9: Quarter | GA9: Regular Cash | GC9: 45904 | GD9: 45917 | GE9: 45917 | GF9: 45939 | GG9: 0.416 | GH9: Quarter | GI9: Regular Cash | HA9: 45831 | HB9: 45884 | HC9: 45884 | HD9: 45910 | HE9: 1.5 | HF9: Quarter | HG9: Regular Cash | HI9: 45882 | HJ9: 45915 | HK9: 45915 | HL9: 45923 | HM9: 2.21 | HN9: Quarter | HO9: Regular Cash | HQ9: 45916 | HR9: 45936 | HS9: 45936 | HT9: 45961 | HU9: 1.5 | HV9: Quarter | HW9: Regular Cash | HY9: 45854 | HZ9: 45870 | IA9: 45870 | IB9: 45884 | IC9: 1.3 | ID9: Quarter | IE9: Regular Cash | IG9: 45870 | IH9: 45884 | II9: 45884 | IJ9: 45910 | IK9: 0.99 | IL9: Quarter | IM9: Regular Cash
A10: 45826 | B10: 45828 | C10: 45828 | D10: 45869 | E10: 1.761117 | F10: Quarter | G10: Income | I10: 45828 | J10: 45831 | K10: 45831 | L10: 45869 | M10: 0.59111 | N10: Quarter | O10: Income | Q10: 45919 | R10: 45922 | S10: 45922 | T10: 45924 | U10: 0.178934 | V10: Quarter | W10: Income | Y10: 45027 | Z10: 45051 | AA10: 45049 | AB10: 45050 | AC10: 2 | AD10: None | AE10: Stock Split | AG10: 45778 | AH10: 45789 | AI10: 45789 | AJ10: 45792 | AK10: 0.26 | AL10: Quarter | AM10: Regular Cash | AW10: 45771 | AX10: 45817 | AY10: 45817 | AZ10: 45824 | BA10: 0.21 | BB10: Quarter | BC10: Regular Cash | BE10: 45806 | BF10: 45824 | BG10: 45824 | BH10: 45834 | BI10: 0.525 | BJ10: Quarter | BK10: Regular Cash | BM10: 45818 | BN10: 45890 | BO10: 45890 | BP10: 45911 | BQ10: 0.83 | BR10: Quarter | BS10: Regular Cash | CC10: 45805 | CD10: 45819 | CE10: 45819 | CF10: 45841 | CG10: 0.01 | CH10: Quarter | CI10: Regular Cash | DA10: 45790 | DB10: 45916 | DC10: 45916 | DD10: 45939 | DE10: 0.649352 | DF10: Quarter | DG10: Regular Cash | DI10: 45813 | DJ10: 45828 | DK10: 45828 | DL10: 45838 | DM10: 0.59 | DN10: Quarter | DO10: Regular Cash | DY10: 45736 | DZ10: 45747 | EA10: 45747 | EB10: 45762 | EC10: 0.115 | ED10: Quarter | EE10: Regular Cash | FU10: 45819 | FV10: 45848 | FW10: 45848 | FX10: 45862 | FY10: 0.5 | FZ10: Quarter | GA10: Regular Cash | GC10: 45813 | GD10: 45826 | GE10: 45826 | GF10: 45848 | GG10: 0.416 | GH10: Quarter | GI10: Regular Cash | HA10: 45782 | HB10: 45793 | HC10: 45793 | HD10: 45818 | HE10: 1.5 | HF10: Quarter | HG10: Regular Cash | HI10: 45812 | HJ10: 45824 | HK10: 45824 | HL10: 45832 | HM10: 2.21 | HN10: Quarter | HO10: Regular Cash | HQ10: 45796 | HR10: 45841 | HS10: 45841 | HT10: 45869 | HU10: 1.4 | HV10: Quarter | HW10: Regular Cash | HY10: 45763 | HZ10: 45779 | IA10: 45779 | IB10: 45793 | IC10: 1.3 | ID10: Quarter | IE10: Regular Cash | IG10: 45779 | IH10: 45792 | II10: 45792 | IJ10: 45818 | IK10: 0.99 | IL10: Quarter | IM10: Regular Cash
A11: 45736 | B11: 45737 | C11: 45737 | D11: 45777 | E11: 1.695528 | F11: Quarter | G11: Income | I11: 45737 | J11: 45740 | K11: 45740 | L11: 45777 | M11: 0.71571 | N11: Quarter | O11: Income | Q11: 45828 | R11: 45831 | S11: 45831 | T11: 45833 | U11: 0.198754 | V11: Quarter | W11: Income | Y11: 44911 | Z11: 44914 | AA11: 44915 | AB11: 44918 | AC11: 1.2005 | AD11: Annual | AE11: Income | AG11: 45687 | AH11: 45698 | AI11: 45698 | AJ11: 45701 | AK11: 0.25 | AL11: Quarter | AM11: Regular Cash | AW11: 45692 | AX11: 45726 | AY11: 45726 | AZ11: 45733 | BA11: 0.2 | BB11: Quarter | BC11: Regular Cash | BE11: 45701 | BF11: 45730 | BG11: 45730 | BH11: 45742 | BI11: 0.525 | BJ11: Quarter | BK11: Regular Cash | BM11: 45727 | BN11: 45792 | BO11: 45792 | BP11: 45820 | BQ11: 0.83 | BR11: Quarter | BS11: Regular Cash | CC11: 45714 | CD11: 45728 | CE11: 45728 | CF11: 45749 | CG11: 0.01 | CH11: Quarter | CI11: Regular Cash | DA11: 45700 | DB11: 45820 | DC11: 45820 | DD11: 45848 | DE11: 0.616441 | DF11: Quarter | DG11: Regular Cash | DI11: 45722 | DJ11: 45736 | DK11: 45736 | DL11: 45747 | DM11: 0.59 | DN11: Quarter | DO11: Regular Cash | DY11: 45644 | DZ11: 45656 | EA11: 45656 | EB11: 45672 | EC11: 0.115 | ED11: Quarter | EE11: Regular Cash | FU11: 45726 | FV11: 45757 | FW11: 45757 | FX11: 45770 | FY11: 0.5 | FZ11: Quarter | GA11: Regular Cash | GC11: 45743 | GD11: 45757 | GE11: 45757 | GF11: 45771 | GG11: 0.416 | GH11: Quarter | GI11: Regular Cash | HA11: 45635 | HB11: 45702 | HC11: 45702 | HD11: 45726 | HE11: 1.5 | HF11: Quarter | HG11: Regular Cash | HI11: 45712 | HJ11: 45726 | HK11: 45726 | HL11: 45734 | HM11: 2.1 | HN11: Quarter | HO11: Regular Cash | HQ11: 45734 | HR11: 45751 | HS11: 45751 | HT11: 45777 | HU11: 1.4 | HV11: Quarter | HW11: Regular Cash | HY11: 45680 | HZ11: 45695 | IA11: 45695 | IB11: 45709 | IC11: 1.16 | ID11: Quarter | IE11: Regular Cash | IG11: 45688 | IH11: 45700 | II11: 45700 | IJ11: 45726 | IK11: 0.99 | IL11: Quarter | IM11: Regular Cash
A12: 45645 | B12: 45646 | C12: 45646 | D12: 45688 | E12: 1.965548 | F12: Quarter | G12: Income | I12: 45646 | J12: 45649 | K12: 45649 | L12: 45657 | M12: 0.83466 | N12: Quarter | O12: Income | Q12: 45737 | R12: 45740 | S12: 45740 | T12: 45742 | U12: 0.187446 | V12: Quarter | W12: Income | Y12: 44547 | Z12: 44550 | AA12: 44551 | AB12: 44557 | AC12: 0.78665 | AD12: Annual | AE12: Income | AG12: 45596 | AH12: 45604 | AI12: 45607 | AJ12: 45610 | AK12: 0.25 | AL12: Quarter | AM12: Regular Cash | AW12: 45595 | AX12: 45635 | AY12: 45635 | AZ12: 45642 | BA12: 0.2 | BB12: Quarter | BC12: Regular Cash | BE12: 45631 | BF12: 45642 | BG12: 45642 | BH12: 45653 | BI12: 0.5 | BJ12: Quarter | BK12: Regular Cash | BM12: 45629 | BN12: 45708 | BO12: 45708 | BP12: 45729 | BQ12: 0.83 | BR12: Quarter | BS12: Regular Cash | CC12: 45616 | CD12: 45631 | CE12: 45631 | CF12: 45653 | CG12: 0.01 | CH12: Quarter | CI12: Regular Cash | DA12: 45608 | DB12: 45734 | DC12: 45734 | DD12: 45757 | DE12: 0.535377 | DF12: Quarter | DG12: Regular Cash | DI12: 45638 | DJ12: 45649 | DK12: 45649 | DL12: 45657 | DM12: 0.59 | DN12: Quarter | DO12: Regular Cash | DY12: 45560 | DZ12: 45572 | EA12: 45572 | EB12: 45588 | EC12: 0.115 | ED12: Quarter | EE12: Regular Cash | FU12: 45635 | FV12: 45667 | FW12: 45666 | FX12: 45680 | FY12: 0.4 | FZ12: Quarter | GA12: Regular Cash | GC12: 45631 | GD12: 45644 | GE12: 45644 | GF12: 45666 | GG12: 0.4 | GH12: Quarter | GI12: Regular Cash | HA12: 45593 | HB12: 45611 | HC12: 45611 | HD12: 45636 | HE12: 1.3 | HF12: Quarter | HG12: Regular Cash | HI12: 45602 | HJ12: 45635 | HK12: 45635 | HL12: 45643 | HM12: 2.1 | HN12: Quarter | HO12: Regular Cash | HQ12: 45635 | HR12: 45663 | HS12: 45663 | HT12: 45688 | HU12: 1.25 | HV12: Quarter | HW12: Regular Cash | HY12: 45581 | HZ12: 45597 | IA12: 45597 | IB12: 45611 | IC12: 1.16 | ID12: Quarter | IE12: Regular Cash | IG12: 45597 | IH12: 45610 | II12: 45610 | IJ12: 45636 | IK12: 0.99 | IL12: Quarter | IM12: Regular Cash
A13: 45554 | B13: 45555 | C13: 45555 | D13: 45596 | E13: 1.745531 | F13: Quarter | G13: Income | I13: 45556 | J13: 45558 | K13: 45558 | L13: 45596 | M13: 0.67686 | N13: Quarter | O13: Income | Q13: 45646 | R13: 45649 | S13: 45649 | T13: 45652 | U13: 0.192979 | V13: Quarter | W13: Income | Y13: 44183 | Z13: 44186 | AA13: 44187 | AB13: 44193 | AC13: 0.7511 | AD13: Annual | AE13: Income | AG13: 45505 | AH13: 45516 | AI13: 45516 | AJ13: 45519 | AK13: 0.25 | AL13: Quarter | AM13: Regular Cash | AW13: 45498 | AX13: 45544 | AY13: 45544 | AZ13: 45551 | BA13: 0.2 | BB13: Quarter | BC13: Regular Cash | BE13: 45540 | BF13: 45551 | BG13: 45551 | BH13: 45561 | BI13: 0.5 | BJ13: Quarter | BK13: Regular Cash | BM13: 45551 | BN13: 45617 | BO13: 45617 | BP13: 45638 | BQ13: 0.83 | BR13: Quarter | BS13: Regular Cash | CC13: 45532 | CD13: 45547 | CE13: 45547 | CF13: 45568 | CG13: 0.01 | CH13: Quarter | CI13: Regular Cash | DA13: 45517 | DB13: 45638 | DC13: 45638 | DD13: 45666 | DE13: 0.480404 | DF13: Quarter | DG13: Regular Cash | DI13: 45540 | DJ13: 45554 | DK13: 45554 | DL13: 45565 | DM13: 0.53 | DN13: Quarter | DO13: Regular Cash | DY13: 45469 | DZ13: 45481 | EA13: 45481 | EB13: 45496 | EC13: 0.115 | ED13: Quarter | EE13: Regular Cash | FU13: 45544 | FV13: 45575 | FW13: 45575 | FX13: 45589 | FY13: 0.4 | FZ13: Quarter | GA13: Regular Cash | GC13: 45540 | GD13: 45553 | GE13: 45553 | GF13: 45573 | GG13: 0.4 | GH13: Quarter | GI13: Regular Cash | HA13: 45467 | HB13: 45519 | HC13: 45519 | HD13: 45545 | HE13: 1.3 | HF13: Quarter | HG13: Regular Cash | HI13: 45511 | HJ13: 45551 | HK13: 45551 | HL13: 45559 | HM13: 2.1 | HN13: Quarter | HO13: Regular Cash | HQ13: 45552 | HR13: 45569 | HS13: 45569 | HT13: 45596 | HU13: 1.25 | HV13: Quarter | HW13: Regular Cash | HY13: 45483 | HZ13: 45499 | IA13: 45499 | IB13: 45513 | IC13: 1.16 | ID13: Quarter | IE13: Regular Cash | IG13: 45506 | IH13: 45519 | II13: 45519 | IJ13: 45545 | IK13: 0.95 | IL13: Quarter | IM13: Regular Cash
A14: 45463 | B14: 45464 | C14: 45464 | D14: 45504 | E14: 1.759024 | F14: Quarter | G14: Income | I14: 45464 | J14: 45467 | K14: 45467 | L14: 45504 | M14: 0.7615 | N14: Quarter | O14: Income | Q14: 45555 | R14: 45558 | S14: 45558 | T14: 45560 | U14: 0.199257 | V14: Quarter | W14: Income | Y14: 43819 | Z14: 43822 | AA14: 43823 | AB14: 43829 | AC14: 1.0611 | AD14: Annual | AE14: Income | AG14: 45414 | AH14: 45422 | AI14: 45425 | AJ14: 45428 | AK14: 0.25 | AL14: Quarter | AM14: Regular Cash | AW14: 45407 | AX14: 45453 | AY14: 45453 | AZ14: 45460 | BA14: 0.2 | BB14: Quarter | BC14: Regular Cash | BE14: 45442 | BF14: 45457 | BG14: 45457 | BH14: 45469 | BI14: 0.5 | BJ14: Quarter | BK14: Regular Cash | BM14: 45455 | BN14: 45519 | BO14: 45519 | BP14: 45547 | BQ14: 0.75 | BR14: Quarter | BS14: Regular Cash | CC14: 45434 | CD14: 45454 | CE14: 45454 | CF14: 45471 | CG14: 0.01 | CH14: Quarter | CI14: Regular Cash | DA14: 45422 | DB14: 45547 | DC14: 45547 | DD14: 45574 | DE14: 0.493613 | DF14: Quarter | DG14: Regular Cash | DI14: 45455 | DJ14: 45488 | DK14: 45484 | DL14: 45485 | DM14: 10 | DN14: None | DO14: Stock Split | DY14: 45371 | DZ14: 45379 | EA14: 45383 | EB14: 45398 | EC14: 0.115 | ED14: Quarter | EE14: Regular Cash | FU14: 45454 | FV14: 45484 | FW14: 45484 | FX14: 45498 | FY14: 0.4 | FZ14: Quarter | GA14: Regular Cash | GC14: 45470 | GD14: 45482 | GE14: 45482 | GF14: 45498 | GG14: 0.4 | GH14: Quarter | GI14: Regular Cash | HA14: 45418 | HB14: 45427 | HC14: 45428 | HD14: 45453 | HE14: 1.3 | HF14: Quarter | HG14: Regular Cash | HI14: 45448 | HJ14: 45460 | HK14: 45460 | HL14: 45468 | HM14: 2.1 | HN14: Quarter | HO14: Regular Cash | HQ14: 45432 | HR14: 45478 | HS14: 45478 | HT14: 45504 | HU14: 1.15 | HV14: Quarter | HW14: Regular Cash | HY14: 45392 | HZ14: 45407 | IA14: 45408 | IB14: 45422 | IC14: 1.16 | ID14: Quarter | IE14: Regular Cash | IG14: 45408 | IH14: 45426 | II14: 45427 | IJ14: 45453 | IK14: 0.95 | IL14: Quarter | IM14: Regular Cash
A15: 45365 | B15: 45366 | C15: 45369 | D15: 45412 | E15: 1.594937 | F15: Quarter | G15: Income | I15: 45366 | J15: 45369 | K15: 45370 | L15: 45412 | M15: 0.57345 | N15: Quarter | O15: Income | Q15: 45464 | R15: 45467 | S15: 45467 | T15: 45469 | U15: 0.200001 | V15: Quarter | W15: Income | Y15: 43453 | Z15: 43454 | AA15: 43455 | AB15: 43461 | AC15: 0.819 | AD15: Annual | AE15: Income | AG15: 45323 | AH15: 45331 | AI15: 45334 | AJ15: 45337 | AK15: 0.24 | AL15: Quarter | AM15: Regular Cash | AW15: 44557 | AX15: 44760 | AY15: 44743 | AZ15: 44757 | BA15: 20 | BB15: None | BC15: Stock Split | BE15: 45323 | BF15: 45343 | BG15: 45344 | BH15: 45377 | BI15: 0.5 | BJ15: Quarter | BK15: Regular Cash | BM15: 45363 | BN15: 45427 | BO15: 45428 | BP15: 45456 | BQ15: 0.75 | BR15: Quarter | BS15: Regular Cash | CC15: 45434 | CD15: 45453 | CE15: 45449 | CF15: 45450 | CG15: 10 | CH15: None | CI15: Stock Split | DA15: 45328 | DB15: 45456 | DC15: 45456 | DD15: 45484 | DE15: 0.42654 | DF15: Quarter | DG15: Regular Cash | DI15: 45455 | DJ15: 45467 | DK15: 45467 | DL15: 45471 | DM15: 0.525 | DN15: Quarter | DO15: Regular Cash | DY15: 45280 | DZ15: 45289 | EA15: 45293 | EB15: 45309 | EC15: 0.115 | ED15: Quarter | EE15: Regular Cash | FU15: 45362 | FV15: 45391 | FW15: 45392 | FX15: 45406 | FY15: 0.4 | FZ15: Quarter | GA15: Regular Cash | GC15: 45350 | GD15: 45364 | GE15: 45365 | GF15: 45393 | GG15: 0.4 | GH15: Quarter | GI15: Regular Cash | HA15: 45268 | HB15: 45336 | HC15: 45337 | HD15: 45359 | HE15: 1.3 | HF15: Quarter | HG15: Regular Cash | HI15: 45345 | HJ15: 45359 | HK15: 45362 | HL15: 45370 | HM15: 1.88 | HN15: Quarter | HO15: Regular Cash | HQ15: 45370 | HR15: 45386 | HS15: 45387 | HT15: 45412 | HU15: 1.15 | HV15: Quarter | HW15: Regular Cash | HY15: 45309 | HZ15: 45323 | IA15: 45324 | IB15: 45338 | IC15: 1.02 | ID15: Quarter | IE15: Regular Cash | IG15: 45324 | IH15: 45335 | II15: 45336 | IJ15: 45362 | IK15: 0.95 | IL15: Quarter | IM15: Regular Cash
A16: 45274 | B16: 45275 | C16: 45278 | D16: 45322 | E16: 1.906073 | F16: Quarter | G16: Income | I16: 45286 | J16: 45287 | K16: 45288 | L16: 45306 | M16: 0.21584 | N16: None | O16: Special Cash | Q16: 45366 | R16: 45369 | S16: 45370 | T16: 45372 | U16: 0.1696 | V16: Quarter | W16: Income | Y16: 43084 | Z16: 43087 | AA16: 43088 | AB16: 43091 | AC16: 0.698 | AD16: Annual | AE16: Income | AG16: 45232 | AH16: 45240 | AI16: 45243 | AJ16: 45246 | AK16: 0.24 | AL16: Quarter | AM16: Regular Cash | AW16: 41011 | AX16: 41732 | AY16: 41725 | AZ16: 41731 | BA16: 1 | BB16: None | BC16: In-specie | BE16: 40940 | BF16: 40482 | BG16: #N/A N/A | BH16: #N/A N/A | BI16: 5 | BJ16: None | BK16: Stock Split | BM16: 45258 | BN16: 45336 | BO16: 45337 | BP16: 45365 | BQ16: 0.75 | BR16: Quarter | BS16: Regular Cash | CC16: 45343 | CD16: 45356 | CE16: 45357 | CF16: 45378 | CG16: 0.004 | CH16: Quarter | CI16: Regular Cash | DA16: 45244 | DB16: 45369 | DC16: 45370 | DD16: 45393 | DE16: 0.431022 | DF16: Quarter | DG16: Regular Cash | DI16: 45358 | DJ16: 45371 | DK16: 45372 | DL16: 45380 | DM16: 0.525 | DN16: Quarter | DO16: Regular Cash | DY16: 45196 | DZ16: 45205 | EA16: 45209 | EB16: 45224 | EC16: 0.115 | ED16: Quarter | EE16: Regular Cash | FU16: 45271 | FV16: 45301 | FW16: 45302 | FX16: 45316 | FY16: 0.4 | FZ16: Quarter | GA16: Regular Cash | GC16: 41299 | GD16: 41382 | GE16: 41367 | GF16: 41381 | GG16: 4 | GH16: None | GI16: Stock Split | HA16: 45231 | HB16: 45244 | HC16: 45245 | HD16: 45268 | HE16: 1.13 | HF16: Quarter | HG16: Regular Cash | HI16: 45238 | HJ16: 45261 | HK16: 45264 | HL16: 45272 | HM16: 1.88 | HN16: Quarter | HO16: Regular Cash | HQ16: 45272 | HR16: 45295 | HS16: 45296 | HT16: 45322 | HU16: 1.05 | HV16: Quarter | HW16: Regular Cash | HY16: 45275 | HZ16: 45287 | IA16: 45288 | IB16: 45303 | IC16: 15 | ID16: None | IE16: Special Cash | IG16: 45226 | IH16: 45244 | II16: 45245 | IJ16: 45271 | IK16: 0.95 | IL16: Quarter | IM16: Regular Cash
A17: 45183 | B17: 45184 | C17: 45187 | D17: 45230 | E17: 1.583169 | F17: Quarter | G17: Income | I17: 45275 | J17: 45278 | K17: 45279 | L17: 45289 | M17: 0.80826 | N17: Quarter | O17: Income | Q17: 45275 | R17: 45278 | S17: 45279 | T17: 45281 | U17: 0.211007 | V17: Quarter | W17: Income | Y17: 42720 | Z17: 42723 | AA17: 42725 | AB17: 42727 | AC17: 0.288 | AD17: Annual | AE17: Income | AG17: 45141 | AH17: 45149 | AI17: 45152 | AJ17: 45155 | AK17: 0.24 | AL17: Quarter | AM17: Regular Cash | BM17: 45188 | BN17: 45245 | BO17: 45246 | BP17: 45274 | BQ17: 0.75 | BR17: Quarter | BS17: Regular Cash | CC17: 45251 | CD17: 45265 | CE17: 45266 | CF17: 45288 | CG17: 0.004 | CH17: Quarter | CI17: Regular Cash | DA17: 45146 | DB17: 45274 | DC17: 45275 | DD17: 45302 | DE17: 0.381765 | DF17: Quarter | DG17: Regular Cash | DI17: 45267 | DJ17: 45279 | DK17: 45280 | DL17: 45289 | DM17: 0.525 | DN17: Quarter | DO17: Regular Cash | DY17: 45105 | DZ17: 45114 | EA17: 45117 | EB17: 45132 | EC17: 0.115 | ED17: Quarter | EE17: Regular Cash | FU17: 45180 | FV17: 45210 | FW17: 45211 | FX17: 45225 | FY17: 0.4 | FZ17: Quarter | GA17: Regular Cash | HA17: 45103 | HB17: 45152 | HC17: 45153 | HD17: 45177 | HE17: 1.13 | HF17: Quarter | HG17: Regular Cash | HI17: 45161 | HJ17: 45177 | HK17: 45180 | HL17: 45188 | HM17: 1.88 | HN17: Quarter | HO17: Regular Cash | HQ17: 45188 | HR17: 45204 | HS17: 45205 | HT17: 45230 | HU17: 1.05 | HV17: Quarter | HW17: Regular Cash | HY17: 45217 | HZ17: 45232 | IA17: 45233 | IB17: 45247 | IC17: 1.02 | ID17: Quarter | IE17: Regular Cash | IG17: 45135 | IH17: 45153 | II17: 45154 | IJ17: 45180 | IK17: 0.91 | IL17: Quarter | IM17: Regular Cash
A18: 45092 | B18: 45093 | C18: 45097 | D18: 45138 | E18: 1.638367 | F18: Quarter | G18: Income | I18: 45184 | J18: 45187 | K18: 45188 | L18: 45230 | M18: 0.53555 | N18: Quarter | O18: Income | Q18: 45184 | R18: 45187 | S18: 45188 | T18: 45190 | U18: 0.180143 | V18: Quarter | W18: Income | Y18: 42356 | Z18: 42359 | AA18: 42361 | AB18: 42366 | AC18: 0.5705 | AD18: Annual | AE18: Income | AG18: 45050 | AH18: 45058 | AI18: 45061 | AJ18: 45064 | AK18: 0.24 | AL18: Quarter | AM18: Regular Cash | BM18: 45090 | BN18: 45154 | BO18: 45155 | BP18: 45183 | BQ18: 0.68 | BR18: Quarter | BS18: Regular Cash | CC18: 45161 | CD18: 45175 | CE18: 45176 | CF18: 45197 | CG18: 0.004 | CH18: Quarter | CI18: Regular Cash | DA18: 45055 | DB18: 45183 | DC18: 45184 | DD18: 45211 | DE18: 0.367441 | DF18: Quarter | DG18: Regular Cash | DI18: 45169 | DJ18: 45189 | DK18: 45190 | DL18: 45198 | DM18: 0.46 | DN18: Quarter | DO18: Regular Cash | DY18: 45013 | DZ18: 45022 | EA18: 45026 | EB18: 45041 | EC18: 0.115 | ED18: Quarter | EE18: Regular Cash | FU18: 45089 | FV18: 45118 | FW18: 45119 | FX18: 45133 | FY18: 0.4 | FZ18: Quarter | GA18: Regular Cash | HA18: 45047 | HB18: 45058 | HC18: 45061 | HD18: 45086 | HE18: 1.13 | HF18: Quarter | HG18: Regular Cash | HI18: 45084 | HJ18: 45092 | HK18: 45096 | HL18: 45104 | HM18: 1.88 | HN18: Quarter | HO18: Regular Cash | HQ18: 45061 | HR18: 45112 | HS18: 45113 | HT18: 45138 | HU18: 1 | HV18: Quarter | HW18: Regular Cash | HY18: 45147 | HZ18: 45162 | IA18: 45163 | IB18: 45177 | IC18: 1.02 | ID18: Quarter | IE18: Regular Cash | IG18: 45044 | IH18: 45061 | II18: 45062 | IJ18: 45086 | IK18: 0.91 | IL18: Quarter | IM18: Regular Cash
A19: 45001 | B19: 45002 | C19: 45005 | D19: 45044 | E19: 1.506204 | F19: Quarter | G19: Income | I19: 45093 | J19: 45097 | K19: 45098 | L19: 45138 | M19: 0.50395 | N19: Quarter | O19: Income | Q19: 45093 | R19: 45097 | S19: 45098 | T19: 45100 | U19: 0.180792 | V19: Quarter | W19: Income | Y19: 41992 | Z19: 41995 | AA19: 41997 | AB19: 42002 | AC19: 0.316 | AD19: Annual | AE19: Income | AG19: 44959 | AH19: 44967 | AI19: 44970 | AJ19: 44973 | AK19: 0.23 | AL19: Quarter | AM19: Regular Cash | BM19: 44999 | BN19: 45063 | BO19: 45064 | BP19: 45085 | BQ19: 0.68 | BR19: Quarter | BS19: Regular Cash | CC19: 45070 | CD19: 45084 | CE19: 45085 | CF19: 45107 | CG19: 0.004 | CH19: Quarter | CI19: Regular Cash | DA19: 44971 | DB19: 45092 | DC19: 45093 | DD19: 45120 | DE19: 0.3468 | DF19: Quarter | DG19: Regular Cash | DI19: 45078 | DJ19: 45098 | DK19: 45099 | DL19: 45107 | DM19: 0.46 | DN19: Quarter | DO19: Regular Cash | DY19: 44916 | DZ19: 44925 | EA19: 44929 | EB19: 44945 | EC19: 0.115 | ED19: Quarter | EE19: Regular Cash | FU19: 44994 | FV19: 45026 | FW19: 45027 | FX19: 45040 | FY19: 0.4 | FZ19: Quarter | GA19: Regular Cash | HA19: 44907 | HB19: 44971 | HC19: 44972 | HD19: 44995 | HE19: 1.13 | HF19: Quarter | HG19: Regular Cash | HI19: 44984 | HJ19: 44995 | HK19: 44998 | HL19: 45006 | HM19: 1.65 | HN19: Quarter | HO19: Regular Cash | HQ19: 45006 | HR19: 45021 | HS19: 45022 | HT19: 45046 | HU19: 1 | HV19: Quarter | HW19: Regular Cash | HY19: 45035 | HZ19: 45050 | IA19: 45051 | IB19: 45065 | IC19: 1.02 | ID19: Quarter | IE19: Regular Cash | IG19: 44957 | IH19: 44970 | II19: 44971 | IJ19: 44995 | IK19: 0.91 | IL19: Quarter | IM19: Regular Cash
A20: 44910 | B20: 44911 | C20: 44914 | D20: 44957 | E20: 1.7814 | F20: Quarter | G20: Income | I20: 45002 | J20: 45005 | K20: 45006 | L20: 45044 | M20: 0.47223 | N20: Quarter | O20: Income | Q20: 45002 | R20: 45005 | S20: 45006 | T20: 45008 | U20: 0.157726 | V20: Quarter | W20: Income | Y20: 41628 | Z20: 41631 | AA20: 41634 | AB20: 41638 | AC20: 0.3295 | AD20: Annual | AE20: Income | AG20: 44861 | AH20: 44869 | AI20: 44872 | AJ20: 44875 | AK20: 0.23 | AL20: Quarter | AM20: Regular Cash | BM20: 44894 | BN20: 44972 | BO20: 44973 | BP20: 44994 | BQ20: 0.68 | BR20: Quarter | BS20: Regular Cash | CC20: 44979 | CD20: 44992 | CE20: 44993 | CF20: 45014 | CG20: 0.004 | CH20: Quarter | CI20: Regular Cash | DA20: 44873 | DB20: 45001 | DC20: 45002 | DD20: 45029 | DE20: 0.356346 | DF20: Quarter | DG20: Regular Cash | DI20: 44987 | DJ20: 45006 | DK20: 45007 | DL20: 45016 | DM20: 0.46 | DN20: Quarter | DO20: Regular Cash | DY20: 44833 | DZ20: 44841 | EA20: 44845 | EB20: 44860 | EC20: 0.115 | ED20: Quarter | EE20: Regular Cash | FU20: 44907 | FV20: 44935 | FW20: 44936 | FX20: 44950 | FY20: 0.32 | FZ20: Quarter | GA20: Regular Cash | HA20: 44851 | HB20: 44879 | HC20: 44880 | HD20: 44904 | HE20: 0.98 | HF20: Quarter | HG20: Regular Cash | HI20: 44869 | HJ20: 44897 | HK20: 44900 | HL20: 44908 | HM20: 1.65 | HN20: Quarter | HO20: Regular Cash | HQ20: 44908 | HR20: 44931 | HS20: 44932 | HT20: 44957 | HU20: 1 | HV20: Quarter | HW20: Regular Cash | HY20: 44945 | HZ20: 44959 | IA20: 44960 | IB20: 44974 | IC20: 0.9 | ID20: Quarter | IE20: Regular Cash | IG20: 44862 | IH20: 44879 | II20: 44880 | IJ20: 44904 | IK20: 0.91 | IL20: Quarter | IM20: Regular Cash
A21: 44819 | B21: 44820 | C21: 44823 | D21: 44865 | E21: 1.596398 | F21: Quarter | G21: Income | I21: 44911 | J21: 44914 | K21: 44915 | L21: 44925 | M21: 0.65541 | N21: Quarter | O21: Income | Q21: 44911 | R21: 44914 | S21: 44915 | T21: 44917 | U21: 0.182682 | V21: Quarter | W21: Income | Y21: 41264 | Z21: 41267 | AA21: 41270 | AB21: 41274 | AC21: 0.35 | AD21: Annual | AE21: Income | AG21: 44770 | AH21: 44778 | AI21: 44781 | AJ21: 44784 | AK21: 0.23 | AL21: Quarter | AM21: Regular Cash | BM21: 44824 | BN21: 44881 | BO21: 44882 | BP21: 44903 | BQ21: 0.68 | BR21: Quarter | BS21: Regular Cash | CC21: 44881 | CD21: 44895 | CE21: 44896 | CF21: 44917 | CG21: 0.004 | CH21: Quarter | CI21: Regular Cash | DA21: 44782 | DB21: 44910 | DC21: 44911 | DD21: 44938 | DE21: 0.353366 | DF21: Quarter | DG21: Regular Cash | DI21: 44903 | DJ21: 44914 | DK21: 44915 | DL21: 44925 | DM21: 0.46 | DN21: Quarter | DO21: Regular Cash | DY21: 44742 | DZ21: 44750 | EA21: 44753 | EB21: 44768 | EC21: 0.115 | ED21: Quarter | EE21: Regular Cash | FU21: 44816 | FV21: 44845 | FW21: 44846 | FX21: 44859 | FY21: 0.32 | FZ21: Quarter | GA21: Regular Cash | HA21: 44739 | HB21: 44785 | HC21: 44788 | HD21: 44813 | HE21: 0.98 | HF21: Quarter | HG21: Regular Cash | HI21: 44790 | HJ21: 44813 | HK21: 44816 | HL21: 44824 | HM21: 1.65 | HN21: Quarter | HO21: Regular Cash | HQ21: 44824 | HR21: 44839 | HS21: 44840 | HT21: 44865 | HU21: 1 | HV21: Quarter | HW21: Regular Cash | HY21: 44846 | HZ21: 44861 | IA21: 44862 | IB21: 44875 | IC21: 0.9 | ID21: Quarter | IE21: Regular Cash | IG21: 44769 | IH21: 44784 | II21: 44785 | IJ21: 44813 | IK21: 0.88 | IL21: Quarter | IM21: Regular Cash
A22: 44728 | B22: 44729 | C22: 44733 | D22: 44771 | E22: 1.576871 | F22: Quarter | G22: Income | I22: 44820 | J22: 44823 | K22: 44824 | L22: 44865 | M22: 0.51856 | N22: Quarter | O22: Income | Q22: 44820 | R22: 44823 | S22: 44824 | T22: 44826 | U22: 0.158333 | V22: Quarter | W22: Income | AG22: 44679 | AH22: 44687 | AI22: 44690 | AJ22: 44693 | AK22: 0.23 | AL22: Quarter | AM22: Regular Cash | BM22: 44726 | BN22: 44790 | BO22: 44791 | BP22: 44812 | BQ22: 0.62 | BR22: Quarter | BS22: Regular Cash | CC22: 44797 | CD22: 44811 | CE22: 44812 | CF22: 44833 | CG22: 0.004 | CH22: Quarter | CI22: Regular Cash | DA22: 44691 | DB22: 44819 | DC22: 44820 | DD22: 44847 | DE22: 0.343565 | DF22: Quarter | DG22: Regular Cash | DI22: 44805 | DJ22: 44825 | DK22: 44826 | DL22: 44834 | DM22: 0.41 | DN22: Quarter | DO22: Regular Cash | DY22: 44649 | DZ22: 44659 | EA22: 44662 | EB22: 44677 | EC22: 0.1 | ED22: Quarter | EE22: Regular Cash | FU22: 44725 | FV22: 44753 | FW22: 44754 | FX22: 44768 | FY22: 0.32 | FZ22: Quarter | GA22: Regular Cash | HA22: 44683 | HB22: 44694 | HC22: 44697 | HD22: 44722 | HE22: 0.98 | HF22: Quarter | HG22: Regular Cash | HI22: 44720 | HJ22: 44728 | HK22: 44732 | HL22: 44740 | HM22: 1.65 | HN22: Quarter | HO22: Regular Cash | HQ22: 44697 | HR22: 44747 | HS22: 44748 | HT22: 44773 | HU22: 1 | HV22: Quarter | HW22: Regular Cash | HY22: 44755 | HZ22: 44770 | IA22: 44771 | IB22: 44785 | IC22: 0.9 | ID22: Quarter | IE22: Regular Cash | IG22: 44678 | IH22: 44693 | II22: 44694 | IJ22: 44722 | IK22: 0.88 | IL22: Quarter | IM22: Regular Cash
A23: 44637 | B23: 44638 | C23: 44641 | D23: 44680 | E23: 1.366009 | F23: Quarter | G23: Income | I23: 44729 | J23: 44733 | K23: 44734 | L23: 44771 | M23: 0.5274 | N23: Quarter | O23: Income | Q23: 44729 | R23: 44733 | S23: 44734 | T23: 44736 | U23: 0.161584 | V23: Quarter | W23: Income | AG23: 44588 | AH23: 44596 | AI23: 44599 | AJ23: 44602 | AK23: 0.22 | AL23: Quarter | AM23: Regular Cash | BM23: 44634 | BN23: 44699 | BO23: 44700 | BP23: 44721 | BQ23: 0.62 | BR23: Quarter | BS23: Regular Cash | CC23: 44706 | CD23: 44720 | CE23: 44721 | CF23: 44743 | CG23: 0.004 | CH23: Quarter | CI23: Regular Cash | DA23: 44607 | DB23: 44728 | DC23: 44729 | DD23: 44756 | DE23: 0.364647 | DF23: Quarter | DG23: Regular Cash | DI23: 44707 | DJ23: 44733 | DK23: 44734 | DL23: 44742 | DM23: 0.41 | DN23: Quarter | DO23: Regular Cash | DY23: 44550 | DZ23: 44561 | EA23: 44564 | EB23: 44579 | EC23: 0.1 | ED23: Quarter | EE23: Regular Cash | FU23: 44630 | FV23: 44658 | FW23: 44659 | FX23: 44672 | FY23: 0.32 | FZ23: Quarter | GA23: Regular Cash | HA23: 44543 | HB23: 44606 | HC23: 44607 | HD23: 44630 | HE23: 0.98 | HF23: Quarter | HG23: Regular Cash | HI23: 44608 | HJ23: 44631 | HK23: 44634 | HL23: 44642 | HM23: 1.45 | HN23: Quarter | HO23: Regular Cash | HQ23: 44635 | HR23: 44656 | HS23: 44657 | HT23: 44681 | HU23: 1 | HV23: Quarter | HW23: Regular Cash | HY23: 44664 | HZ23: 44679 | IA23: 44680 | IB23: 44694 | IC23: 0.9 | ID23: Quarter | IE23: Regular Cash | IG23: 44587 | IH23: 44601 | II23: 44602 | IJ23: 44630 | IK23: 0.88 | IL23: Quarter | IM23: Regular Cash
A24: 44546 | B24: 44547 | C24: 44550 | D24: 44592 | E24: 1.636431 | F24: Quarter | G24: Income | I24: 44638 | J24: 44641 | K24: 44642 | L24: 44680 | M24: 0.43369 | N24: Quarter | O24: Income | Q24: 44638 | R24: 44641 | S24: 44642 | T24: 44644 | U24: 0.14281 | V24: Quarter | W24: Income | AG24: 44497 | AH24: 44505 | AI24: 44508 | AJ24: 44511 | AK24: 0.22 | AL24: Quarter | AM24: Regular Cash | BM24: 44537 | BN24: 44608 | BO24: 44609 | BP24: 44630 | BQ24: 0.62 | BR24: Quarter | BS24: Regular Cash | CC24: 44608 | CD24: 44622 | CE24: 44623 | CF24: 44644 | CG24: 0.004 | CH24: Quarter | CI24: Regular Cash | DA24: 44509 | DB24: 44636 | DC24: 44637 | DD24: 44665 | DE24: 0.375734 | DF24: Quarter | DG24: Regular Cash | DI24: 44623 | DJ24: 44641 | DK24: 44642 | DL24: 44651 | DM24: 0.41 | DN24: Quarter | DO24: Regular Cash | DY24: 44410 | DZ24: 44469 | EA24: 44470 | EB24: 44487 | EC24: 0.1 | ED24: Quarter | EE24: Regular Cash | FU24: 44539 | FV24: 44567 | FW24: 44568 | FX24: 44580 | FY24: 0.32 | FZ24: Quarter | GA24: Regular Cash | HA24: 44487 | HB24: 44512 | HC24: 44515 | HD24: 44540 | HE24: 0.85 | HF24: Quarter | HG24: Regular Cash | HI24: 44505 | HJ24: 44533 | HK24: 44536 | HL24: 44544 | HM24: 1.45 | HN24: Quarter | HO24: Regular Cash | HQ24: 44544 | HR24: 44566 | HS24: 44567 | HT24: 44592 | HU24: 1 | HV24: Quarter | HW24: Regular Cash | HY24: 44581 | HZ24: 44595 | IA24: 44596 | IB24: 44610 | IC24: 0.79 | ID24: Quarter | IE24: Regular Cash | IG24: 44496 | IH24: 44510 | II24: 44512 | IJ24: 44540 | IK24: 0.88 | IL24: Quarter | IM24: Regular Cash
A25: 44455 | B25: 44456 | C25: 44459 | D25: 44498 | E25: 1.428117 | F25: Quarter | G25: Income | I25: 44547 | J25: 44550 | K25: 44551 | L25: 44561 | M25: 0.49141 | N25: Quarter | O25: Income | Q25: 44547 | R25: 44550 | S25: 44551 | T25: 44553 | U25: 0.158272 | V25: Quarter | W25: Income | AG25: 44404 | AH25: 44414 | AI25: 44417 | AJ25: 44420 | AK25: 0.22 | AL25: Quarter | AM25: Regular Cash | BM25: 44453 | BN25: 44517 | BO25: 44518 | BP25: 44539 | BQ25: 0.62 | BR25: Quarter | BS25: Regular Cash | CC25: 44517 | CD25: 44531 | CE25: 44532 | CF25: 44553 | CG25: 0.004 | CH25: Quarter | CI25: Regular Cash | DA25: 44419 | DB25: 44546 | DC25: 44547 | DD25: 44574 | DE25: 0.392615 | DF25: Quarter | DG25: Regular Cash | DI25: 44539 | DJ25: 44551 | DK25: 44552 | DL25: 44561 | DM25: 0.41 | DN25: Quarter | DO25: Regular Cash | DY25: 42571 | DZ25: 42571 | EA25: 42583 | EB25: #N/A N/A | EC25: 1 | ED25: None | EE25: Poison Pill Rights | FU25: 44452 | FV25: 44477 | FW25: 44481 | FX25: 44495 | FY25: 0.32 | FZ25: Quarter | GA25: Regular Cash | HA25: 44376 | HB25: 44420 | HC25: 44421 | HD25: 44449 | HE25: 0.85 | HF25: Quarter | HG25: Regular Cash | HI25: 44419 | HJ25: 44449 | HK25: 44452 | HL25: 44460 | HM25: 1.45 | HN25: Quarter | HO25: Regular Cash | HQ25: 44460 | HR25: 44474 | HS25: 44475 | HT25: 44500 | HU25: 1 | HV25: Quarter | HW25: Regular Cash | HY25: 44482 | HZ25: 44497 | IA25: 44498 | IB25: 44512 | IC25: 0.79 | ID25: Quarter | IE25: Regular Cash | IG25: 44405 | IH25: 44420 | II25: 44421 | IJ25: 44449 | IK25: 0.87 | IL25: Quarter | IM25: Regular Cash
A26: 44364 | B26: 44365 | C26: 44368 | D26: 44407 | E26: 1.375875 | F26: Quarter | G26: Income | I26: 44456 | J26: 44459 | K26: 44460 | L26: 44498 | M26: 0.41391 | N26: Quarter | O26: Income | Q26: 44456 | R26: 44459 | S26: 44460 | T26: 44462 | U26: 0.136431 | V26: Quarter | W26: Income | AG26: 44314 | AH26: 44323 | AI26: 44326 | AJ26: 44329 | AK26: 0.22 | AL26: Quarter | AM26: Regular Cash | BM26: 44363 | BN26: 44426 | BO26: 44427 | BP26: 44448 | BQ26: 0.56 | BR26: Quarter | BS26: Regular Cash | CC26: 44426 | CD26: 44439 | CE26: 44440 | CF26: 44462 | CG26: 0.004 | CH26: Quarter | CI26: Regular Cash | DA26: 44357 | DB26: 44455 | DC26: 44456 | DD26: 44483 | DE26: 0.388084 | DF26: Quarter | DG26: Regular Cash | DI26: 44441 | DJ26: 44460 | DK26: 44461 | DL26: 44469 | DM26: 0.36 | DN26: Quarter | DO26: Regular Cash | FU26: 44362 | FV26: 44391 | FW26: 44392 | FX26: 44406 | FY26: 0.32 | FZ26: Quarter | GA26: Regular Cash | HA26: 44319 | HB26: 44329 | HC26: 44330 | HD26: 44357 | HE26: 0.85 | HF26: Quarter | HG26: Regular Cash | HI26: 44356 | HJ26: 44365 | HK26: 44368 | HL26: 44376 | HM26: 1.45 | HN26: Quarter | HO26: Regular Cash | HQ26: 44333 | HR26: 44379 | HS26: 44383 | HT26: 44408 | HU26: 0.9 | HV26: Quarter | HW26: Regular Cash | HY26: 44390 | HZ26: 44406 | IA26: 44407 | IB26: 44421 | IC26: 0.79 | ID26: Quarter | IE26: Regular Cash | IG26: 44314 | IH26: 44328 | II26: 44329 | IJ26: 44357 | IK26: 0.87 | IL26: Quarter | IM26: Regular Cash
A27: 44273 | B27: 44274 | C27: 44277 | D27: 44316 | E27: 1.277788 | F27: Quarter | G27: Income | I27: 44365 | J27: 44368 | K27: 44369 | L27: 44407 | M27: 0.39679 | N27: Quarter | O27: Income | Q27: 44365 | R27: 44368 | S27: 44369 | T27: 44371 | U27: 0.129746 | V27: Quarter | W27: Income | AG27: 44223 | AH27: 44232 | AI27: 44235 | AJ27: 44238 | AK27: 0.205 | AL27: Quarter | AM27: Regular Cash | BM27: 44271 | BN27: 44335 | BO27: 44336 | BP27: 44357 | BQ27: 0.56 | BR27: Quarter | BS27: Regular Cash | CC27: 44337 | CD27: 44397 | CE27: 44368 | CF27: 44396 | CG27: 3 | CH27: None | CI27: Stock Dividend | DA27: 44236 | DB27: 44364 | DC27: 44365 | DD27: 44392 | DE27: 0.352025 | DF27: Quarter | DG27: Regular Cash | DI27: 44350 | DJ27: 44368 | DK27: 44369 | DL27: 44377 | DM27: 0.36 | DN27: Quarter | DO27: Regular Cash | FU27: 44265 | FV27: 44293 | FW27: 44294 | FX27: 44308 | FY27: 0.32 | FZ27: Quarter | GA27: Regular Cash | HA27: 44179 | HB27: 44238 | HC27: 44239 | HD27: 44265 | HE27: 0.85 | HF27: Quarter | HG27: Regular Cash | HI27: 44251 | HJ27: 44267 | HK27: 44270 | HL27: 44278 | HM27: 1.25 | HN27: Quarter | HO27: Regular Cash | HQ27: 44271 | HR27: 44291 | HS27: 44292 | HT27: 44316 | HU27: 0.9 | HV27: Quarter | HW27: Regular Cash | HY27: 44300 | HZ27: 44315 | IA27: 44316 | IB27: 44330 | IC27: 0.79 | ID27: Quarter | IE27: Regular Cash | IG27: 44223 | IH27: 44236 | II27: 44237 | IJ27: 44265 | IK27: 0.87 | IL27: Quarter | IM27: Regular Cash
A28: 44182 | B28: 44183 | C28: 44186 | D28: 44225 | E28: 1.58 | F28: Quarter | G28: Income | I28: 44274 | J28: 44277 | K28: 44278 | L28: 44316 | M28: 0.39468 | N28: Quarter | O28: Income | Q28: 44274 | R28: 44277 | S28: 44278 | T28: 44280 | U28: 0.136575 | V28: Quarter | W28: Income | AG28: 44133 | AH28: 44141 | AI28: 44144 | AJ28: 44147 | AK28: 0.205 | AL28: Quarter | AM28: Regular Cash | BM28: 44167 | BN28: 44244 | BO28: 44245 | BP28: 44266 | BQ28: 0.56 | BR28: Quarter | BS28: Regular Cash | CC28: 44342 | CD28: 44356 | CE28: 44357 | CF28: 44378 | CG28: 0.004 | CH28: Quarter | CI28: Regular Cash | DA28: 44145 | DB28: 44272 | DC28: 44273 | DD28: 44301 | DE28: 0.347478 | DF28: Quarter | DG28: Regular Cash | DI28: 44259 | DJ28: 44274 | DK28: 44277 | DL28: 44286 | DM28: 0.36 | DN28: Quarter | DO28: Regular Cash | FU28: 44175 | FV28: 44202 | FW28: 44203 | FX28: 44217 | FY28: 0.24 | FZ28: Quarter | GA28: Regular Cash | HA28: 44123 | HB28: 44147 | HC28: 44148 | HD28: 44175 | HE28: 0.74 | HF28: Quarter | HG28: Regular Cash | HI28: 44139 | HJ28: 44169 | HK28: 44172 | HL28: 44180 | HM28: 1.25 | HN28: Quarter | HO28: Regular Cash | HQ28: 44173 | HR28: 44201 | HS28: 44202 | HT28: 44227 | HU28: 0.9 | HV28: Quarter | HW28: Regular Cash | HY28: 44217 | HZ28: 44231 | IA28: 44232 | IB28: 44246 | IC28: 0.7 | ID28: Quarter | IE28: Regular Cash | IG28: 44132 | IH28: 44145 | II28: 44147 | IJ28: 44175 | IK28: 0.87 | IL28: Quarter | IM28: Regular Cash
A29: 44091 | B29: 44092 | C29: 44095 | D29: 44134 | E29: 1.339224 | F29: Quarter | G29: Income | I29: 44183 | J29: 44186 | K29: 44187 | L29: 44196 | M29: 0.56133 | N29: Quarter | O29: Income | Q29: 44183 | R29: 44186 | S29: 44187 | T29: 44189 | U29: 0.148821 | V29: Quarter | W29: Income | AG29: 44042 | AH29: 44074 | AI29: 44067 | AJ29: 44071 | AK29: 4 | AL29: None | AM29: Stock Split | BM29: 44089 | BN29: 44153 | BO29: 44154 | BP29: 44175 | BQ29: 0.56 | BR29: Quarter | BS29: Regular Cash | CC29: 44251 | CD29: 44264 | CE29: 44265 | CF29: 44286 | CG29: 0.004 | CH29: Quarter | CI29: Regular Cash | DA29: 44055 | DB29: 44182 | DC29: 44183 | DD29: 44210 | DE29: 0.352678 | DF29: Quarter | DG29: Regular Cash | DI29: 44175 | DJ29: 44183 | DK29: 44186 | DL29: 44196 | DM29: 0.36 | DN29: Quarter | DO29: Regular Cash | FU29: 44084 | FV29: 44111 | FW29: 44112 | FX29: 44126 | FY29: 0.24 | FZ29: Quarter | GA29: Regular Cash | HA29: 44027 | HB29: 44056 | HC29: 44057 | HD29: 44084 | HE29: 0.74 | HF29: Quarter | HG29: Regular Cash | HI29: 44048 | HJ29: 44085 | HK29: 44088 | HL29: 44096 | HM29: 1.25 | HN29: Quarter | HO29: Regular Cash | HQ29: 44089 | HR29: 44109 | HS29: 44110 | HT29: 44135 | HU29: 0.9 | HV29: Quarter | HW29: Regular Cash | HY29: 44151 | HZ29: 44166 | IA29: 44167 | IB29: 44176 | IC29: 10 | ID29: None | IE29: Special Cash | IG29: 44041 | IH29: 44055 | II29: 44056 | IJ29: 44084 | IK29: 0.87 | IL29: Quarter | IM29: Regular Cash
